[2024-09-15 20:04:30,691] {taskinstance.py:1159} INFO - Dependencies all met for <TaskInstance: BRONZER_GET_STONCKS.BRONZE_TSLA scheduled__2024-01-20T00:00:00+00:00 [queued]>
[2024-09-15 20:04:30,695] {taskinstance.py:1159} INFO - Dependencies all met for <TaskInstance: BRONZER_GET_STONCKS.BRONZE_TSLA scheduled__2024-01-20T00:00:00+00:00 [queued]>
[2024-09-15 20:04:30,695] {taskinstance.py:1356} INFO - 
--------------------------------------------------------------------------------
[2024-09-15 20:04:30,695] {taskinstance.py:1357} INFO - Starting attempt 1 of 1
[2024-09-15 20:04:30,695] {taskinstance.py:1358} INFO - 
--------------------------------------------------------------------------------
[2024-09-15 20:04:30,705] {taskinstance.py:1377} INFO - Executing <Task(_PythonDecoratedOperator): BRONZE_TSLA> on 2024-01-20 00:00:00+00:00
[2024-09-15 20:04:30,708] {standard_task_runner.py:52} INFO - Started process 11658 to run task
[2024-09-15 20:04:30,710] {standard_task_runner.py:79} INFO - Running: ['airflow', 'tasks', 'run', 'BRONZER_GET_STONCKS', 'BRONZE_TSLA', 'scheduled__2024-01-20T00:00:00+00:00', '--job-id', '68', '--raw', '--subdir', 'DAGS_FOLDER/get_stocks.py', '--cfg-path', '/tmp/tmppgadc368', '--error-file', '/tmp/tmpbmvv5qnb']
[2024-09-15 20:04:30,711] {standard_task_runner.py:80} INFO - Job 68: Subtask BRONZE_TSLA
[2024-09-15 20:04:30,739] {task_command.py:370} INFO - Running <TaskInstance: BRONZER_GET_STONCKS.BRONZE_TSLA scheduled__2024-01-20T00:00:00+00:00 [running]> on host kaiwang.
[2024-09-15 20:04:30,779] {taskinstance.py:1569} INFO - Exporting the following env vars:
AIRFLOW_CTX_DAG_OWNER=airflow
AIRFLOW_CTX_DAG_ID=BRONZER_GET_STONCKS
AIRFLOW_CTX_TASK_ID=BRONZE_TSLA
AIRFLOW_CTX_EXECUTION_DATE=2024-01-20T00:00:00+00:00
AIRFLOW_CTX_TRY_NUMBER=1
AIRFLOW_CTX_DAG_RUN_ID=scheduled__2024-01-20T00:00:00+00:00
[2024-09-15 20:04:30,780] {taskinstance.py:1889} ERROR - Task failed with exception
Traceback (most recent call last):
  File "/usr/lib/python3.10/pathlib.py", line 1175, in mkdir
    self._accessor.mkdir(self, mode)
FileNotFoundError: [Errno 2] No such file or directory: '/datalake/TSLA'

During handling of the above exception, another exception occurred:

Traceback (most recent call last):
  File "/home/kaiwang/Documents/airflow_celeby/venv/lib/python3.10/site-packages/airflow/decorators/base.py", line 179, in execute
    return_value = super().execute(context)
  File "/home/kaiwang/Documents/airflow_celeby/venv/lib/python3.10/site-packages/airflow/operators/python.py", line 171, in execute
    return_value = self.execute_callable()
  File "/home/kaiwang/Documents/airflow_celeby/venv/lib/python3.10/site-packages/airflow/operators/python.py", line 189, in execute_callable
    return self.python_callable(*self.op_args, **self.op_kwargs)
  File "/home/kaiwang/Documents/airflow_celeby/dags/get_stocks.py", line 21, in get_history
    (Path(file_path).parent).mkdir(parents=True, exist_ok=True)
  File "/usr/lib/python3.10/pathlib.py", line 1179, in mkdir
    self.parent.mkdir(parents=True, exist_ok=True)
  File "/usr/lib/python3.10/pathlib.py", line 1175, in mkdir
    self._accessor.mkdir(self, mode)
PermissionError: [Errno 13] Permission denied: '/datalake'
[2024-09-15 20:04:30,783] {taskinstance.py:1395} INFO - Marking task as FAILED. dag_id=BRONZER_GET_STONCKS, task_id=BRONZE_TSLA, execution_date=20240120T000000, start_date=20240915T230430, end_date=20240915T230430
[2024-09-15 20:04:30,791] {standard_task_runner.py:92} ERROR - Failed to execute job 68 for task BRONZE_TSLA ([Errno 13] Permission denied: '/datalake'; 11658)
[2024-09-15 20:04:30,803] {local_task_job.py:156} INFO - Task exited with return code 1
[2024-09-15 20:04:30,812] {local_task_job.py:273} INFO - 0 downstream tasks scheduled from follow-on schedule check
[2024-09-15 20:11:46,943] {taskinstance.py:1159} INFO - Dependencies all met for <TaskInstance: BRONZER_GET_STONCKS.BRONZE_TSLA scheduled__2024-01-20T00:00:00+00:00 [queued]>
[2024-09-15 20:11:46,948] {taskinstance.py:1159} INFO - Dependencies all met for <TaskInstance: BRONZER_GET_STONCKS.BRONZE_TSLA scheduled__2024-01-20T00:00:00+00:00 [queued]>
[2024-09-15 20:11:46,948] {taskinstance.py:1356} INFO - 
--------------------------------------------------------------------------------
[2024-09-15 20:11:46,948] {taskinstance.py:1357} INFO - Starting attempt 1 of 1
[2024-09-15 20:11:46,948] {taskinstance.py:1358} INFO - 
--------------------------------------------------------------------------------
[2024-09-15 20:11:46,959] {taskinstance.py:1377} INFO - Executing <Task(_PythonDecoratedOperator): BRONZE_TSLA> on 2024-01-20 00:00:00+00:00
[2024-09-15 20:11:46,962] {standard_task_runner.py:52} INFO - Started process 12995 to run task
[2024-09-15 20:11:46,964] {standard_task_runner.py:79} INFO - Running: ['airflow', 'tasks', 'run', 'BRONZER_GET_STONCKS', 'BRONZE_TSLA', 'scheduled__2024-01-20T00:00:00+00:00', '--job-id', '119', '--raw', '--subdir', 'DAGS_FOLDER/get_stocks.py', '--cfg-path', '/tmp/tmpiiv0on5f', '--error-file', '/tmp/tmpvoylrsg_']
[2024-09-15 20:11:46,965] {standard_task_runner.py:80} INFO - Job 119: Subtask BRONZE_TSLA
[2024-09-15 20:11:46,993] {task_command.py:370} INFO - Running <TaskInstance: BRONZER_GET_STONCKS.BRONZE_TSLA scheduled__2024-01-20T00:00:00+00:00 [running]> on host kaiwang.
[2024-09-15 20:11:47,035] {taskinstance.py:1569} INFO - Exporting the following env vars:
AIRFLOW_CTX_DAG_OWNER=airflow
AIRFLOW_CTX_DAG_ID=BRONZER_GET_STONCKS
AIRFLOW_CTX_TASK_ID=BRONZE_TSLA
AIRFLOW_CTX_EXECUTION_DATE=2024-01-20T00:00:00+00:00
AIRFLOW_CTX_TRY_NUMBER=1
AIRFLOW_CTX_DAG_RUN_ID=scheduled__2024-01-20T00:00:00+00:00
[2024-09-15 20:11:47,036] {taskinstance.py:1889} ERROR - Task failed with exception
Traceback (most recent call last):
  File "/usr/lib/python3.10/pathlib.py", line 1175, in mkdir
    self._accessor.mkdir(self, mode)
FileNotFoundError: [Errno 2] No such file or directory: '/Documents/airflow_celeby/datalake/TSLA'

During handling of the above exception, another exception occurred:

Traceback (most recent call last):
  File "/usr/lib/python3.10/pathlib.py", line 1175, in mkdir
    self._accessor.mkdir(self, mode)
FileNotFoundError: [Errno 2] No such file or directory: '/Documents/airflow_celeby/datalake'

During handling of the above exception, another exception occurred:

Traceback (most recent call last):
  File "/usr/lib/python3.10/pathlib.py", line 1175, in mkdir
    self._accessor.mkdir(self, mode)
FileNotFoundError: [Errno 2] No such file or directory: '/Documents/airflow_celeby'

During handling of the above exception, another exception occurred:

Traceback (most recent call last):
  File "/home/kaiwang/Documents/airflow_celeby/venv/lib/python3.10/site-packages/airflow/decorators/base.py", line 179, in execute
    return_value = super().execute(context)
  File "/home/kaiwang/Documents/airflow_celeby/venv/lib/python3.10/site-packages/airflow/operators/python.py", line 171, in execute
    return_value = self.execute_callable()
  File "/home/kaiwang/Documents/airflow_celeby/venv/lib/python3.10/site-packages/airflow/operators/python.py", line 189, in execute_callable
    return self.python_callable(*self.op_args, **self.op_kwargs)
  File "/home/kaiwang/Documents/airflow_celeby/dags/get_stocks.py", line 21, in get_history
    (Path(file_path).parent).mkdir(parents=True, exist_ok=True)
  File "/usr/lib/python3.10/pathlib.py", line 1179, in mkdir
    self.parent.mkdir(parents=True, exist_ok=True)
  File "/usr/lib/python3.10/pathlib.py", line 1179, in mkdir
    self.parent.mkdir(parents=True, exist_ok=True)
  File "/usr/lib/python3.10/pathlib.py", line 1179, in mkdir
    self.parent.mkdir(parents=True, exist_ok=True)
  File "/usr/lib/python3.10/pathlib.py", line 1175, in mkdir
    self._accessor.mkdir(self, mode)
PermissionError: [Errno 13] Permission denied: '/Documents'
[2024-09-15 20:11:47,039] {taskinstance.py:1395} INFO - Marking task as FAILED. dag_id=BRONZER_GET_STONCKS, task_id=BRONZE_TSLA, execution_date=20240120T000000, start_date=20240915T231146, end_date=20240915T231147
[2024-09-15 20:11:47,048] {standard_task_runner.py:92} ERROR - Failed to execute job 119 for task BRONZE_TSLA ([Errno 13] Permission denied: '/Documents'; 12995)
[2024-09-15 20:11:47,057] {local_task_job.py:156} INFO - Task exited with return code 1
[2024-09-15 20:11:47,066] {local_task_job.py:273} INFO - 0 downstream tasks scheduled from follow-on schedule check
[2024-09-15 23:27:59,609] {taskinstance.py:1159} INFO - Dependencies all met for <TaskInstance: BRONZER_GET_STONCKS.BRONZE_TSLA scheduled__2024-01-20T00:00:00+00:00 [queued]>
[2024-09-15 23:27:59,614] {taskinstance.py:1159} INFO - Dependencies all met for <TaskInstance: BRONZER_GET_STONCKS.BRONZE_TSLA scheduled__2024-01-20T00:00:00+00:00 [queued]>
[2024-09-15 23:27:59,614] {taskinstance.py:1356} INFO - 
--------------------------------------------------------------------------------
[2024-09-15 23:27:59,614] {taskinstance.py:1357} INFO - Starting attempt 1 of 1
[2024-09-15 23:27:59,614] {taskinstance.py:1358} INFO - 
--------------------------------------------------------------------------------
[2024-09-15 23:27:59,624] {taskinstance.py:1377} INFO - Executing <Task(_PythonDecoratedOperator): BRONZE_TSLA> on 2024-01-20 00:00:00+00:00
[2024-09-15 23:27:59,627] {standard_task_runner.py:52} INFO - Started process 14333 to run task
[2024-09-15 23:27:59,629] {standard_task_runner.py:79} INFO - Running: ['airflow', 'tasks', 'run', 'BRONZER_GET_STONCKS', 'BRONZE_TSLA', 'scheduled__2024-01-20T00:00:00+00:00', '--job-id', '119', '--raw', '--subdir', 'DAGS_FOLDER/get_stocks.py', '--cfg-path', '/tmp/tmpxu44pb2f', '--error-file', '/tmp/tmp21smc4oo']
[2024-09-15 23:27:59,630] {standard_task_runner.py:80} INFO - Job 119: Subtask BRONZE_TSLA
[2024-09-15 23:27:59,660] {task_command.py:370} INFO - Running <TaskInstance: BRONZER_GET_STONCKS.BRONZE_TSLA scheduled__2024-01-20T00:00:00+00:00 [running]> on host kaiwang.
[2024-09-15 23:27:59,700] {taskinstance.py:1569} INFO - Exporting the following env vars:
AIRFLOW_CTX_DAG_OWNER=airflow
AIRFLOW_CTX_DAG_ID=BRONZER_GET_STONCKS
AIRFLOW_CTX_TASK_ID=BRONZE_TSLA
AIRFLOW_CTX_EXECUTION_DATE=2024-01-20T00:00:00+00:00
AIRFLOW_CTX_TRY_NUMBER=1
AIRFLOW_CTX_DAG_RUN_ID=scheduled__2024-01-20T00:00:00+00:00
[2024-09-15 23:28:02,743] {history.py:244} ERROR - $TSLA: possibly delisted; no price data found  (1h 2024-01-17 -> 2024-01-03) (Yahoo error = "Invalid input - start date cannot be after end date. startDate = 1705467600, endDate = 1704258000")
[2024-09-15 23:28:02,745] {python.py:173} INFO - Done. Returned value was: None
[2024-09-15 23:28:02,750] {taskinstance.py:1395} INFO - Marking task as SUCCESS. dag_id=BRONZER_GET_STONCKS, task_id=BRONZE_TSLA, execution_date=20240120T000000, start_date=20240916T022759, end_date=20240916T022802
[2024-09-15 23:28:02,779] {local_task_job.py:156} INFO - Task exited with return code 0
[2024-09-15 23:28:02,788] {local_task_job.py:273} INFO - 0 downstream tasks scheduled from follow-on schedule check
