[2024-09-15 20:04:07,708] {taskinstance.py:1159} INFO - Dependencies all met for <TaskInstance: BRONZER_GET_STONCKS.BRONZE_GOOG scheduled__2024-01-16T00:00:00+00:00 [queued]>
[2024-09-15 20:04:07,712] {taskinstance.py:1159} INFO - Dependencies all met for <TaskInstance: BRONZER_GET_STONCKS.BRONZE_GOOG scheduled__2024-01-16T00:00:00+00:00 [queued]>
[2024-09-15 20:04:07,712] {taskinstance.py:1356} INFO - 
--------------------------------------------------------------------------------
[2024-09-15 20:04:07,712] {taskinstance.py:1357} INFO - Starting attempt 1 of 1
[2024-09-15 20:04:07,712] {taskinstance.py:1358} INFO - 
--------------------------------------------------------------------------------
[2024-09-15 20:04:07,723] {taskinstance.py:1377} INFO - Executing <Task(_PythonDecoratedOperator): BRONZE_GOOG> on 2024-01-16 00:00:00+00:00
[2024-09-15 20:04:07,725] {standard_task_runner.py:52} INFO - Started process 11504 to run task
[2024-09-15 20:04:07,727] {standard_task_runner.py:79} INFO - Running: ['airflow', 'tasks', 'run', 'BRONZER_GET_STONCKS', 'BRONZE_GOOG', 'scheduled__2024-01-16T00:00:00+00:00', '--job-id', '51', '--raw', '--subdir', 'DAGS_FOLDER/get_stocks.py', '--cfg-path', '/tmp/tmp__zfhm0c', '--error-file', '/tmp/tmpd69kx1w0']
[2024-09-15 20:04:07,728] {standard_task_runner.py:80} INFO - Job 51: Subtask BRONZE_GOOG
[2024-09-15 20:04:07,755] {task_command.py:370} INFO - Running <TaskInstance: BRONZER_GET_STONCKS.BRONZE_GOOG scheduled__2024-01-16T00:00:00+00:00 [running]> on host kaiwang.
[2024-09-15 20:04:07,796] {taskinstance.py:1569} INFO - Exporting the following env vars:
AIRFLOW_CTX_DAG_OWNER=airflow
AIRFLOW_CTX_DAG_ID=BRONZER_GET_STONCKS
AIRFLOW_CTX_TASK_ID=BRONZE_GOOG
AIRFLOW_CTX_EXECUTION_DATE=2024-01-16T00:00:00+00:00
AIRFLOW_CTX_TRY_NUMBER=1
AIRFLOW_CTX_DAG_RUN_ID=scheduled__2024-01-16T00:00:00+00:00
[2024-09-15 20:04:07,797] {taskinstance.py:1889} ERROR - Task failed with exception
Traceback (most recent call last):
  File "/usr/lib/python3.10/pathlib.py", line 1175, in mkdir
    self._accessor.mkdir(self, mode)
FileNotFoundError: [Errno 2] No such file or directory: '/datalake/GOOG'

During handling of the above exception, another exception occurred:

Traceback (most recent call last):
  File "/home/kaiwang/Documents/airflow_celeby/venv/lib/python3.10/site-packages/airflow/decorators/base.py", line 179, in execute
    return_value = super().execute(context)
  File "/home/kaiwang/Documents/airflow_celeby/venv/lib/python3.10/site-packages/airflow/operators/python.py", line 171, in execute
    return_value = self.execute_callable()
  File "/home/kaiwang/Documents/airflow_celeby/venv/lib/python3.10/site-packages/airflow/operators/python.py", line 189, in execute_callable
    return self.python_callable(*self.op_args, **self.op_kwargs)
  File "/home/kaiwang/Documents/airflow_celeby/dags/get_stocks.py", line 21, in get_history
    (Path(file_path).parent).mkdir(parents=True, exist_ok=True)
  File "/usr/lib/python3.10/pathlib.py", line 1179, in mkdir
    self.parent.mkdir(parents=True, exist_ok=True)
  File "/usr/lib/python3.10/pathlib.py", line 1175, in mkdir
    self._accessor.mkdir(self, mode)
PermissionError: [Errno 13] Permission denied: '/datalake'
[2024-09-15 20:04:07,800] {taskinstance.py:1395} INFO - Marking task as FAILED. dag_id=BRONZER_GET_STONCKS, task_id=BRONZE_GOOG, execution_date=20240116T000000, start_date=20240915T230407, end_date=20240915T230407
[2024-09-15 20:04:07,808] {standard_task_runner.py:92} ERROR - Failed to execute job 51 for task BRONZE_GOOG ([Errno 13] Permission denied: '/datalake'; 11504)
[2024-09-15 20:04:07,820] {local_task_job.py:156} INFO - Task exited with return code 1
[2024-09-15 20:04:07,829] {local_task_job.py:273} INFO - 0 downstream tasks scheduled from follow-on schedule check
[2024-09-15 20:06:56,957] {taskinstance.py:1159} INFO - Dependencies all met for <TaskInstance: BRONZER_GET_STONCKS.BRONZE_GOOG scheduled__2024-01-16T00:00:00+00:00 [queued]>
[2024-09-15 20:06:56,961] {taskinstance.py:1159} INFO - Dependencies all met for <TaskInstance: BRONZER_GET_STONCKS.BRONZE_GOOG scheduled__2024-01-16T00:00:00+00:00 [queued]>
[2024-09-15 20:06:56,962] {taskinstance.py:1356} INFO - 
--------------------------------------------------------------------------------
[2024-09-15 20:06:56,962] {taskinstance.py:1357} INFO - Starting attempt 1 of 1
[2024-09-15 20:06:56,962] {taskinstance.py:1358} INFO - 
--------------------------------------------------------------------------------
[2024-09-15 20:06:56,972] {taskinstance.py:1377} INFO - Executing <Task(_PythonDecoratedOperator): BRONZE_GOOG> on 2024-01-16 00:00:00+00:00
[2024-09-15 20:06:56,974] {standard_task_runner.py:52} INFO - Started process 12220 to run task
[2024-09-15 20:06:56,977] {standard_task_runner.py:79} INFO - Running: ['airflow', 'tasks', 'run', 'BRONZER_GET_STONCKS', 'BRONZE_GOOG', 'scheduled__2024-01-16T00:00:00+00:00', '--job-id', '53', '--raw', '--subdir', 'DAGS_FOLDER/get_stocks.py', '--cfg-path', '/tmp/tmpcxusg4ug', '--error-file', '/tmp/tmphq19_h6x']
[2024-09-15 20:06:56,977] {standard_task_runner.py:80} INFO - Job 53: Subtask BRONZE_GOOG
[2024-09-15 20:06:57,004] {task_command.py:370} INFO - Running <TaskInstance: BRONZER_GET_STONCKS.BRONZE_GOOG scheduled__2024-01-16T00:00:00+00:00 [running]> on host kaiwang.
[2024-09-15 20:06:57,041] {taskinstance.py:1569} INFO - Exporting the following env vars:
AIRFLOW_CTX_DAG_OWNER=airflow
AIRFLOW_CTX_DAG_ID=BRONZER_GET_STONCKS
AIRFLOW_CTX_TASK_ID=BRONZE_GOOG
AIRFLOW_CTX_EXECUTION_DATE=2024-01-16T00:00:00+00:00
AIRFLOW_CTX_TRY_NUMBER=1
AIRFLOW_CTX_DAG_RUN_ID=scheduled__2024-01-16T00:00:00+00:00
[2024-09-15 20:07:00,799] {history.py:244} ERROR - $GOOG: possibly delisted; no price data found  (1h 2024-01-13 -> 2024-01-03) (Yahoo error = "Invalid input - start date cannot be after end date. startDate = 1705122000, endDate = 1704258000")
[2024-09-15 20:07:00,804] {python.py:173} INFO - Done. Returned value was: None
[2024-09-15 20:07:00,810] {taskinstance.py:1395} INFO - Marking task as SUCCESS. dag_id=BRONZER_GET_STONCKS, task_id=BRONZE_GOOG, execution_date=20240116T000000, start_date=20240915T230656, end_date=20240915T230700
[2024-09-15 20:07:00,851] {local_task_job.py:156} INFO - Task exited with return code 0
[2024-09-15 20:07:00,864] {local_task_job.py:273} INFO - 0 downstream tasks scheduled from follow-on schedule check
[2024-09-15 20:11:06,315] {taskinstance.py:1159} INFO - Dependencies all met for <TaskInstance: BRONZER_GET_STONCKS.BRONZE_GOOG scheduled__2024-01-16T00:00:00+00:00 [queued]>
[2024-09-15 20:11:06,320] {taskinstance.py:1159} INFO - Dependencies all met for <TaskInstance: BRONZER_GET_STONCKS.BRONZE_GOOG scheduled__2024-01-16T00:00:00+00:00 [queued]>
[2024-09-15 20:11:06,320] {taskinstance.py:1356} INFO - 
--------------------------------------------------------------------------------
[2024-09-15 20:11:06,320] {taskinstance.py:1357} INFO - Starting attempt 1 of 1
[2024-09-15 20:11:06,320] {taskinstance.py:1358} INFO - 
--------------------------------------------------------------------------------
[2024-09-15 20:11:06,333] {taskinstance.py:1377} INFO - Executing <Task(_PythonDecoratedOperator): BRONZE_GOOG> on 2024-01-16 00:00:00+00:00
[2024-09-15 20:11:06,335] {standard_task_runner.py:52} INFO - Started process 12831 to run task
[2024-09-15 20:11:06,338] {standard_task_runner.py:79} INFO - Running: ['airflow', 'tasks', 'run', 'BRONZER_GET_STONCKS', 'BRONZE_GOOG', 'scheduled__2024-01-16T00:00:00+00:00', '--job-id', '102', '--raw', '--subdir', 'DAGS_FOLDER/get_stocks.py', '--cfg-path', '/tmp/tmpj1bb0woj', '--error-file', '/tmp/tmptqkdb1qn']
[2024-09-15 20:11:06,338] {standard_task_runner.py:80} INFO - Job 102: Subtask BRONZE_GOOG
[2024-09-15 20:11:06,369] {task_command.py:370} INFO - Running <TaskInstance: BRONZER_GET_STONCKS.BRONZE_GOOG scheduled__2024-01-16T00:00:00+00:00 [running]> on host kaiwang.
[2024-09-15 20:11:06,416] {taskinstance.py:1569} INFO - Exporting the following env vars:
AIRFLOW_CTX_DAG_OWNER=airflow
AIRFLOW_CTX_DAG_ID=BRONZER_GET_STONCKS
AIRFLOW_CTX_TASK_ID=BRONZE_GOOG
AIRFLOW_CTX_EXECUTION_DATE=2024-01-16T00:00:00+00:00
AIRFLOW_CTX_TRY_NUMBER=1
AIRFLOW_CTX_DAG_RUN_ID=scheduled__2024-01-16T00:00:00+00:00
[2024-09-15 20:11:06,417] {taskinstance.py:1889} ERROR - Task failed with exception
Traceback (most recent call last):
  File "/usr/lib/python3.10/pathlib.py", line 1175, in mkdir
    self._accessor.mkdir(self, mode)
FileNotFoundError: [Errno 2] No such file or directory: '/datalake/GOOG'

During handling of the above exception, another exception occurred:

Traceback (most recent call last):
  File "/home/kaiwang/Documents/airflow_celeby/venv/lib/python3.10/site-packages/airflow/decorators/base.py", line 179, in execute
    return_value = super().execute(context)
  File "/home/kaiwang/Documents/airflow_celeby/venv/lib/python3.10/site-packages/airflow/operators/python.py", line 171, in execute
    return_value = self.execute_callable()
  File "/home/kaiwang/Documents/airflow_celeby/venv/lib/python3.10/site-packages/airflow/operators/python.py", line 189, in execute_callable
    return self.python_callable(*self.op_args, **self.op_kwargs)
  File "/home/kaiwang/Documents/airflow_celeby/dags/get_stocks.py", line 21, in get_history
    (Path(file_path).parent).mkdir(parents=True, exist_ok=True)
  File "/usr/lib/python3.10/pathlib.py", line 1179, in mkdir
    self.parent.mkdir(parents=True, exist_ok=True)
  File "/usr/lib/python3.10/pathlib.py", line 1175, in mkdir
    self._accessor.mkdir(self, mode)
PermissionError: [Errno 13] Permission denied: '/datalake'
[2024-09-15 20:11:06,419] {taskinstance.py:1395} INFO - Marking task as FAILED. dag_id=BRONZER_GET_STONCKS, task_id=BRONZE_GOOG, execution_date=20240116T000000, start_date=20240915T231106, end_date=20240915T231106
[2024-09-15 20:11:06,429] {standard_task_runner.py:92} ERROR - Failed to execute job 102 for task BRONZE_GOOG ([Errno 13] Permission denied: '/datalake'; 12831)
[2024-09-15 20:11:06,471] {local_task_job.py:156} INFO - Task exited with return code 1
[2024-09-15 20:11:06,499] {local_task_job.py:273} INFO - 0 downstream tasks scheduled from follow-on schedule check
[2024-09-15 20:13:28,682] {taskinstance.py:1159} INFO - Dependencies all met for <TaskInstance: BRONZER_GET_STONCKS.BRONZE_GOOG scheduled__2024-01-16T00:00:00+00:00 [queued]>
[2024-09-15 20:13:28,686] {taskinstance.py:1159} INFO - Dependencies all met for <TaskInstance: BRONZER_GET_STONCKS.BRONZE_GOOG scheduled__2024-01-16T00:00:00+00:00 [queued]>
[2024-09-15 20:13:28,686] {taskinstance.py:1356} INFO - 
--------------------------------------------------------------------------------
[2024-09-15 20:13:28,686] {taskinstance.py:1357} INFO - Starting attempt 1 of 1
[2024-09-15 20:13:28,686] {taskinstance.py:1358} INFO - 
--------------------------------------------------------------------------------
[2024-09-15 20:13:28,696] {taskinstance.py:1377} INFO - Executing <Task(_PythonDecoratedOperator): BRONZE_GOOG> on 2024-01-16 00:00:00+00:00
[2024-09-15 20:13:28,699] {standard_task_runner.py:52} INFO - Started process 13435 to run task
[2024-09-15 20:13:28,701] {standard_task_runner.py:79} INFO - Running: ['airflow', 'tasks', 'run', 'BRONZER_GET_STONCKS', 'BRONZE_GOOG', 'scheduled__2024-01-16T00:00:00+00:00', '--job-id', '102', '--raw', '--subdir', 'DAGS_FOLDER/get_stocks.py', '--cfg-path', '/tmp/tmpf71r4rr8', '--error-file', '/tmp/tmpbm2p1vo7']
[2024-09-15 20:13:28,702] {standard_task_runner.py:80} INFO - Job 102: Subtask BRONZE_GOOG
[2024-09-15 20:13:28,731] {task_command.py:370} INFO - Running <TaskInstance: BRONZER_GET_STONCKS.BRONZE_GOOG scheduled__2024-01-16T00:00:00+00:00 [running]> on host kaiwang.
[2024-09-15 20:13:28,769] {taskinstance.py:1569} INFO - Exporting the following env vars:
AIRFLOW_CTX_DAG_OWNER=airflow
AIRFLOW_CTX_DAG_ID=BRONZER_GET_STONCKS
AIRFLOW_CTX_TASK_ID=BRONZE_GOOG
AIRFLOW_CTX_EXECUTION_DATE=2024-01-16T00:00:00+00:00
AIRFLOW_CTX_TRY_NUMBER=1
AIRFLOW_CTX_DAG_RUN_ID=scheduled__2024-01-16T00:00:00+00:00
[2024-09-15 20:13:28,770] {taskinstance.py:1889} ERROR - Task failed with exception
Traceback (most recent call last):
  File "/usr/lib/python3.10/pathlib.py", line 1175, in mkdir
    self._accessor.mkdir(self, mode)
FileNotFoundError: [Errno 2] No such file or directory: '/Documents/airflow_celeby/datalake/GOOG'

During handling of the above exception, another exception occurred:

Traceback (most recent call last):
  File "/usr/lib/python3.10/pathlib.py", line 1175, in mkdir
    self._accessor.mkdir(self, mode)
FileNotFoundError: [Errno 2] No such file or directory: '/Documents/airflow_celeby/datalake'

During handling of the above exception, another exception occurred:

Traceback (most recent call last):
  File "/usr/lib/python3.10/pathlib.py", line 1175, in mkdir
    self._accessor.mkdir(self, mode)
FileNotFoundError: [Errno 2] No such file or directory: '/Documents/airflow_celeby'

During handling of the above exception, another exception occurred:

Traceback (most recent call last):
  File "/home/kaiwang/Documents/airflow_celeby/venv/lib/python3.10/site-packages/airflow/decorators/base.py", line 179, in execute
    return_value = super().execute(context)
  File "/home/kaiwang/Documents/airflow_celeby/venv/lib/python3.10/site-packages/airflow/operators/python.py", line 171, in execute
    return_value = self.execute_callable()
  File "/home/kaiwang/Documents/airflow_celeby/venv/lib/python3.10/site-packages/airflow/operators/python.py", line 189, in execute_callable
    return self.python_callable(*self.op_args, **self.op_kwargs)
  File "/home/kaiwang/Documents/airflow_celeby/dags/get_stocks.py", line 21, in get_history
    (Path(file_path).parent).mkdir(parents=True, exist_ok=True)
  File "/usr/lib/python3.10/pathlib.py", line 1179, in mkdir
    self.parent.mkdir(parents=True, exist_ok=True)
  File "/usr/lib/python3.10/pathlib.py", line 1179, in mkdir
    self.parent.mkdir(parents=True, exist_ok=True)
  File "/usr/lib/python3.10/pathlib.py", line 1179, in mkdir
    self.parent.mkdir(parents=True, exist_ok=True)
  File "/usr/lib/python3.10/pathlib.py", line 1175, in mkdir
    self._accessor.mkdir(self, mode)
PermissionError: [Errno 13] Permission denied: '/Documents'
[2024-09-15 20:13:28,772] {taskinstance.py:1395} INFO - Marking task as FAILED. dag_id=BRONZER_GET_STONCKS, task_id=BRONZE_GOOG, execution_date=20240116T000000, start_date=20240915T231328, end_date=20240915T231328
[2024-09-15 20:13:28,781] {standard_task_runner.py:92} ERROR - Failed to execute job 102 for task BRONZE_GOOG ([Errno 13] Permission denied: '/Documents'; 13435)
[2024-09-15 20:13:28,794] {local_task_job.py:156} INFO - Task exited with return code 1
[2024-09-15 20:13:28,822] {local_task_job.py:273} INFO - 0 downstream tasks scheduled from follow-on schedule check
[2024-09-15 20:18:06,600] {taskinstance.py:1159} INFO - Dependencies all met for <TaskInstance: BRONZER_GET_STONCKS.BRONZE_GOOG scheduled__2024-01-16T00:00:00+00:00 [queued]>
[2024-09-15 20:18:06,604] {taskinstance.py:1159} INFO - Dependencies all met for <TaskInstance: BRONZER_GET_STONCKS.BRONZE_GOOG scheduled__2024-01-16T00:00:00+00:00 [queued]>
[2024-09-15 20:18:06,605] {taskinstance.py:1356} INFO - 
--------------------------------------------------------------------------------
[2024-09-15 20:18:06,605] {taskinstance.py:1357} INFO - Starting attempt 1 of 1
[2024-09-15 20:18:06,605] {taskinstance.py:1358} INFO - 
--------------------------------------------------------------------------------
[2024-09-15 20:18:06,616] {taskinstance.py:1377} INFO - Executing <Task(_PythonDecoratedOperator): BRONZE_GOOG> on 2024-01-16 00:00:00+00:00
[2024-09-15 20:18:06,618] {standard_task_runner.py:52} INFO - Started process 14097 to run task
[2024-09-15 20:18:06,620] {standard_task_runner.py:79} INFO - Running: ['airflow', 'tasks', 'run', 'BRONZER_GET_STONCKS', 'BRONZE_GOOG', 'scheduled__2024-01-16T00:00:00+00:00', '--job-id', '102', '--raw', '--subdir', 'DAGS_FOLDER/get_stocks.py', '--cfg-path', '/tmp/tmplxzsv6sk', '--error-file', '/tmp/tmpilmozy6e']
[2024-09-15 20:18:06,621] {standard_task_runner.py:80} INFO - Job 102: Subtask BRONZE_GOOG
[2024-09-15 20:18:06,650] {task_command.py:370} INFO - Running <TaskInstance: BRONZER_GET_STONCKS.BRONZE_GOOG scheduled__2024-01-16T00:00:00+00:00 [running]> on host kaiwang.
[2024-09-15 20:18:06,691] {taskinstance.py:1569} INFO - Exporting the following env vars:
AIRFLOW_CTX_DAG_OWNER=airflow
AIRFLOW_CTX_DAG_ID=BRONZER_GET_STONCKS
AIRFLOW_CTX_TASK_ID=BRONZE_GOOG
AIRFLOW_CTX_EXECUTION_DATE=2024-01-16T00:00:00+00:00
AIRFLOW_CTX_TRY_NUMBER=1
AIRFLOW_CTX_DAG_RUN_ID=scheduled__2024-01-16T00:00:00+00:00
[2024-09-15 20:18:09,857] {history.py:244} ERROR - $GOOG: possibly delisted; no price data found  (1h 2024-01-13 -> 2024-01-03) (Yahoo error = "Invalid input - start date cannot be after end date. startDate = 1705122000, endDate = 1704258000")
[2024-09-15 20:18:09,862] {python.py:173} INFO - Done. Returned value was: None
[2024-09-15 20:18:09,869] {taskinstance.py:1395} INFO - Marking task as SUCCESS. dag_id=BRONZER_GET_STONCKS, task_id=BRONZE_GOOG, execution_date=20240116T000000, start_date=20240915T231806, end_date=20240915T231809
[2024-09-15 20:18:09,901] {local_task_job.py:156} INFO - Task exited with return code 0
[2024-09-15 20:18:09,911] {local_task_job.py:273} INFO - 0 downstream tasks scheduled from follow-on schedule check
