[2024-09-15 20:03:47,752] {taskinstance.py:1159} INFO - Dependencies all met for <TaskInstance: BRONZER_GET_STONCKS.BRONZE_AAPL scheduled__2024-01-11T00:00:00+00:00 [queued]>
[2024-09-15 20:03:47,756] {taskinstance.py:1159} INFO - Dependencies all met for <TaskInstance: BRONZER_GET_STONCKS.BRONZE_AAPL scheduled__2024-01-11T00:00:00+00:00 [queued]>
[2024-09-15 20:03:47,756] {taskinstance.py:1356} INFO - 
--------------------------------------------------------------------------------
[2024-09-15 20:03:47,756] {taskinstance.py:1357} INFO - Starting attempt 1 of 1
[2024-09-15 20:03:47,756] {taskinstance.py:1358} INFO - 
--------------------------------------------------------------------------------
[2024-09-15 20:03:47,767] {taskinstance.py:1377} INFO - Executing <Task(_PythonDecoratedOperator): BRONZE_AAPL> on 2024-01-11 00:00:00+00:00
[2024-09-15 20:03:47,769] {standard_task_runner.py:52} INFO - Started process 11377 to run task
[2024-09-15 20:03:47,771] {standard_task_runner.py:79} INFO - Running: ['airflow', 'tasks', 'run', 'BRONZER_GET_STONCKS', 'BRONZE_AAPL', 'scheduled__2024-01-11T00:00:00+00:00', '--job-id', '37', '--raw', '--subdir', 'DAGS_FOLDER/get_stocks.py', '--cfg-path', '/tmp/tmpotcm6boy', '--error-file', '/tmp/tmpiqvppuwi']
[2024-09-15 20:03:47,772] {standard_task_runner.py:80} INFO - Job 37: Subtask BRONZE_AAPL
[2024-09-15 20:03:47,802] {task_command.py:370} INFO - Running <TaskInstance: BRONZER_GET_STONCKS.BRONZE_AAPL scheduled__2024-01-11T00:00:00+00:00 [running]> on host kaiwang.
[2024-09-15 20:03:47,844] {taskinstance.py:1569} INFO - Exporting the following env vars:
AIRFLOW_CTX_DAG_OWNER=airflow
AIRFLOW_CTX_DAG_ID=BRONZER_GET_STONCKS
AIRFLOW_CTX_TASK_ID=BRONZE_AAPL
AIRFLOW_CTX_EXECUTION_DATE=2024-01-11T00:00:00+00:00
AIRFLOW_CTX_TRY_NUMBER=1
AIRFLOW_CTX_DAG_RUN_ID=scheduled__2024-01-11T00:00:00+00:00
[2024-09-15 20:03:47,845] {taskinstance.py:1889} ERROR - Task failed with exception
Traceback (most recent call last):
  File "/usr/lib/python3.10/pathlib.py", line 1175, in mkdir
    self._accessor.mkdir(self, mode)
FileNotFoundError: [Errno 2] No such file or directory: '/datalake/AAPL'

During handling of the above exception, another exception occurred:

Traceback (most recent call last):
  File "/home/kaiwang/Documents/airflow_celeby/venv/lib/python3.10/site-packages/airflow/decorators/base.py", line 179, in execute
    return_value = super().execute(context)
  File "/home/kaiwang/Documents/airflow_celeby/venv/lib/python3.10/site-packages/airflow/operators/python.py", line 171, in execute
    return_value = self.execute_callable()
  File "/home/kaiwang/Documents/airflow_celeby/venv/lib/python3.10/site-packages/airflow/operators/python.py", line 189, in execute_callable
    return self.python_callable(*self.op_args, **self.op_kwargs)
  File "/home/kaiwang/Documents/airflow_celeby/dags/get_stocks.py", line 21, in get_history
    (Path(file_path).parent).mkdir(parents=True, exist_ok=True)
  File "/usr/lib/python3.10/pathlib.py", line 1179, in mkdir
    self.parent.mkdir(parents=True, exist_ok=True)
  File "/usr/lib/python3.10/pathlib.py", line 1175, in mkdir
    self._accessor.mkdir(self, mode)
PermissionError: [Errno 13] Permission denied: '/datalake'
[2024-09-15 20:03:47,847] {taskinstance.py:1395} INFO - Marking task as FAILED. dag_id=BRONZER_GET_STONCKS, task_id=BRONZE_AAPL, execution_date=20240111T000000, start_date=20240915T230347, end_date=20240915T230347
[2024-09-15 20:03:47,856] {standard_task_runner.py:92} ERROR - Failed to execute job 37 for task BRONZE_AAPL ([Errno 13] Permission denied: '/datalake'; 11377)
[2024-09-15 20:03:47,864] {local_task_job.py:156} INFO - Task exited with return code 1
[2024-09-15 20:03:47,875] {local_task_job.py:273} INFO - 0 downstream tasks scheduled from follow-on schedule check
[2024-09-15 20:06:32,591] {taskinstance.py:1159} INFO - Dependencies all met for <TaskInstance: BRONZER_GET_STONCKS.BRONZE_AAPL scheduled__2024-01-11T00:00:00+00:00 [queued]>
[2024-09-15 20:06:32,595] {taskinstance.py:1159} INFO - Dependencies all met for <TaskInstance: BRONZER_GET_STONCKS.BRONZE_AAPL scheduled__2024-01-11T00:00:00+00:00 [queued]>
[2024-09-15 20:06:32,595] {taskinstance.py:1356} INFO - 
--------------------------------------------------------------------------------
[2024-09-15 20:06:32,595] {taskinstance.py:1357} INFO - Starting attempt 1 of 1
[2024-09-15 20:06:32,595] {taskinstance.py:1358} INFO - 
--------------------------------------------------------------------------------
[2024-09-15 20:06:32,605] {taskinstance.py:1377} INFO - Executing <Task(_PythonDecoratedOperator): BRONZE_AAPL> on 2024-01-11 00:00:00+00:00
[2024-09-15 20:06:32,607] {standard_task_runner.py:52} INFO - Started process 12087 to run task
[2024-09-15 20:06:32,610] {standard_task_runner.py:79} INFO - Running: ['airflow', 'tasks', 'run', 'BRONZER_GET_STONCKS', 'BRONZE_AAPL', 'scheduled__2024-01-11T00:00:00+00:00', '--job-id', '39', '--raw', '--subdir', 'DAGS_FOLDER/get_stocks.py', '--cfg-path', '/tmp/tmpkeajujny', '--error-file', '/tmp/tmphvh2zxma']
[2024-09-15 20:06:32,610] {standard_task_runner.py:80} INFO - Job 39: Subtask BRONZE_AAPL
[2024-09-15 20:06:32,638] {task_command.py:370} INFO - Running <TaskInstance: BRONZER_GET_STONCKS.BRONZE_AAPL scheduled__2024-01-11T00:00:00+00:00 [running]> on host kaiwang.
[2024-09-15 20:06:32,678] {taskinstance.py:1569} INFO - Exporting the following env vars:
AIRFLOW_CTX_DAG_OWNER=airflow
AIRFLOW_CTX_DAG_ID=BRONZER_GET_STONCKS
AIRFLOW_CTX_TASK_ID=BRONZE_AAPL
AIRFLOW_CTX_EXECUTION_DATE=2024-01-11T00:00:00+00:00
AIRFLOW_CTX_TRY_NUMBER=1
AIRFLOW_CTX_DAG_RUN_ID=scheduled__2024-01-11T00:00:00+00:00
[2024-09-15 20:06:32,679] {taskinstance.py:1889} ERROR - Task failed with exception
Traceback (most recent call last):
  File "/usr/lib/python3.10/pathlib.py", line 1175, in mkdir
    self._accessor.mkdir(self, mode)
FileNotFoundError: [Errno 2] No such file or directory: '/datalake/AAPL'

During handling of the above exception, another exception occurred:

Traceback (most recent call last):
  File "/home/kaiwang/Documents/airflow_celeby/venv/lib/python3.10/site-packages/airflow/decorators/base.py", line 179, in execute
    return_value = super().execute(context)
  File "/home/kaiwang/Documents/airflow_celeby/venv/lib/python3.10/site-packages/airflow/operators/python.py", line 171, in execute
    return_value = self.execute_callable()
  File "/home/kaiwang/Documents/airflow_celeby/venv/lib/python3.10/site-packages/airflow/operators/python.py", line 189, in execute_callable
    return self.python_callable(*self.op_args, **self.op_kwargs)
  File "/home/kaiwang/Documents/airflow_celeby/dags/get_stocks.py", line 21, in get_history
    (Path(file_path).parent).mkdir(parents=True, exist_ok=True)
  File "/usr/lib/python3.10/pathlib.py", line 1179, in mkdir
    self.parent.mkdir(parents=True, exist_ok=True)
  File "/usr/lib/python3.10/pathlib.py", line 1175, in mkdir
    self._accessor.mkdir(self, mode)
PermissionError: [Errno 13] Permission denied: '/datalake'
[2024-09-15 20:06:32,681] {taskinstance.py:1395} INFO - Marking task as FAILED. dag_id=BRONZER_GET_STONCKS, task_id=BRONZE_AAPL, execution_date=20240111T000000, start_date=20240915T230632, end_date=20240915T230632
[2024-09-15 20:06:32,690] {standard_task_runner.py:92} ERROR - Failed to execute job 39 for task BRONZE_AAPL ([Errno 13] Permission denied: '/datalake'; 12087)
[2024-09-15 20:06:32,702] {local_task_job.py:156} INFO - Task exited with return code 1
[2024-09-15 20:06:32,712] {local_task_job.py:273} INFO - 0 downstream tasks scheduled from follow-on schedule check
[2024-09-15 20:09:55,052] {taskinstance.py:1159} INFO - Dependencies all met for <TaskInstance: BRONZER_GET_STONCKS.BRONZE_AAPL scheduled__2024-01-11T00:00:00+00:00 [queued]>
[2024-09-15 20:09:55,056] {taskinstance.py:1159} INFO - Dependencies all met for <TaskInstance: BRONZER_GET_STONCKS.BRONZE_AAPL scheduled__2024-01-11T00:00:00+00:00 [queued]>
[2024-09-15 20:09:55,056] {taskinstance.py:1356} INFO - 
--------------------------------------------------------------------------------
[2024-09-15 20:09:55,056] {taskinstance.py:1357} INFO - Starting attempt 1 of 1
[2024-09-15 20:09:55,056] {taskinstance.py:1358} INFO - 
--------------------------------------------------------------------------------
[2024-09-15 20:09:55,068] {taskinstance.py:1377} INFO - Executing <Task(_PythonDecoratedOperator): BRONZE_AAPL> on 2024-01-11 00:00:00+00:00
[2024-09-15 20:09:55,070] {standard_task_runner.py:52} INFO - Started process 12683 to run task
[2024-09-15 20:09:55,072] {standard_task_runner.py:79} INFO - Running: ['airflow', 'tasks', 'run', 'BRONZER_GET_STONCKS', 'BRONZE_AAPL', 'scheduled__2024-01-11T00:00:00+00:00', '--job-id', '88', '--raw', '--subdir', 'DAGS_FOLDER/get_stocks.py', '--cfg-path', '/tmp/tmpz_bk5v0u', '--error-file', '/tmp/tmpq86t3x4r']
[2024-09-15 20:09:55,073] {standard_task_runner.py:80} INFO - Job 88: Subtask BRONZE_AAPL
[2024-09-15 20:09:55,100] {task_command.py:370} INFO - Running <TaskInstance: BRONZER_GET_STONCKS.BRONZE_AAPL scheduled__2024-01-11T00:00:00+00:00 [running]> on host kaiwang.
[2024-09-15 20:09:55,140] {taskinstance.py:1569} INFO - Exporting the following env vars:
AIRFLOW_CTX_DAG_OWNER=airflow
AIRFLOW_CTX_DAG_ID=BRONZER_GET_STONCKS
AIRFLOW_CTX_TASK_ID=BRONZE_AAPL
AIRFLOW_CTX_EXECUTION_DATE=2024-01-11T00:00:00+00:00
AIRFLOW_CTX_TRY_NUMBER=1
AIRFLOW_CTX_DAG_RUN_ID=scheduled__2024-01-11T00:00:00+00:00
[2024-09-15 20:09:59,091] {history.py:244} ERROR - $AAPL: possibly delisted; no price data found  (1h 2024-01-08 -> 2024-01-03) (Yahoo error = "Invalid input - start date cannot be after end date. startDate = 1704690000, endDate = 1704258000")
[2024-09-15 20:09:59,093] {python.py:173} INFO - Done. Returned value was: None
[2024-09-15 20:09:59,097] {taskinstance.py:1395} INFO - Marking task as SUCCESS. dag_id=BRONZER_GET_STONCKS, task_id=BRONZE_AAPL, execution_date=20240111T000000, start_date=20240915T230955, end_date=20240915T230959
[2024-09-15 20:09:59,148] {local_task_job.py:156} INFO - Task exited with return code 0
[2024-09-15 20:09:59,158] {local_task_job.py:273} INFO - 0 downstream tasks scheduled from follow-on schedule check
[2024-09-15 20:13:08,551] {taskinstance.py:1159} INFO - Dependencies all met for <TaskInstance: BRONZER_GET_STONCKS.BRONZE_AAPL scheduled__2024-01-11T00:00:00+00:00 [queued]>
[2024-09-15 20:13:08,557] {taskinstance.py:1159} INFO - Dependencies all met for <TaskInstance: BRONZER_GET_STONCKS.BRONZE_AAPL scheduled__2024-01-11T00:00:00+00:00 [queued]>
[2024-09-15 20:13:08,557] {taskinstance.py:1356} INFO - 
--------------------------------------------------------------------------------
[2024-09-15 20:13:08,557] {taskinstance.py:1357} INFO - Starting attempt 1 of 1
[2024-09-15 20:13:08,558] {taskinstance.py:1358} INFO - 
--------------------------------------------------------------------------------
[2024-09-15 20:13:08,569] {taskinstance.py:1377} INFO - Executing <Task(_PythonDecoratedOperator): BRONZE_AAPL> on 2024-01-11 00:00:00+00:00
[2024-09-15 20:13:08,572] {standard_task_runner.py:52} INFO - Started process 13307 to run task
[2024-09-15 20:13:08,574] {standard_task_runner.py:79} INFO - Running: ['airflow', 'tasks', 'run', 'BRONZER_GET_STONCKS', 'BRONZE_AAPL', 'scheduled__2024-01-11T00:00:00+00:00', '--job-id', '88', '--raw', '--subdir', 'DAGS_FOLDER/get_stocks.py', '--cfg-path', '/tmp/tmpw3m80qoj', '--error-file', '/tmp/tmp4kxoz3rj']
[2024-09-15 20:13:08,574] {standard_task_runner.py:80} INFO - Job 88: Subtask BRONZE_AAPL
[2024-09-15 20:13:08,601] {task_command.py:370} INFO - Running <TaskInstance: BRONZER_GET_STONCKS.BRONZE_AAPL scheduled__2024-01-11T00:00:00+00:00 [running]> on host kaiwang.
[2024-09-15 20:13:08,642] {taskinstance.py:1569} INFO - Exporting the following env vars:
AIRFLOW_CTX_DAG_OWNER=airflow
AIRFLOW_CTX_DAG_ID=BRONZER_GET_STONCKS
AIRFLOW_CTX_TASK_ID=BRONZE_AAPL
AIRFLOW_CTX_EXECUTION_DATE=2024-01-11T00:00:00+00:00
AIRFLOW_CTX_TRY_NUMBER=1
AIRFLOW_CTX_DAG_RUN_ID=scheduled__2024-01-11T00:00:00+00:00
[2024-09-15 20:13:08,643] {taskinstance.py:1889} ERROR - Task failed with exception
Traceback (most recent call last):
  File "/usr/lib/python3.10/pathlib.py", line 1175, in mkdir
    self._accessor.mkdir(self, mode)
FileNotFoundError: [Errno 2] No such file or directory: '/Documents/airflow_celeby/datalake/AAPL'

During handling of the above exception, another exception occurred:

Traceback (most recent call last):
  File "/usr/lib/python3.10/pathlib.py", line 1175, in mkdir
    self._accessor.mkdir(self, mode)
FileNotFoundError: [Errno 2] No such file or directory: '/Documents/airflow_celeby/datalake'

During handling of the above exception, another exception occurred:

Traceback (most recent call last):
  File "/usr/lib/python3.10/pathlib.py", line 1175, in mkdir
    self._accessor.mkdir(self, mode)
FileNotFoundError: [Errno 2] No such file or directory: '/Documents/airflow_celeby'

During handling of the above exception, another exception occurred:

Traceback (most recent call last):
  File "/home/kaiwang/Documents/airflow_celeby/venv/lib/python3.10/site-packages/airflow/decorators/base.py", line 179, in execute
    return_value = super().execute(context)
  File "/home/kaiwang/Documents/airflow_celeby/venv/lib/python3.10/site-packages/airflow/operators/python.py", line 171, in execute
    return_value = self.execute_callable()
  File "/home/kaiwang/Documents/airflow_celeby/venv/lib/python3.10/site-packages/airflow/operators/python.py", line 189, in execute_callable
    return self.python_callable(*self.op_args, **self.op_kwargs)
  File "/home/kaiwang/Documents/airflow_celeby/dags/get_stocks.py", line 21, in get_history
    (Path(file_path).parent).mkdir(parents=True, exist_ok=True)
  File "/usr/lib/python3.10/pathlib.py", line 1179, in mkdir
    self.parent.mkdir(parents=True, exist_ok=True)
  File "/usr/lib/python3.10/pathlib.py", line 1179, in mkdir
    self.parent.mkdir(parents=True, exist_ok=True)
  File "/usr/lib/python3.10/pathlib.py", line 1179, in mkdir
    self.parent.mkdir(parents=True, exist_ok=True)
  File "/usr/lib/python3.10/pathlib.py", line 1175, in mkdir
    self._accessor.mkdir(self, mode)
PermissionError: [Errno 13] Permission denied: '/Documents'
[2024-09-15 20:13:08,645] {taskinstance.py:1395} INFO - Marking task as FAILED. dag_id=BRONZER_GET_STONCKS, task_id=BRONZE_AAPL, execution_date=20240111T000000, start_date=20240915T231308, end_date=20240915T231308
[2024-09-15 20:13:08,657] {standard_task_runner.py:92} ERROR - Failed to execute job 88 for task BRONZE_AAPL ([Errno 13] Permission denied: '/Documents'; 13307)
[2024-09-15 20:13:08,667] {local_task_job.py:156} INFO - Task exited with return code 1
[2024-09-15 20:13:08,676] {local_task_job.py:273} INFO - 0 downstream tasks scheduled from follow-on schedule check
[2024-09-15 20:16:57,761] {taskinstance.py:1159} INFO - Dependencies all met for <TaskInstance: BRONZER_GET_STONCKS.BRONZE_AAPL scheduled__2024-01-11T00:00:00+00:00 [queued]>
[2024-09-15 20:16:57,765] {taskinstance.py:1159} INFO - Dependencies all met for <TaskInstance: BRONZER_GET_STONCKS.BRONZE_AAPL scheduled__2024-01-11T00:00:00+00:00 [queued]>
[2024-09-15 20:16:57,765] {taskinstance.py:1356} INFO - 
--------------------------------------------------------------------------------
[2024-09-15 20:16:57,765] {taskinstance.py:1357} INFO - Starting attempt 1 of 1
[2024-09-15 20:16:57,765] {taskinstance.py:1358} INFO - 
--------------------------------------------------------------------------------
[2024-09-15 20:16:57,776] {taskinstance.py:1377} INFO - Executing <Task(_PythonDecoratedOperator): BRONZE_AAPL> on 2024-01-11 00:00:00+00:00
[2024-09-15 20:16:57,778] {standard_task_runner.py:52} INFO - Started process 13966 to run task
[2024-09-15 20:16:57,780] {standard_task_runner.py:79} INFO - Running: ['airflow', 'tasks', 'run', 'BRONZER_GET_STONCKS', 'BRONZE_AAPL', 'scheduled__2024-01-11T00:00:00+00:00', '--job-id', '88', '--raw', '--subdir', 'DAGS_FOLDER/get_stocks.py', '--cfg-path', '/tmp/tmpbo_tl3cd', '--error-file', '/tmp/tmp8ntz1as_']
[2024-09-15 20:16:57,781] {standard_task_runner.py:80} INFO - Job 88: Subtask BRONZE_AAPL
[2024-09-15 20:16:57,809] {task_command.py:370} INFO - Running <TaskInstance: BRONZER_GET_STONCKS.BRONZE_AAPL scheduled__2024-01-11T00:00:00+00:00 [running]> on host kaiwang.
[2024-09-15 20:16:57,849] {taskinstance.py:1569} INFO - Exporting the following env vars:
AIRFLOW_CTX_DAG_OWNER=airflow
AIRFLOW_CTX_DAG_ID=BRONZER_GET_STONCKS
AIRFLOW_CTX_TASK_ID=BRONZE_AAPL
AIRFLOW_CTX_EXECUTION_DATE=2024-01-11T00:00:00+00:00
AIRFLOW_CTX_TRY_NUMBER=1
AIRFLOW_CTX_DAG_RUN_ID=scheduled__2024-01-11T00:00:00+00:00
[2024-09-15 20:17:02,390] {history.py:244} ERROR - $AAPL: possibly delisted; no price data found  (1h 2024-01-08 -> 2024-01-03) (Yahoo error = "Invalid input - start date cannot be after end date. startDate = 1704690000, endDate = 1704258000")
[2024-09-15 20:17:02,393] {python.py:173} INFO - Done. Returned value was: None
[2024-09-15 20:17:02,398] {taskinstance.py:1395} INFO - Marking task as SUCCESS. dag_id=BRONZER_GET_STONCKS, task_id=BRONZE_AAPL, execution_date=20240111T000000, start_date=20240915T231657, end_date=20240915T231702
[2024-09-15 20:17:02,425] {local_task_job.py:156} INFO - Task exited with return code 0
[2024-09-15 20:17:02,438] {local_task_job.py:273} INFO - 0 downstream tasks scheduled from follow-on schedule check
