[2024-09-15 20:03:56,600] {taskinstance.py:1159} INFO - Dependencies all met for <TaskInstance: BRONZER_GET_STONCKS.BRONZE_GOOG scheduled__2024-01-12T00:00:00+00:00 [queued]>
[2024-09-15 20:03:56,604] {taskinstance.py:1159} INFO - Dependencies all met for <TaskInstance: BRONZER_GET_STONCKS.BRONZE_GOOG scheduled__2024-01-12T00:00:00+00:00 [queued]>
[2024-09-15 20:03:56,605] {taskinstance.py:1356} INFO - 
--------------------------------------------------------------------------------
[2024-09-15 20:03:56,605] {taskinstance.py:1357} INFO - Starting attempt 1 of 1
[2024-09-15 20:03:56,605] {taskinstance.py:1358} INFO - 
--------------------------------------------------------------------------------
[2024-09-15 20:03:56,615] {taskinstance.py:1377} INFO - Executing <Task(_PythonDecoratedOperator): BRONZE_GOOG> on 2024-01-12 00:00:00+00:00
[2024-09-15 20:03:56,617] {standard_task_runner.py:52} INFO - Started process 11432 to run task
[2024-09-15 20:03:56,620] {standard_task_runner.py:79} INFO - Running: ['airflow', 'tasks', 'run', 'BRONZER_GET_STONCKS', 'BRONZE_GOOG', 'scheduled__2024-01-12T00:00:00+00:00', '--job-id', '43', '--raw', '--subdir', 'DAGS_FOLDER/get_stocks.py', '--cfg-path', '/tmp/tmpmyo7zhpl', '--error-file', '/tmp/tmpf76xcex5']
[2024-09-15 20:03:56,620] {standard_task_runner.py:80} INFO - Job 43: Subtask BRONZE_GOOG
[2024-09-15 20:03:56,650] {task_command.py:370} INFO - Running <TaskInstance: BRONZER_GET_STONCKS.BRONZE_GOOG scheduled__2024-01-12T00:00:00+00:00 [running]> on host kaiwang.
[2024-09-15 20:03:56,688] {taskinstance.py:1569} INFO - Exporting the following env vars:
AIRFLOW_CTX_DAG_OWNER=airflow
AIRFLOW_CTX_DAG_ID=BRONZER_GET_STONCKS
AIRFLOW_CTX_TASK_ID=BRONZE_GOOG
AIRFLOW_CTX_EXECUTION_DATE=2024-01-12T00:00:00+00:00
AIRFLOW_CTX_TRY_NUMBER=1
AIRFLOW_CTX_DAG_RUN_ID=scheduled__2024-01-12T00:00:00+00:00
[2024-09-15 20:03:56,689] {taskinstance.py:1889} ERROR - Task failed with exception
Traceback (most recent call last):
  File "/usr/lib/python3.10/pathlib.py", line 1175, in mkdir
    self._accessor.mkdir(self, mode)
FileNotFoundError: [Errno 2] No such file or directory: '/datalake/GOOG'

During handling of the above exception, another exception occurred:

Traceback (most recent call last):
  File "/home/kaiwang/Documents/airflow_celeby/venv/lib/python3.10/site-packages/airflow/decorators/base.py", line 179, in execute
    return_value = super().execute(context)
  File "/home/kaiwang/Documents/airflow_celeby/venv/lib/python3.10/site-packages/airflow/operators/python.py", line 171, in execute
    return_value = self.execute_callable()
  File "/home/kaiwang/Documents/airflow_celeby/venv/lib/python3.10/site-packages/airflow/operators/python.py", line 189, in execute_callable
    return self.python_callable(*self.op_args, **self.op_kwargs)
  File "/home/kaiwang/Documents/airflow_celeby/dags/get_stocks.py", line 21, in get_history
    (Path(file_path).parent).mkdir(parents=True, exist_ok=True)
  File "/usr/lib/python3.10/pathlib.py", line 1179, in mkdir
    self.parent.mkdir(parents=True, exist_ok=True)
  File "/usr/lib/python3.10/pathlib.py", line 1175, in mkdir
    self._accessor.mkdir(self, mode)
PermissionError: [Errno 13] Permission denied: '/datalake'
[2024-09-15 20:03:56,691] {taskinstance.py:1395} INFO - Marking task as FAILED. dag_id=BRONZER_GET_STONCKS, task_id=BRONZE_GOOG, execution_date=20240112T000000, start_date=20240915T230356, end_date=20240915T230356
[2024-09-15 20:03:56,699] {standard_task_runner.py:92} ERROR - Failed to execute job 43 for task BRONZE_GOOG ([Errno 13] Permission denied: '/datalake'; 11432)
[2024-09-15 20:03:56,712] {local_task_job.py:156} INFO - Task exited with return code 1
[2024-09-15 20:03:56,722] {local_task_job.py:273} INFO - 0 downstream tasks scheduled from follow-on schedule check
[2024-09-15 20:06:41,226] {taskinstance.py:1159} INFO - Dependencies all met for <TaskInstance: BRONZER_GET_STONCKS.BRONZE_GOOG scheduled__2024-01-12T00:00:00+00:00 [queued]>
[2024-09-15 20:06:41,231] {taskinstance.py:1159} INFO - Dependencies all met for <TaskInstance: BRONZER_GET_STONCKS.BRONZE_GOOG scheduled__2024-01-12T00:00:00+00:00 [queued]>
[2024-09-15 20:06:41,231] {taskinstance.py:1356} INFO - 
--------------------------------------------------------------------------------
[2024-09-15 20:06:41,231] {taskinstance.py:1357} INFO - Starting attempt 1 of 1
[2024-09-15 20:06:41,231] {taskinstance.py:1358} INFO - 
--------------------------------------------------------------------------------
[2024-09-15 20:06:41,243] {taskinstance.py:1377} INFO - Executing <Task(_PythonDecoratedOperator): BRONZE_GOOG> on 2024-01-12 00:00:00+00:00
[2024-09-15 20:06:41,245] {standard_task_runner.py:52} INFO - Started process 12141 to run task
[2024-09-15 20:06:41,247] {standard_task_runner.py:79} INFO - Running: ['airflow', 'tasks', 'run', 'BRONZER_GET_STONCKS', 'BRONZE_GOOG', 'scheduled__2024-01-12T00:00:00+00:00', '--job-id', '45', '--raw', '--subdir', 'DAGS_FOLDER/get_stocks.py', '--cfg-path', '/tmp/tmpl08amrmu', '--error-file', '/tmp/tmppo1r79gv']
[2024-09-15 20:06:41,247] {standard_task_runner.py:80} INFO - Job 45: Subtask BRONZE_GOOG
[2024-09-15 20:06:41,275] {task_command.py:370} INFO - Running <TaskInstance: BRONZER_GET_STONCKS.BRONZE_GOOG scheduled__2024-01-12T00:00:00+00:00 [running]> on host kaiwang.
[2024-09-15 20:06:41,312] {taskinstance.py:1569} INFO - Exporting the following env vars:
AIRFLOW_CTX_DAG_OWNER=airflow
AIRFLOW_CTX_DAG_ID=BRONZER_GET_STONCKS
AIRFLOW_CTX_TASK_ID=BRONZE_GOOG
AIRFLOW_CTX_EXECUTION_DATE=2024-01-12T00:00:00+00:00
AIRFLOW_CTX_TRY_NUMBER=1
AIRFLOW_CTX_DAG_RUN_ID=scheduled__2024-01-12T00:00:00+00:00
[2024-09-15 20:06:41,313] {taskinstance.py:1889} ERROR - Task failed with exception
Traceback (most recent call last):
  File "/usr/lib/python3.10/pathlib.py", line 1175, in mkdir
    self._accessor.mkdir(self, mode)
FileNotFoundError: [Errno 2] No such file or directory: '/datalake/GOOG'

During handling of the above exception, another exception occurred:

Traceback (most recent call last):
  File "/home/kaiwang/Documents/airflow_celeby/venv/lib/python3.10/site-packages/airflow/decorators/base.py", line 179, in execute
    return_value = super().execute(context)
  File "/home/kaiwang/Documents/airflow_celeby/venv/lib/python3.10/site-packages/airflow/operators/python.py", line 171, in execute
    return_value = self.execute_callable()
  File "/home/kaiwang/Documents/airflow_celeby/venv/lib/python3.10/site-packages/airflow/operators/python.py", line 189, in execute_callable
    return self.python_callable(*self.op_args, **self.op_kwargs)
  File "/home/kaiwang/Documents/airflow_celeby/dags/get_stocks.py", line 21, in get_history
    (Path(file_path).parent).mkdir(parents=True, exist_ok=True)
  File "/usr/lib/python3.10/pathlib.py", line 1179, in mkdir
    self.parent.mkdir(parents=True, exist_ok=True)
  File "/usr/lib/python3.10/pathlib.py", line 1175, in mkdir
    self._accessor.mkdir(self, mode)
PermissionError: [Errno 13] Permission denied: '/datalake'
[2024-09-15 20:06:41,315] {taskinstance.py:1395} INFO - Marking task as FAILED. dag_id=BRONZER_GET_STONCKS, task_id=BRONZE_GOOG, execution_date=20240112T000000, start_date=20240915T230641, end_date=20240915T230641
[2024-09-15 20:06:41,323] {standard_task_runner.py:92} ERROR - Failed to execute job 45 for task BRONZE_GOOG ([Errno 13] Permission denied: '/datalake'; 12141)
[2024-09-15 20:06:41,340] {local_task_job.py:156} INFO - Task exited with return code 1
[2024-09-15 20:06:41,349] {local_task_job.py:273} INFO - 0 downstream tasks scheduled from follow-on schedule check
[2024-09-15 20:10:27,847] {taskinstance.py:1159} INFO - Dependencies all met for <TaskInstance: BRONZER_GET_STONCKS.BRONZE_GOOG scheduled__2024-01-12T00:00:00+00:00 [queued]>
[2024-09-15 20:10:27,851] {taskinstance.py:1159} INFO - Dependencies all met for <TaskInstance: BRONZER_GET_STONCKS.BRONZE_GOOG scheduled__2024-01-12T00:00:00+00:00 [queued]>
[2024-09-15 20:10:27,851] {taskinstance.py:1356} INFO - 
--------------------------------------------------------------------------------
[2024-09-15 20:10:27,851] {taskinstance.py:1357} INFO - Starting attempt 1 of 1
[2024-09-15 20:10:27,851] {taskinstance.py:1358} INFO - 
--------------------------------------------------------------------------------
[2024-09-15 20:10:27,861] {taskinstance.py:1377} INFO - Executing <Task(_PythonDecoratedOperator): BRONZE_GOOG> on 2024-01-12 00:00:00+00:00
[2024-09-15 20:10:27,863] {standard_task_runner.py:52} INFO - Started process 12749 to run task
[2024-09-15 20:10:27,865] {standard_task_runner.py:79} INFO - Running: ['airflow', 'tasks', 'run', 'BRONZER_GET_STONCKS', 'BRONZE_GOOG', 'scheduled__2024-01-12T00:00:00+00:00', '--job-id', '94', '--raw', '--subdir', 'DAGS_FOLDER/get_stocks.py', '--cfg-path', '/tmp/tmp3ad1yaic', '--error-file', '/tmp/tmp4jjlp0k4']
[2024-09-15 20:10:27,866] {standard_task_runner.py:80} INFO - Job 94: Subtask BRONZE_GOOG
[2024-09-15 20:10:27,896] {task_command.py:370} INFO - Running <TaskInstance: BRONZER_GET_STONCKS.BRONZE_GOOG scheduled__2024-01-12T00:00:00+00:00 [running]> on host kaiwang.
[2024-09-15 20:10:27,936] {taskinstance.py:1569} INFO - Exporting the following env vars:
AIRFLOW_CTX_DAG_OWNER=airflow
AIRFLOW_CTX_DAG_ID=BRONZER_GET_STONCKS
AIRFLOW_CTX_TASK_ID=BRONZE_GOOG
AIRFLOW_CTX_EXECUTION_DATE=2024-01-12T00:00:00+00:00
AIRFLOW_CTX_TRY_NUMBER=1
AIRFLOW_CTX_DAG_RUN_ID=scheduled__2024-01-12T00:00:00+00:00
[2024-09-15 20:10:32,697] {history.py:244} ERROR - $GOOG: possibly delisted; no price data found  (1h 2024-01-09 -> 2024-01-03) (Yahoo error = "Invalid input - start date cannot be after end date. startDate = 1704776400, endDate = 1704258000")
[2024-09-15 20:10:32,705] {python.py:173} INFO - Done. Returned value was: None
[2024-09-15 20:10:32,715] {taskinstance.py:1395} INFO - Marking task as SUCCESS. dag_id=BRONZER_GET_STONCKS, task_id=BRONZE_GOOG, execution_date=20240112T000000, start_date=20240915T231027, end_date=20240915T231032
[2024-09-15 20:10:32,756] {local_task_job.py:156} INFO - Task exited with return code 0
[2024-09-15 20:10:32,767] {local_task_job.py:273} INFO - 0 downstream tasks scheduled from follow-on schedule check
[2024-09-15 20:13:16,717] {taskinstance.py:1159} INFO - Dependencies all met for <TaskInstance: BRONZER_GET_STONCKS.BRONZE_GOOG scheduled__2024-01-12T00:00:00+00:00 [queued]>
[2024-09-15 20:13:16,721] {taskinstance.py:1159} INFO - Dependencies all met for <TaskInstance: BRONZER_GET_STONCKS.BRONZE_GOOG scheduled__2024-01-12T00:00:00+00:00 [queued]>
[2024-09-15 20:13:16,722] {taskinstance.py:1356} INFO - 
--------------------------------------------------------------------------------
[2024-09-15 20:13:16,722] {taskinstance.py:1357} INFO - Starting attempt 1 of 1
[2024-09-15 20:13:16,722] {taskinstance.py:1358} INFO - 
--------------------------------------------------------------------------------
[2024-09-15 20:13:16,732] {taskinstance.py:1377} INFO - Executing <Task(_PythonDecoratedOperator): BRONZE_GOOG> on 2024-01-12 00:00:00+00:00
[2024-09-15 20:13:16,735] {standard_task_runner.py:52} INFO - Started process 13361 to run task
[2024-09-15 20:13:16,738] {standard_task_runner.py:79} INFO - Running: ['airflow', 'tasks', 'run', 'BRONZER_GET_STONCKS', 'BRONZE_GOOG', 'scheduled__2024-01-12T00:00:00+00:00', '--job-id', '94', '--raw', '--subdir', 'DAGS_FOLDER/get_stocks.py', '--cfg-path', '/tmp/tmp2mf7kakz', '--error-file', '/tmp/tmpd70_102q']
[2024-09-15 20:13:16,738] {standard_task_runner.py:80} INFO - Job 94: Subtask BRONZE_GOOG
[2024-09-15 20:13:16,769] {task_command.py:370} INFO - Running <TaskInstance: BRONZER_GET_STONCKS.BRONZE_GOOG scheduled__2024-01-12T00:00:00+00:00 [running]> on host kaiwang.
[2024-09-15 20:13:16,809] {taskinstance.py:1569} INFO - Exporting the following env vars:
AIRFLOW_CTX_DAG_OWNER=airflow
AIRFLOW_CTX_DAG_ID=BRONZER_GET_STONCKS
AIRFLOW_CTX_TASK_ID=BRONZE_GOOG
AIRFLOW_CTX_EXECUTION_DATE=2024-01-12T00:00:00+00:00
AIRFLOW_CTX_TRY_NUMBER=1
AIRFLOW_CTX_DAG_RUN_ID=scheduled__2024-01-12T00:00:00+00:00
[2024-09-15 20:13:16,810] {taskinstance.py:1889} ERROR - Task failed with exception
Traceback (most recent call last):
  File "/usr/lib/python3.10/pathlib.py", line 1175, in mkdir
    self._accessor.mkdir(self, mode)
FileNotFoundError: [Errno 2] No such file or directory: '/Documents/airflow_celeby/datalake/GOOG'

During handling of the above exception, another exception occurred:

Traceback (most recent call last):
  File "/usr/lib/python3.10/pathlib.py", line 1175, in mkdir
    self._accessor.mkdir(self, mode)
FileNotFoundError: [Errno 2] No such file or directory: '/Documents/airflow_celeby/datalake'

During handling of the above exception, another exception occurred:

Traceback (most recent call last):
  File "/usr/lib/python3.10/pathlib.py", line 1175, in mkdir
    self._accessor.mkdir(self, mode)
FileNotFoundError: [Errno 2] No such file or directory: '/Documents/airflow_celeby'

During handling of the above exception, another exception occurred:

Traceback (most recent call last):
  File "/home/kaiwang/Documents/airflow_celeby/venv/lib/python3.10/site-packages/airflow/decorators/base.py", line 179, in execute
    return_value = super().execute(context)
  File "/home/kaiwang/Documents/airflow_celeby/venv/lib/python3.10/site-packages/airflow/operators/python.py", line 171, in execute
    return_value = self.execute_callable()
  File "/home/kaiwang/Documents/airflow_celeby/venv/lib/python3.10/site-packages/airflow/operators/python.py", line 189, in execute_callable
    return self.python_callable(*self.op_args, **self.op_kwargs)
  File "/home/kaiwang/Documents/airflow_celeby/dags/get_stocks.py", line 21, in get_history
    (Path(file_path).parent).mkdir(parents=True, exist_ok=True)
  File "/usr/lib/python3.10/pathlib.py", line 1179, in mkdir
    self.parent.mkdir(parents=True, exist_ok=True)
  File "/usr/lib/python3.10/pathlib.py", line 1179, in mkdir
    self.parent.mkdir(parents=True, exist_ok=True)
  File "/usr/lib/python3.10/pathlib.py", line 1179, in mkdir
    self.parent.mkdir(parents=True, exist_ok=True)
  File "/usr/lib/python3.10/pathlib.py", line 1175, in mkdir
    self._accessor.mkdir(self, mode)
PermissionError: [Errno 13] Permission denied: '/Documents'
[2024-09-15 20:13:16,812] {taskinstance.py:1395} INFO - Marking task as FAILED. dag_id=BRONZER_GET_STONCKS, task_id=BRONZE_GOOG, execution_date=20240112T000000, start_date=20240915T231316, end_date=20240915T231316
[2024-09-15 20:13:16,821] {standard_task_runner.py:92} ERROR - Failed to execute job 94 for task BRONZE_GOOG ([Errno 13] Permission denied: '/Documents'; 13361)
[2024-09-15 20:13:16,830] {local_task_job.py:156} INFO - Task exited with return code 1
[2024-09-15 20:13:16,840] {local_task_job.py:273} INFO - 0 downstream tasks scheduled from follow-on schedule check
[2024-09-15 20:17:27,851] {taskinstance.py:1159} INFO - Dependencies all met for <TaskInstance: BRONZER_GET_STONCKS.BRONZE_GOOG scheduled__2024-01-12T00:00:00+00:00 [queued]>
[2024-09-15 20:17:27,855] {taskinstance.py:1159} INFO - Dependencies all met for <TaskInstance: BRONZER_GET_STONCKS.BRONZE_GOOG scheduled__2024-01-12T00:00:00+00:00 [queued]>
[2024-09-15 20:17:27,855] {taskinstance.py:1356} INFO - 
--------------------------------------------------------------------------------
[2024-09-15 20:17:27,855] {taskinstance.py:1357} INFO - Starting attempt 1 of 1
[2024-09-15 20:17:27,855] {taskinstance.py:1358} INFO - 
--------------------------------------------------------------------------------
[2024-09-15 20:17:27,870] {taskinstance.py:1377} INFO - Executing <Task(_PythonDecoratedOperator): BRONZE_GOOG> on 2024-01-12 00:00:00+00:00
[2024-09-15 20:17:27,873] {standard_task_runner.py:52} INFO - Started process 14024 to run task
[2024-09-15 20:17:27,875] {standard_task_runner.py:79} INFO - Running: ['airflow', 'tasks', 'run', 'BRONZER_GET_STONCKS', 'BRONZE_GOOG', 'scheduled__2024-01-12T00:00:00+00:00', '--job-id', '94', '--raw', '--subdir', 'DAGS_FOLDER/get_stocks.py', '--cfg-path', '/tmp/tmpg9mugvod', '--error-file', '/tmp/tmpcskexutj']
[2024-09-15 20:17:27,876] {standard_task_runner.py:80} INFO - Job 94: Subtask BRONZE_GOOG
[2024-09-15 20:17:27,905] {task_command.py:370} INFO - Running <TaskInstance: BRONZER_GET_STONCKS.BRONZE_GOOG scheduled__2024-01-12T00:00:00+00:00 [running]> on host kaiwang.
[2024-09-15 20:17:27,946] {taskinstance.py:1569} INFO - Exporting the following env vars:
AIRFLOW_CTX_DAG_OWNER=airflow
AIRFLOW_CTX_DAG_ID=BRONZER_GET_STONCKS
AIRFLOW_CTX_TASK_ID=BRONZE_GOOG
AIRFLOW_CTX_EXECUTION_DATE=2024-01-12T00:00:00+00:00
AIRFLOW_CTX_TRY_NUMBER=1
AIRFLOW_CTX_DAG_RUN_ID=scheduled__2024-01-12T00:00:00+00:00
[2024-09-15 20:17:31,242] {history.py:244} ERROR - $GOOG: possibly delisted; no price data found  (1h 2024-01-09 -> 2024-01-03) (Yahoo error = "Invalid input - start date cannot be after end date. startDate = 1704776400, endDate = 1704258000")
[2024-09-15 20:17:31,244] {python.py:173} INFO - Done. Returned value was: None
[2024-09-15 20:17:31,249] {taskinstance.py:1395} INFO - Marking task as SUCCESS. dag_id=BRONZER_GET_STONCKS, task_id=BRONZE_GOOG, execution_date=20240112T000000, start_date=20240915T231727, end_date=20240915T231731
[2024-09-15 20:17:31,274] {local_task_job.py:156} INFO - Task exited with return code 0
[2024-09-15 20:17:31,285] {local_task_job.py:273} INFO - 0 downstream tasks scheduled from follow-on schedule check
