[2024-09-15 20:04:33,453] {taskinstance.py:1159} INFO - Dependencies all met for <TaskInstance: BRONZER_GET_STONCKS.BRONZE_MSFT scheduled__2024-01-23T00:00:00+00:00 [queued]>
[2024-09-15 20:04:33,456] {taskinstance.py:1159} INFO - Dependencies all met for <TaskInstance: BRONZER_GET_STONCKS.BRONZE_MSFT scheduled__2024-01-23T00:00:00+00:00 [queued]>
[2024-09-15 20:04:33,457] {taskinstance.py:1356} INFO - 
--------------------------------------------------------------------------------
[2024-09-15 20:04:33,457] {taskinstance.py:1357} INFO - Starting attempt 1 of 1
[2024-09-15 20:04:33,457] {taskinstance.py:1358} INFO - 
--------------------------------------------------------------------------------
[2024-09-15 20:04:33,467] {taskinstance.py:1377} INFO - Executing <Task(_PythonDecoratedOperator): BRONZE_MSFT> on 2024-01-23 00:00:00+00:00
[2024-09-15 20:04:33,469] {standard_task_runner.py:52} INFO - Started process 11678 to run task
[2024-09-15 20:04:33,471] {standard_task_runner.py:79} INFO - Running: ['airflow', 'tasks', 'run', 'BRONZER_GET_STONCKS', 'BRONZE_MSFT', 'scheduled__2024-01-23T00:00:00+00:00', '--job-id', '70', '--raw', '--subdir', 'DAGS_FOLDER/get_stocks.py', '--cfg-path', '/tmp/tmp_qq9p6qx', '--error-file', '/tmp/tmp4n32gzlp']
[2024-09-15 20:04:33,471] {standard_task_runner.py:80} INFO - Job 70: Subtask BRONZE_MSFT
[2024-09-15 20:04:33,499] {task_command.py:370} INFO - Running <TaskInstance: BRONZER_GET_STONCKS.BRONZE_MSFT scheduled__2024-01-23T00:00:00+00:00 [running]> on host kaiwang.
[2024-09-15 20:04:33,538] {taskinstance.py:1569} INFO - Exporting the following env vars:
AIRFLOW_CTX_DAG_OWNER=airflow
AIRFLOW_CTX_DAG_ID=BRONZER_GET_STONCKS
AIRFLOW_CTX_TASK_ID=BRONZE_MSFT
AIRFLOW_CTX_EXECUTION_DATE=2024-01-23T00:00:00+00:00
AIRFLOW_CTX_TRY_NUMBER=1
AIRFLOW_CTX_DAG_RUN_ID=scheduled__2024-01-23T00:00:00+00:00
[2024-09-15 20:04:33,538] {taskinstance.py:1889} ERROR - Task failed with exception
Traceback (most recent call last):
  File "/usr/lib/python3.10/pathlib.py", line 1175, in mkdir
    self._accessor.mkdir(self, mode)
FileNotFoundError: [Errno 2] No such file or directory: '/datalake/MSFT'

During handling of the above exception, another exception occurred:

Traceback (most recent call last):
  File "/home/kaiwang/Documents/airflow_celeby/venv/lib/python3.10/site-packages/airflow/decorators/base.py", line 179, in execute
    return_value = super().execute(context)
  File "/home/kaiwang/Documents/airflow_celeby/venv/lib/python3.10/site-packages/airflow/operators/python.py", line 171, in execute
    return_value = self.execute_callable()
  File "/home/kaiwang/Documents/airflow_celeby/venv/lib/python3.10/site-packages/airflow/operators/python.py", line 189, in execute_callable
    return self.python_callable(*self.op_args, **self.op_kwargs)
  File "/home/kaiwang/Documents/airflow_celeby/dags/get_stocks.py", line 21, in get_history
    (Path(file_path).parent).mkdir(parents=True, exist_ok=True)
  File "/usr/lib/python3.10/pathlib.py", line 1179, in mkdir
    self.parent.mkdir(parents=True, exist_ok=True)
  File "/usr/lib/python3.10/pathlib.py", line 1175, in mkdir
    self._accessor.mkdir(self, mode)
PermissionError: [Errno 13] Permission denied: '/datalake'
[2024-09-15 20:04:33,541] {taskinstance.py:1395} INFO - Marking task as FAILED. dag_id=BRONZER_GET_STONCKS, task_id=BRONZE_MSFT, execution_date=20240123T000000, start_date=20240915T230433, end_date=20240915T230433
[2024-09-15 20:04:33,549] {standard_task_runner.py:92} ERROR - Failed to execute job 70 for task BRONZE_MSFT ([Errno 13] Permission denied: '/datalake'; 11678)
[2024-09-15 20:04:33,564] {local_task_job.py:156} INFO - Task exited with return code 1
[2024-09-15 20:04:33,573] {local_task_job.py:273} INFO - 0 downstream tasks scheduled from follow-on schedule check
[2024-09-15 20:11:50,259] {taskinstance.py:1159} INFO - Dependencies all met for <TaskInstance: BRONZER_GET_STONCKS.BRONZE_MSFT scheduled__2024-01-23T00:00:00+00:00 [queued]>
[2024-09-15 20:11:50,263] {taskinstance.py:1159} INFO - Dependencies all met for <TaskInstance: BRONZER_GET_STONCKS.BRONZE_MSFT scheduled__2024-01-23T00:00:00+00:00 [queued]>
[2024-09-15 20:11:50,263] {taskinstance.py:1356} INFO - 
--------------------------------------------------------------------------------
[2024-09-15 20:11:50,264] {taskinstance.py:1357} INFO - Starting attempt 1 of 1
[2024-09-15 20:11:50,264] {taskinstance.py:1358} INFO - 
--------------------------------------------------------------------------------
[2024-09-15 20:11:50,276] {taskinstance.py:1377} INFO - Executing <Task(_PythonDecoratedOperator): BRONZE_MSFT> on 2024-01-23 00:00:00+00:00
[2024-09-15 20:11:50,279] {standard_task_runner.py:52} INFO - Started process 13014 to run task
[2024-09-15 20:11:50,282] {standard_task_runner.py:79} INFO - Running: ['airflow', 'tasks', 'run', 'BRONZER_GET_STONCKS', 'BRONZE_MSFT', 'scheduled__2024-01-23T00:00:00+00:00', '--job-id', '121', '--raw', '--subdir', 'DAGS_FOLDER/get_stocks.py', '--cfg-path', '/tmp/tmpo5xi_z3x', '--error-file', '/tmp/tmpqa2hm50c']
[2024-09-15 20:11:50,283] {standard_task_runner.py:80} INFO - Job 121: Subtask BRONZE_MSFT
[2024-09-15 20:11:50,312] {task_command.py:370} INFO - Running <TaskInstance: BRONZER_GET_STONCKS.BRONZE_MSFT scheduled__2024-01-23T00:00:00+00:00 [running]> on host kaiwang.
[2024-09-15 20:11:50,351] {taskinstance.py:1569} INFO - Exporting the following env vars:
AIRFLOW_CTX_DAG_OWNER=airflow
AIRFLOW_CTX_DAG_ID=BRONZER_GET_STONCKS
AIRFLOW_CTX_TASK_ID=BRONZE_MSFT
AIRFLOW_CTX_EXECUTION_DATE=2024-01-23T00:00:00+00:00
AIRFLOW_CTX_TRY_NUMBER=1
AIRFLOW_CTX_DAG_RUN_ID=scheduled__2024-01-23T00:00:00+00:00
[2024-09-15 20:11:50,352] {taskinstance.py:1889} ERROR - Task failed with exception
Traceback (most recent call last):
  File "/usr/lib/python3.10/pathlib.py", line 1175, in mkdir
    self._accessor.mkdir(self, mode)
FileNotFoundError: [Errno 2] No such file or directory: '/Documents/airflow_celeby/datalake/MSFT'

During handling of the above exception, another exception occurred:

Traceback (most recent call last):
  File "/usr/lib/python3.10/pathlib.py", line 1175, in mkdir
    self._accessor.mkdir(self, mode)
FileNotFoundError: [Errno 2] No such file or directory: '/Documents/airflow_celeby/datalake'

During handling of the above exception, another exception occurred:

Traceback (most recent call last):
  File "/usr/lib/python3.10/pathlib.py", line 1175, in mkdir
    self._accessor.mkdir(self, mode)
FileNotFoundError: [Errno 2] No such file or directory: '/Documents/airflow_celeby'

During handling of the above exception, another exception occurred:

Traceback (most recent call last):
  File "/home/kaiwang/Documents/airflow_celeby/venv/lib/python3.10/site-packages/airflow/decorators/base.py", line 179, in execute
    return_value = super().execute(context)
  File "/home/kaiwang/Documents/airflow_celeby/venv/lib/python3.10/site-packages/airflow/operators/python.py", line 171, in execute
    return_value = self.execute_callable()
  File "/home/kaiwang/Documents/airflow_celeby/venv/lib/python3.10/site-packages/airflow/operators/python.py", line 189, in execute_callable
    return self.python_callable(*self.op_args, **self.op_kwargs)
  File "/home/kaiwang/Documents/airflow_celeby/dags/get_stocks.py", line 21, in get_history
    (Path(file_path).parent).mkdir(parents=True, exist_ok=True)
  File "/usr/lib/python3.10/pathlib.py", line 1179, in mkdir
    self.parent.mkdir(parents=True, exist_ok=True)
  File "/usr/lib/python3.10/pathlib.py", line 1179, in mkdir
    self.parent.mkdir(parents=True, exist_ok=True)
  File "/usr/lib/python3.10/pathlib.py", line 1179, in mkdir
    self.parent.mkdir(parents=True, exist_ok=True)
  File "/usr/lib/python3.10/pathlib.py", line 1175, in mkdir
    self._accessor.mkdir(self, mode)
PermissionError: [Errno 13] Permission denied: '/Documents'
[2024-09-15 20:11:50,354] {taskinstance.py:1395} INFO - Marking task as FAILED. dag_id=BRONZER_GET_STONCKS, task_id=BRONZE_MSFT, execution_date=20240123T000000, start_date=20240915T231150, end_date=20240915T231150
[2024-09-15 20:11:50,363] {standard_task_runner.py:92} ERROR - Failed to execute job 121 for task BRONZE_MSFT ([Errno 13] Permission denied: '/Documents'; 13014)
[2024-09-15 20:11:50,375] {local_task_job.py:156} INFO - Task exited with return code 1
[2024-09-15 20:11:50,386] {local_task_job.py:273} INFO - 0 downstream tasks scheduled from follow-on schedule check
[2024-09-15 23:28:08,678] {taskinstance.py:1159} INFO - Dependencies all met for <TaskInstance: BRONZER_GET_STONCKS.BRONZE_MSFT scheduled__2024-01-23T00:00:00+00:00 [queued]>
[2024-09-15 23:28:08,684] {taskinstance.py:1159} INFO - Dependencies all met for <TaskInstance: BRONZER_GET_STONCKS.BRONZE_MSFT scheduled__2024-01-23T00:00:00+00:00 [queued]>
[2024-09-15 23:28:08,684] {taskinstance.py:1356} INFO - 
--------------------------------------------------------------------------------
[2024-09-15 23:28:08,684] {taskinstance.py:1357} INFO - Starting attempt 1 of 1
[2024-09-15 23:28:08,684] {taskinstance.py:1358} INFO - 
--------------------------------------------------------------------------------
[2024-09-15 23:28:08,695] {taskinstance.py:1377} INFO - Executing <Task(_PythonDecoratedOperator): BRONZE_MSFT> on 2024-01-23 00:00:00+00:00
[2024-09-15 23:28:08,698] {standard_task_runner.py:52} INFO - Started process 14353 to run task
[2024-09-15 23:28:08,701] {standard_task_runner.py:79} INFO - Running: ['airflow', 'tasks', 'run', 'BRONZER_GET_STONCKS', 'BRONZE_MSFT', 'scheduled__2024-01-23T00:00:00+00:00', '--job-id', '121', '--raw', '--subdir', 'DAGS_FOLDER/get_stocks.py', '--cfg-path', '/tmp/tmpxjy2y0r7', '--error-file', '/tmp/tmpkad_7r_b']
[2024-09-15 23:28:08,701] {standard_task_runner.py:80} INFO - Job 121: Subtask BRONZE_MSFT
[2024-09-15 23:28:08,730] {task_command.py:370} INFO - Running <TaskInstance: BRONZER_GET_STONCKS.BRONZE_MSFT scheduled__2024-01-23T00:00:00+00:00 [running]> on host kaiwang.
[2024-09-15 23:28:08,770] {taskinstance.py:1569} INFO - Exporting the following env vars:
AIRFLOW_CTX_DAG_OWNER=airflow
AIRFLOW_CTX_DAG_ID=BRONZER_GET_STONCKS
AIRFLOW_CTX_TASK_ID=BRONZE_MSFT
AIRFLOW_CTX_EXECUTION_DATE=2024-01-23T00:00:00+00:00
AIRFLOW_CTX_TRY_NUMBER=1
AIRFLOW_CTX_DAG_RUN_ID=scheduled__2024-01-23T00:00:00+00:00
[2024-09-15 23:28:10,985] {history.py:244} ERROR - $MSFT: possibly delisted; no price data found  (1h 2024-01-20 -> 2024-01-03) (Yahoo error = "Invalid input - start date cannot be after end date. startDate = 1705726800, endDate = 1704258000")
[2024-09-15 23:28:10,986] {python.py:173} INFO - Done. Returned value was: None
[2024-09-15 23:28:10,991] {taskinstance.py:1395} INFO - Marking task as SUCCESS. dag_id=BRONZER_GET_STONCKS, task_id=BRONZE_MSFT, execution_date=20240123T000000, start_date=20240916T022808, end_date=20240916T022810
[2024-09-15 23:28:11,005] {local_task_job.py:156} INFO - Task exited with return code 0
[2024-09-15 23:28:11,015] {local_task_job.py:273} INFO - 0 downstream tasks scheduled from follow-on schedule check
