[2024-09-15 20:04:29,418] {taskinstance.py:1159} INFO - Dependencies all met for <TaskInstance: BRONZER_GET_STONCKS.BRONZE_GOOG scheduled__2024-01-20T00:00:00+00:00 [queued]>
[2024-09-15 20:04:29,422] {taskinstance.py:1159} INFO - Dependencies all met for <TaskInstance: BRONZER_GET_STONCKS.BRONZE_GOOG scheduled__2024-01-20T00:00:00+00:00 [queued]>
[2024-09-15 20:04:29,423] {taskinstance.py:1356} INFO - 
--------------------------------------------------------------------------------
[2024-09-15 20:04:29,423] {taskinstance.py:1357} INFO - Starting attempt 1 of 1
[2024-09-15 20:04:29,423] {taskinstance.py:1358} INFO - 
--------------------------------------------------------------------------------
[2024-09-15 20:04:29,433] {taskinstance.py:1377} INFO - Executing <Task(_PythonDecoratedOperator): BRONZE_GOOG> on 2024-01-20 00:00:00+00:00
[2024-09-15 20:04:29,435] {standard_task_runner.py:52} INFO - Started process 11649 to run task
[2024-09-15 20:04:29,438] {standard_task_runner.py:79} INFO - Running: ['airflow', 'tasks', 'run', 'BRONZER_GET_STONCKS', 'BRONZE_GOOG', 'scheduled__2024-01-20T00:00:00+00:00', '--job-id', '67', '--raw', '--subdir', 'DAGS_FOLDER/get_stocks.py', '--cfg-path', '/tmp/tmpj0izplfs', '--error-file', '/tmp/tmpujf1fhoy']
[2024-09-15 20:04:29,439] {standard_task_runner.py:80} INFO - Job 67: Subtask BRONZE_GOOG
[2024-09-15 20:04:29,471] {task_command.py:370} INFO - Running <TaskInstance: BRONZER_GET_STONCKS.BRONZE_GOOG scheduled__2024-01-20T00:00:00+00:00 [running]> on host kaiwang.
[2024-09-15 20:04:29,512] {taskinstance.py:1569} INFO - Exporting the following env vars:
AIRFLOW_CTX_DAG_OWNER=airflow
AIRFLOW_CTX_DAG_ID=BRONZER_GET_STONCKS
AIRFLOW_CTX_TASK_ID=BRONZE_GOOG
AIRFLOW_CTX_EXECUTION_DATE=2024-01-20T00:00:00+00:00
AIRFLOW_CTX_TRY_NUMBER=1
AIRFLOW_CTX_DAG_RUN_ID=scheduled__2024-01-20T00:00:00+00:00
[2024-09-15 20:04:29,513] {taskinstance.py:1889} ERROR - Task failed with exception
Traceback (most recent call last):
  File "/usr/lib/python3.10/pathlib.py", line 1175, in mkdir
    self._accessor.mkdir(self, mode)
FileNotFoundError: [Errno 2] No such file or directory: '/datalake/GOOG'

During handling of the above exception, another exception occurred:

Traceback (most recent call last):
  File "/home/kaiwang/Documents/airflow_celeby/venv/lib/python3.10/site-packages/airflow/decorators/base.py", line 179, in execute
    return_value = super().execute(context)
  File "/home/kaiwang/Documents/airflow_celeby/venv/lib/python3.10/site-packages/airflow/operators/python.py", line 171, in execute
    return_value = self.execute_callable()
  File "/home/kaiwang/Documents/airflow_celeby/venv/lib/python3.10/site-packages/airflow/operators/python.py", line 189, in execute_callable
    return self.python_callable(*self.op_args, **self.op_kwargs)
  File "/home/kaiwang/Documents/airflow_celeby/dags/get_stocks.py", line 21, in get_history
    (Path(file_path).parent).mkdir(parents=True, exist_ok=True)
  File "/usr/lib/python3.10/pathlib.py", line 1179, in mkdir
    self.parent.mkdir(parents=True, exist_ok=True)
  File "/usr/lib/python3.10/pathlib.py", line 1175, in mkdir
    self._accessor.mkdir(self, mode)
PermissionError: [Errno 13] Permission denied: '/datalake'
[2024-09-15 20:04:29,516] {taskinstance.py:1395} INFO - Marking task as FAILED. dag_id=BRONZER_GET_STONCKS, task_id=BRONZE_GOOG, execution_date=20240120T000000, start_date=20240915T230429, end_date=20240915T230429
[2024-09-15 20:04:29,525] {standard_task_runner.py:92} ERROR - Failed to execute job 67 for task BRONZE_GOOG ([Errno 13] Permission denied: '/datalake'; 11649)
[2024-09-15 20:04:29,531] {local_task_job.py:156} INFO - Task exited with return code 1
[2024-09-15 20:04:29,541] {local_task_job.py:273} INFO - 0 downstream tasks scheduled from follow-on schedule check
[2024-09-15 20:11:45,674] {taskinstance.py:1159} INFO - Dependencies all met for <TaskInstance: BRONZER_GET_STONCKS.BRONZE_GOOG scheduled__2024-01-20T00:00:00+00:00 [queued]>
[2024-09-15 20:11:45,679] {taskinstance.py:1159} INFO - Dependencies all met for <TaskInstance: BRONZER_GET_STONCKS.BRONZE_GOOG scheduled__2024-01-20T00:00:00+00:00 [queued]>
[2024-09-15 20:11:45,679] {taskinstance.py:1356} INFO - 
--------------------------------------------------------------------------------
[2024-09-15 20:11:45,679] {taskinstance.py:1357} INFO - Starting attempt 1 of 1
[2024-09-15 20:11:45,679] {taskinstance.py:1358} INFO - 
--------------------------------------------------------------------------------
[2024-09-15 20:11:45,693] {taskinstance.py:1377} INFO - Executing <Task(_PythonDecoratedOperator): BRONZE_GOOG> on 2024-01-20 00:00:00+00:00
[2024-09-15 20:11:45,696] {standard_task_runner.py:52} INFO - Started process 12986 to run task
[2024-09-15 20:11:45,698] {standard_task_runner.py:79} INFO - Running: ['airflow', 'tasks', 'run', 'BRONZER_GET_STONCKS', 'BRONZE_GOOG', 'scheduled__2024-01-20T00:00:00+00:00', '--job-id', '118', '--raw', '--subdir', 'DAGS_FOLDER/get_stocks.py', '--cfg-path', '/tmp/tmpf_7g4ioh', '--error-file', '/tmp/tmpht8o6y0s']
[2024-09-15 20:11:45,699] {standard_task_runner.py:80} INFO - Job 118: Subtask BRONZE_GOOG
[2024-09-15 20:11:45,727] {task_command.py:370} INFO - Running <TaskInstance: BRONZER_GET_STONCKS.BRONZE_GOOG scheduled__2024-01-20T00:00:00+00:00 [running]> on host kaiwang.
[2024-09-15 20:11:45,767] {taskinstance.py:1569} INFO - Exporting the following env vars:
AIRFLOW_CTX_DAG_OWNER=airflow
AIRFLOW_CTX_DAG_ID=BRONZER_GET_STONCKS
AIRFLOW_CTX_TASK_ID=BRONZE_GOOG
AIRFLOW_CTX_EXECUTION_DATE=2024-01-20T00:00:00+00:00
AIRFLOW_CTX_TRY_NUMBER=1
AIRFLOW_CTX_DAG_RUN_ID=scheduled__2024-01-20T00:00:00+00:00
[2024-09-15 20:11:45,767] {taskinstance.py:1889} ERROR - Task failed with exception
Traceback (most recent call last):
  File "/usr/lib/python3.10/pathlib.py", line 1175, in mkdir
    self._accessor.mkdir(self, mode)
FileNotFoundError: [Errno 2] No such file or directory: '/Documents/airflow_celeby/datalake/GOOG'

During handling of the above exception, another exception occurred:

Traceback (most recent call last):
  File "/usr/lib/python3.10/pathlib.py", line 1175, in mkdir
    self._accessor.mkdir(self, mode)
FileNotFoundError: [Errno 2] No such file or directory: '/Documents/airflow_celeby/datalake'

During handling of the above exception, another exception occurred:

Traceback (most recent call last):
  File "/usr/lib/python3.10/pathlib.py", line 1175, in mkdir
    self._accessor.mkdir(self, mode)
FileNotFoundError: [Errno 2] No such file or directory: '/Documents/airflow_celeby'

During handling of the above exception, another exception occurred:

Traceback (most recent call last):
  File "/home/kaiwang/Documents/airflow_celeby/venv/lib/python3.10/site-packages/airflow/decorators/base.py", line 179, in execute
    return_value = super().execute(context)
  File "/home/kaiwang/Documents/airflow_celeby/venv/lib/python3.10/site-packages/airflow/operators/python.py", line 171, in execute
    return_value = self.execute_callable()
  File "/home/kaiwang/Documents/airflow_celeby/venv/lib/python3.10/site-packages/airflow/operators/python.py", line 189, in execute_callable
    return self.python_callable(*self.op_args, **self.op_kwargs)
  File "/home/kaiwang/Documents/airflow_celeby/dags/get_stocks.py", line 21, in get_history
    (Path(file_path).parent).mkdir(parents=True, exist_ok=True)
  File "/usr/lib/python3.10/pathlib.py", line 1179, in mkdir
    self.parent.mkdir(parents=True, exist_ok=True)
  File "/usr/lib/python3.10/pathlib.py", line 1179, in mkdir
    self.parent.mkdir(parents=True, exist_ok=True)
  File "/usr/lib/python3.10/pathlib.py", line 1179, in mkdir
    self.parent.mkdir(parents=True, exist_ok=True)
  File "/usr/lib/python3.10/pathlib.py", line 1175, in mkdir
    self._accessor.mkdir(self, mode)
PermissionError: [Errno 13] Permission denied: '/Documents'
[2024-09-15 20:11:45,770] {taskinstance.py:1395} INFO - Marking task as FAILED. dag_id=BRONZER_GET_STONCKS, task_id=BRONZE_GOOG, execution_date=20240120T000000, start_date=20240915T231145, end_date=20240915T231145
[2024-09-15 20:11:45,779] {standard_task_runner.py:92} ERROR - Failed to execute job 118 for task BRONZE_GOOG ([Errno 13] Permission denied: '/Documents'; 12986)
[2024-09-15 20:11:45,791] {local_task_job.py:156} INFO - Task exited with return code 1
[2024-09-15 20:11:45,801] {local_task_job.py:273} INFO - 0 downstream tasks scheduled from follow-on schedule check
[2024-09-15 23:27:55,182] {taskinstance.py:1159} INFO - Dependencies all met for <TaskInstance: BRONZER_GET_STONCKS.BRONZE_GOOG scheduled__2024-01-20T00:00:00+00:00 [queued]>
[2024-09-15 23:27:55,187] {taskinstance.py:1159} INFO - Dependencies all met for <TaskInstance: BRONZER_GET_STONCKS.BRONZE_GOOG scheduled__2024-01-20T00:00:00+00:00 [queued]>
[2024-09-15 23:27:55,187] {taskinstance.py:1356} INFO - 
--------------------------------------------------------------------------------
[2024-09-15 23:27:55,187] {taskinstance.py:1357} INFO - Starting attempt 1 of 1
[2024-09-15 23:27:55,187] {taskinstance.py:1358} INFO - 
--------------------------------------------------------------------------------
[2024-09-15 23:27:55,198] {taskinstance.py:1377} INFO - Executing <Task(_PythonDecoratedOperator): BRONZE_GOOG> on 2024-01-20 00:00:00+00:00
[2024-09-15 23:27:55,201] {standard_task_runner.py:52} INFO - Started process 14324 to run task
[2024-09-15 23:27:55,203] {standard_task_runner.py:79} INFO - Running: ['airflow', 'tasks', 'run', 'BRONZER_GET_STONCKS', 'BRONZE_GOOG', 'scheduled__2024-01-20T00:00:00+00:00', '--job-id', '118', '--raw', '--subdir', 'DAGS_FOLDER/get_stocks.py', '--cfg-path', '/tmp/tmpvvlpohz9', '--error-file', '/tmp/tmp3fxlve_t']
[2024-09-15 23:27:55,203] {standard_task_runner.py:80} INFO - Job 118: Subtask BRONZE_GOOG
[2024-09-15 23:27:55,232] {task_command.py:370} INFO - Running <TaskInstance: BRONZER_GET_STONCKS.BRONZE_GOOG scheduled__2024-01-20T00:00:00+00:00 [running]> on host kaiwang.
[2024-09-15 23:27:55,272] {taskinstance.py:1569} INFO - Exporting the following env vars:
AIRFLOW_CTX_DAG_OWNER=airflow
AIRFLOW_CTX_DAG_ID=BRONZER_GET_STONCKS
AIRFLOW_CTX_TASK_ID=BRONZE_GOOG
AIRFLOW_CTX_EXECUTION_DATE=2024-01-20T00:00:00+00:00
AIRFLOW_CTX_TRY_NUMBER=1
AIRFLOW_CTX_DAG_RUN_ID=scheduled__2024-01-20T00:00:00+00:00
[2024-09-15 23:27:58,386] {history.py:244} ERROR - $GOOG: possibly delisted; no price data found  (1h 2024-01-17 -> 2024-01-03) (Yahoo error = "Invalid input - start date cannot be after end date. startDate = 1705467600, endDate = 1704258000")
[2024-09-15 23:27:58,388] {python.py:173} INFO - Done. Returned value was: None
[2024-09-15 23:27:58,392] {taskinstance.py:1395} INFO - Marking task as SUCCESS. dag_id=BRONZER_GET_STONCKS, task_id=BRONZE_GOOG, execution_date=20240120T000000, start_date=20240916T022755, end_date=20240916T022758
[2024-09-15 23:27:58,434] {local_task_job.py:156} INFO - Task exited with return code 0
[2024-09-15 23:27:58,444] {local_task_job.py:273} INFO - 0 downstream tasks scheduled from follow-on schedule check
