[2024-09-15 20:04:01,597] {taskinstance.py:1159} INFO - Dependencies all met for <TaskInstance: BRONZER_GET_STONCKS.BRONZE_GOOG scheduled__2024-01-13T00:00:00+00:00 [queued]>
[2024-09-15 20:04:01,601] {taskinstance.py:1159} INFO - Dependencies all met for <TaskInstance: BRONZER_GET_STONCKS.BRONZE_GOOG scheduled__2024-01-13T00:00:00+00:00 [queued]>
[2024-09-15 20:04:01,601] {taskinstance.py:1356} INFO - 
--------------------------------------------------------------------------------
[2024-09-15 20:04:01,601] {taskinstance.py:1357} INFO - Starting attempt 1 of 1
[2024-09-15 20:04:01,601] {taskinstance.py:1358} INFO - 
--------------------------------------------------------------------------------
[2024-09-15 20:04:01,614] {taskinstance.py:1377} INFO - Executing <Task(_PythonDecoratedOperator): BRONZE_GOOG> on 2024-01-13 00:00:00+00:00
[2024-09-15 20:04:01,616] {standard_task_runner.py:52} INFO - Started process 11468 to run task
[2024-09-15 20:04:01,619] {standard_task_runner.py:79} INFO - Running: ['airflow', 'tasks', 'run', 'BRONZER_GET_STONCKS', 'BRONZE_GOOG', 'scheduled__2024-01-13T00:00:00+00:00', '--job-id', '47', '--raw', '--subdir', 'DAGS_FOLDER/get_stocks.py', '--cfg-path', '/tmp/tmpz94t3gnk', '--error-file', '/tmp/tmpqpgg17jt']
[2024-09-15 20:04:01,619] {standard_task_runner.py:80} INFO - Job 47: Subtask BRONZE_GOOG
[2024-09-15 20:04:01,647] {task_command.py:370} INFO - Running <TaskInstance: BRONZER_GET_STONCKS.BRONZE_GOOG scheduled__2024-01-13T00:00:00+00:00 [running]> on host kaiwang.
[2024-09-15 20:04:01,687] {taskinstance.py:1569} INFO - Exporting the following env vars:
AIRFLOW_CTX_DAG_OWNER=airflow
AIRFLOW_CTX_DAG_ID=BRONZER_GET_STONCKS
AIRFLOW_CTX_TASK_ID=BRONZE_GOOG
AIRFLOW_CTX_EXECUTION_DATE=2024-01-13T00:00:00+00:00
AIRFLOW_CTX_TRY_NUMBER=1
AIRFLOW_CTX_DAG_RUN_ID=scheduled__2024-01-13T00:00:00+00:00
[2024-09-15 20:04:01,687] {taskinstance.py:1889} ERROR - Task failed with exception
Traceback (most recent call last):
  File "/usr/lib/python3.10/pathlib.py", line 1175, in mkdir
    self._accessor.mkdir(self, mode)
FileNotFoundError: [Errno 2] No such file or directory: '/datalake/GOOG'

During handling of the above exception, another exception occurred:

Traceback (most recent call last):
  File "/home/kaiwang/Documents/airflow_celeby/venv/lib/python3.10/site-packages/airflow/decorators/base.py", line 179, in execute
    return_value = super().execute(context)
  File "/home/kaiwang/Documents/airflow_celeby/venv/lib/python3.10/site-packages/airflow/operators/python.py", line 171, in execute
    return_value = self.execute_callable()
  File "/home/kaiwang/Documents/airflow_celeby/venv/lib/python3.10/site-packages/airflow/operators/python.py", line 189, in execute_callable
    return self.python_callable(*self.op_args, **self.op_kwargs)
  File "/home/kaiwang/Documents/airflow_celeby/dags/get_stocks.py", line 21, in get_history
    (Path(file_path).parent).mkdir(parents=True, exist_ok=True)
  File "/usr/lib/python3.10/pathlib.py", line 1179, in mkdir
    self.parent.mkdir(parents=True, exist_ok=True)
  File "/usr/lib/python3.10/pathlib.py", line 1175, in mkdir
    self._accessor.mkdir(self, mode)
PermissionError: [Errno 13] Permission denied: '/datalake'
[2024-09-15 20:04:01,690] {taskinstance.py:1395} INFO - Marking task as FAILED. dag_id=BRONZER_GET_STONCKS, task_id=BRONZE_GOOG, execution_date=20240113T000000, start_date=20240915T230401, end_date=20240915T230401
[2024-09-15 20:04:01,698] {standard_task_runner.py:92} ERROR - Failed to execute job 47 for task BRONZE_GOOG ([Errno 13] Permission denied: '/datalake'; 11468)
[2024-09-15 20:04:01,711] {local_task_job.py:156} INFO - Task exited with return code 1
[2024-09-15 20:04:01,721] {local_task_job.py:273} INFO - 0 downstream tasks scheduled from follow-on schedule check
[2024-09-15 20:06:46,855] {taskinstance.py:1159} INFO - Dependencies all met for <TaskInstance: BRONZER_GET_STONCKS.BRONZE_GOOG scheduled__2024-01-13T00:00:00+00:00 [queued]>
[2024-09-15 20:06:46,860] {taskinstance.py:1159} INFO - Dependencies all met for <TaskInstance: BRONZER_GET_STONCKS.BRONZE_GOOG scheduled__2024-01-13T00:00:00+00:00 [queued]>
[2024-09-15 20:06:46,860] {taskinstance.py:1356} INFO - 
--------------------------------------------------------------------------------
[2024-09-15 20:06:46,860] {taskinstance.py:1357} INFO - Starting attempt 1 of 1
[2024-09-15 20:06:46,860] {taskinstance.py:1358} INFO - 
--------------------------------------------------------------------------------
[2024-09-15 20:06:46,870] {taskinstance.py:1377} INFO - Executing <Task(_PythonDecoratedOperator): BRONZE_GOOG> on 2024-01-13 00:00:00+00:00
[2024-09-15 20:06:46,872] {standard_task_runner.py:52} INFO - Started process 12180 to run task
[2024-09-15 20:06:46,874] {standard_task_runner.py:79} INFO - Running: ['airflow', 'tasks', 'run', 'BRONZER_GET_STONCKS', 'BRONZE_GOOG', 'scheduled__2024-01-13T00:00:00+00:00', '--job-id', '49', '--raw', '--subdir', 'DAGS_FOLDER/get_stocks.py', '--cfg-path', '/tmp/tmpgycuggdh', '--error-file', '/tmp/tmpdnpolj4x']
[2024-09-15 20:06:46,875] {standard_task_runner.py:80} INFO - Job 49: Subtask BRONZE_GOOG
[2024-09-15 20:06:46,902] {task_command.py:370} INFO - Running <TaskInstance: BRONZER_GET_STONCKS.BRONZE_GOOG scheduled__2024-01-13T00:00:00+00:00 [running]> on host kaiwang.
[2024-09-15 20:06:46,942] {taskinstance.py:1569} INFO - Exporting the following env vars:
AIRFLOW_CTX_DAG_OWNER=airflow
AIRFLOW_CTX_DAG_ID=BRONZER_GET_STONCKS
AIRFLOW_CTX_TASK_ID=BRONZE_GOOG
AIRFLOW_CTX_EXECUTION_DATE=2024-01-13T00:00:00+00:00
AIRFLOW_CTX_TRY_NUMBER=1
AIRFLOW_CTX_DAG_RUN_ID=scheduled__2024-01-13T00:00:00+00:00
[2024-09-15 20:06:46,943] {taskinstance.py:1889} ERROR - Task failed with exception
Traceback (most recent call last):
  File "/usr/lib/python3.10/pathlib.py", line 1175, in mkdir
    self._accessor.mkdir(self, mode)
FileNotFoundError: [Errno 2] No such file or directory: '/datalake/GOOG'

During handling of the above exception, another exception occurred:

Traceback (most recent call last):
  File "/home/kaiwang/Documents/airflow_celeby/venv/lib/python3.10/site-packages/airflow/decorators/base.py", line 179, in execute
    return_value = super().execute(context)
  File "/home/kaiwang/Documents/airflow_celeby/venv/lib/python3.10/site-packages/airflow/operators/python.py", line 171, in execute
    return_value = self.execute_callable()
  File "/home/kaiwang/Documents/airflow_celeby/venv/lib/python3.10/site-packages/airflow/operators/python.py", line 189, in execute_callable
    return self.python_callable(*self.op_args, **self.op_kwargs)
  File "/home/kaiwang/Documents/airflow_celeby/dags/get_stocks.py", line 21, in get_history
    (Path(file_path).parent).mkdir(parents=True, exist_ok=True)
  File "/usr/lib/python3.10/pathlib.py", line 1179, in mkdir
    self.parent.mkdir(parents=True, exist_ok=True)
  File "/usr/lib/python3.10/pathlib.py", line 1175, in mkdir
    self._accessor.mkdir(self, mode)
PermissionError: [Errno 13] Permission denied: '/datalake'
[2024-09-15 20:06:46,945] {taskinstance.py:1395} INFO - Marking task as FAILED. dag_id=BRONZER_GET_STONCKS, task_id=BRONZE_GOOG, execution_date=20240113T000000, start_date=20240915T230646, end_date=20240915T230646
[2024-09-15 20:06:46,954] {standard_task_runner.py:92} ERROR - Failed to execute job 49 for task BRONZE_GOOG ([Errno 13] Permission denied: '/datalake'; 12180)
[2024-09-15 20:06:46,967] {local_task_job.py:156} INFO - Task exited with return code 1
[2024-09-15 20:06:46,977] {local_task_job.py:273} INFO - 0 downstream tasks scheduled from follow-on schedule check
[2024-09-15 20:10:51,558] {taskinstance.py:1159} INFO - Dependencies all met for <TaskInstance: BRONZER_GET_STONCKS.BRONZE_GOOG scheduled__2024-01-13T00:00:00+00:00 [queued]>
[2024-09-15 20:10:51,562] {taskinstance.py:1159} INFO - Dependencies all met for <TaskInstance: BRONZER_GET_STONCKS.BRONZE_GOOG scheduled__2024-01-13T00:00:00+00:00 [queued]>
[2024-09-15 20:10:51,562] {taskinstance.py:1356} INFO - 
--------------------------------------------------------------------------------
[2024-09-15 20:10:51,562] {taskinstance.py:1357} INFO - Starting attempt 1 of 1
[2024-09-15 20:10:51,562] {taskinstance.py:1358} INFO - 
--------------------------------------------------------------------------------
[2024-09-15 20:10:51,572] {taskinstance.py:1377} INFO - Executing <Task(_PythonDecoratedOperator): BRONZE_GOOG> on 2024-01-13 00:00:00+00:00
[2024-09-15 20:10:51,574] {standard_task_runner.py:52} INFO - Started process 12790 to run task
[2024-09-15 20:10:51,577] {standard_task_runner.py:79} INFO - Running: ['airflow', 'tasks', 'run', 'BRONZER_GET_STONCKS', 'BRONZE_GOOG', 'scheduled__2024-01-13T00:00:00+00:00', '--job-id', '98', '--raw', '--subdir', 'DAGS_FOLDER/get_stocks.py', '--cfg-path', '/tmp/tmp81_r58bn', '--error-file', '/tmp/tmpioryo4g6']
[2024-09-15 20:10:51,577] {standard_task_runner.py:80} INFO - Job 98: Subtask BRONZE_GOOG
[2024-09-15 20:10:51,614] {task_command.py:370} INFO - Running <TaskInstance: BRONZER_GET_STONCKS.BRONZE_GOOG scheduled__2024-01-13T00:00:00+00:00 [running]> on host kaiwang.
[2024-09-15 20:10:51,654] {taskinstance.py:1569} INFO - Exporting the following env vars:
AIRFLOW_CTX_DAG_OWNER=airflow
AIRFLOW_CTX_DAG_ID=BRONZER_GET_STONCKS
AIRFLOW_CTX_TASK_ID=BRONZE_GOOG
AIRFLOW_CTX_EXECUTION_DATE=2024-01-13T00:00:00+00:00
AIRFLOW_CTX_TRY_NUMBER=1
AIRFLOW_CTX_DAG_RUN_ID=scheduled__2024-01-13T00:00:00+00:00
[2024-09-15 20:10:55,827] {history.py:244} ERROR - $GOOG: possibly delisted; no price data found  (1h 2024-01-10 -> 2024-01-03) (Yahoo error = "Invalid input - start date cannot be after end date. startDate = 1704862800, endDate = 1704258000")
[2024-09-15 20:10:55,836] {python.py:173} INFO - Done. Returned value was: None
[2024-09-15 20:10:55,847] {taskinstance.py:1395} INFO - Marking task as SUCCESS. dag_id=BRONZER_GET_STONCKS, task_id=BRONZE_GOOG, execution_date=20240113T000000, start_date=20240915T231051, end_date=20240915T231055
[2024-09-15 20:10:55,900] {local_task_job.py:156} INFO - Task exited with return code 0
[2024-09-15 20:10:55,909] {local_task_job.py:273} INFO - 0 downstream tasks scheduled from follow-on schedule check
[2024-09-15 20:13:23,510] {taskinstance.py:1159} INFO - Dependencies all met for <TaskInstance: BRONZER_GET_STONCKS.BRONZE_GOOG scheduled__2024-01-13T00:00:00+00:00 [queued]>
[2024-09-15 20:13:23,514] {taskinstance.py:1159} INFO - Dependencies all met for <TaskInstance: BRONZER_GET_STONCKS.BRONZE_GOOG scheduled__2024-01-13T00:00:00+00:00 [queued]>
[2024-09-15 20:13:23,515] {taskinstance.py:1356} INFO - 
--------------------------------------------------------------------------------
[2024-09-15 20:13:23,515] {taskinstance.py:1357} INFO - Starting attempt 1 of 1
[2024-09-15 20:13:23,515] {taskinstance.py:1358} INFO - 
--------------------------------------------------------------------------------
[2024-09-15 20:13:23,525] {taskinstance.py:1377} INFO - Executing <Task(_PythonDecoratedOperator): BRONZE_GOOG> on 2024-01-13 00:00:00+00:00
[2024-09-15 20:13:23,528] {standard_task_runner.py:52} INFO - Started process 13399 to run task
[2024-09-15 20:13:23,530] {standard_task_runner.py:79} INFO - Running: ['airflow', 'tasks', 'run', 'BRONZER_GET_STONCKS', 'BRONZE_GOOG', 'scheduled__2024-01-13T00:00:00+00:00', '--job-id', '98', '--raw', '--subdir', 'DAGS_FOLDER/get_stocks.py', '--cfg-path', '/tmp/tmpya7sk5dp', '--error-file', '/tmp/tmpo15aspjg']
[2024-09-15 20:13:23,531] {standard_task_runner.py:80} INFO - Job 98: Subtask BRONZE_GOOG
[2024-09-15 20:13:23,557] {task_command.py:370} INFO - Running <TaskInstance: BRONZER_GET_STONCKS.BRONZE_GOOG scheduled__2024-01-13T00:00:00+00:00 [running]> on host kaiwang.
[2024-09-15 20:13:23,600] {taskinstance.py:1569} INFO - Exporting the following env vars:
AIRFLOW_CTX_DAG_OWNER=airflow
AIRFLOW_CTX_DAG_ID=BRONZER_GET_STONCKS
AIRFLOW_CTX_TASK_ID=BRONZE_GOOG
AIRFLOW_CTX_EXECUTION_DATE=2024-01-13T00:00:00+00:00
AIRFLOW_CTX_TRY_NUMBER=1
AIRFLOW_CTX_DAG_RUN_ID=scheduled__2024-01-13T00:00:00+00:00
[2024-09-15 20:13:23,601] {taskinstance.py:1889} ERROR - Task failed with exception
Traceback (most recent call last):
  File "/usr/lib/python3.10/pathlib.py", line 1175, in mkdir
    self._accessor.mkdir(self, mode)
FileNotFoundError: [Errno 2] No such file or directory: '/Documents/airflow_celeby/datalake/GOOG'

During handling of the above exception, another exception occurred:

Traceback (most recent call last):
  File "/usr/lib/python3.10/pathlib.py", line 1175, in mkdir
    self._accessor.mkdir(self, mode)
FileNotFoundError: [Errno 2] No such file or directory: '/Documents/airflow_celeby/datalake'

During handling of the above exception, another exception occurred:

Traceback (most recent call last):
  File "/usr/lib/python3.10/pathlib.py", line 1175, in mkdir
    self._accessor.mkdir(self, mode)
FileNotFoundError: [Errno 2] No such file or directory: '/Documents/airflow_celeby'

During handling of the above exception, another exception occurred:

Traceback (most recent call last):
  File "/home/kaiwang/Documents/airflow_celeby/venv/lib/python3.10/site-packages/airflow/decorators/base.py", line 179, in execute
    return_value = super().execute(context)
  File "/home/kaiwang/Documents/airflow_celeby/venv/lib/python3.10/site-packages/airflow/operators/python.py", line 171, in execute
    return_value = self.execute_callable()
  File "/home/kaiwang/Documents/airflow_celeby/venv/lib/python3.10/site-packages/airflow/operators/python.py", line 189, in execute_callable
    return self.python_callable(*self.op_args, **self.op_kwargs)
  File "/home/kaiwang/Documents/airflow_celeby/dags/get_stocks.py", line 21, in get_history
    (Path(file_path).parent).mkdir(parents=True, exist_ok=True)
  File "/usr/lib/python3.10/pathlib.py", line 1179, in mkdir
    self.parent.mkdir(parents=True, exist_ok=True)
  File "/usr/lib/python3.10/pathlib.py", line 1179, in mkdir
    self.parent.mkdir(parents=True, exist_ok=True)
  File "/usr/lib/python3.10/pathlib.py", line 1179, in mkdir
    self.parent.mkdir(parents=True, exist_ok=True)
  File "/usr/lib/python3.10/pathlib.py", line 1175, in mkdir
    self._accessor.mkdir(self, mode)
PermissionError: [Errno 13] Permission denied: '/Documents'
[2024-09-15 20:13:23,603] {taskinstance.py:1395} INFO - Marking task as FAILED. dag_id=BRONZER_GET_STONCKS, task_id=BRONZE_GOOG, execution_date=20240113T000000, start_date=20240915T231323, end_date=20240915T231323
[2024-09-15 20:13:23,612] {standard_task_runner.py:92} ERROR - Failed to execute job 98 for task BRONZE_GOOG ([Errno 13] Permission denied: '/Documents'; 13399)
[2024-09-15 20:13:23,623] {local_task_job.py:156} INFO - Task exited with return code 1
[2024-09-15 20:13:23,632] {local_task_job.py:273} INFO - 0 downstream tasks scheduled from follow-on schedule check
[2024-09-15 20:17:47,407] {taskinstance.py:1159} INFO - Dependencies all met for <TaskInstance: BRONZER_GET_STONCKS.BRONZE_GOOG scheduled__2024-01-13T00:00:00+00:00 [queued]>
[2024-09-15 20:17:47,411] {taskinstance.py:1159} INFO - Dependencies all met for <TaskInstance: BRONZER_GET_STONCKS.BRONZE_GOOG scheduled__2024-01-13T00:00:00+00:00 [queued]>
[2024-09-15 20:17:47,411] {taskinstance.py:1356} INFO - 
--------------------------------------------------------------------------------
[2024-09-15 20:17:47,411] {taskinstance.py:1357} INFO - Starting attempt 1 of 1
[2024-09-15 20:17:47,411] {taskinstance.py:1358} INFO - 
--------------------------------------------------------------------------------
[2024-09-15 20:17:47,423] {taskinstance.py:1377} INFO - Executing <Task(_PythonDecoratedOperator): BRONZE_GOOG> on 2024-01-13 00:00:00+00:00
[2024-09-15 20:17:47,425] {standard_task_runner.py:52} INFO - Started process 14060 to run task
[2024-09-15 20:17:47,427] {standard_task_runner.py:79} INFO - Running: ['airflow', 'tasks', 'run', 'BRONZER_GET_STONCKS', 'BRONZE_GOOG', 'scheduled__2024-01-13T00:00:00+00:00', '--job-id', '98', '--raw', '--subdir', 'DAGS_FOLDER/get_stocks.py', '--cfg-path', '/tmp/tmp7_egnzt3', '--error-file', '/tmp/tmpbyb_ovmi']
[2024-09-15 20:17:47,427] {standard_task_runner.py:80} INFO - Job 98: Subtask BRONZE_GOOG
[2024-09-15 20:17:47,459] {task_command.py:370} INFO - Running <TaskInstance: BRONZER_GET_STONCKS.BRONZE_GOOG scheduled__2024-01-13T00:00:00+00:00 [running]> on host kaiwang.
[2024-09-15 20:17:47,500] {taskinstance.py:1569} INFO - Exporting the following env vars:
AIRFLOW_CTX_DAG_OWNER=airflow
AIRFLOW_CTX_DAG_ID=BRONZER_GET_STONCKS
AIRFLOW_CTX_TASK_ID=BRONZE_GOOG
AIRFLOW_CTX_EXECUTION_DATE=2024-01-13T00:00:00+00:00
AIRFLOW_CTX_TRY_NUMBER=1
AIRFLOW_CTX_DAG_RUN_ID=scheduled__2024-01-13T00:00:00+00:00
[2024-09-15 20:17:50,529] {history.py:244} ERROR - $GOOG: possibly delisted; no price data found  (1h 2024-01-10 -> 2024-01-03) (Yahoo error = "Invalid input - start date cannot be after end date. startDate = 1704862800, endDate = 1704258000")
[2024-09-15 20:17:50,531] {python.py:173} INFO - Done. Returned value was: None
[2024-09-15 20:17:50,537] {taskinstance.py:1395} INFO - Marking task as SUCCESS. dag_id=BRONZER_GET_STONCKS, task_id=BRONZE_GOOG, execution_date=20240113T000000, start_date=20240915T231747, end_date=20240915T231750
[2024-09-15 20:17:50,587] {local_task_job.py:156} INFO - Task exited with return code 0
[2024-09-15 20:17:50,598] {local_task_job.py:273} INFO - 0 downstream tasks scheduled from follow-on schedule check
