[2024-09-15 20:04:36,021] {taskinstance.py:1159} INFO - Dependencies all met for <TaskInstance: BRONZER_GET_STONCKS.BRONZE_TSLA scheduled__2024-01-23T00:00:00+00:00 [queued]>
[2024-09-15 20:04:36,025] {taskinstance.py:1159} INFO - Dependencies all met for <TaskInstance: BRONZER_GET_STONCKS.BRONZE_TSLA scheduled__2024-01-23T00:00:00+00:00 [queued]>
[2024-09-15 20:04:36,025] {taskinstance.py:1356} INFO - 
--------------------------------------------------------------------------------
[2024-09-15 20:04:36,025] {taskinstance.py:1357} INFO - Starting attempt 1 of 1
[2024-09-15 20:04:36,025] {taskinstance.py:1358} INFO - 
--------------------------------------------------------------------------------
[2024-09-15 20:04:36,035] {taskinstance.py:1377} INFO - Executing <Task(_PythonDecoratedOperator): BRONZE_TSLA> on 2024-01-23 00:00:00+00:00
[2024-09-15 20:04:36,037] {standard_task_runner.py:52} INFO - Started process 11696 to run task
[2024-09-15 20:04:36,039] {standard_task_runner.py:79} INFO - Running: ['airflow', 'tasks', 'run', 'BRONZER_GET_STONCKS', 'BRONZE_TSLA', 'scheduled__2024-01-23T00:00:00+00:00', '--job-id', '72', '--raw', '--subdir', 'DAGS_FOLDER/get_stocks.py', '--cfg-path', '/tmp/tmpl3_icumb', '--error-file', '/tmp/tmpk_bz2rv6']
[2024-09-15 20:04:36,040] {standard_task_runner.py:80} INFO - Job 72: Subtask BRONZE_TSLA
[2024-09-15 20:04:36,067] {task_command.py:370} INFO - Running <TaskInstance: BRONZER_GET_STONCKS.BRONZE_TSLA scheduled__2024-01-23T00:00:00+00:00 [running]> on host kaiwang.
[2024-09-15 20:04:36,106] {taskinstance.py:1569} INFO - Exporting the following env vars:
AIRFLOW_CTX_DAG_OWNER=airflow
AIRFLOW_CTX_DAG_ID=BRONZER_GET_STONCKS
AIRFLOW_CTX_TASK_ID=BRONZE_TSLA
AIRFLOW_CTX_EXECUTION_DATE=2024-01-23T00:00:00+00:00
AIRFLOW_CTX_TRY_NUMBER=1
AIRFLOW_CTX_DAG_RUN_ID=scheduled__2024-01-23T00:00:00+00:00
[2024-09-15 20:04:36,107] {taskinstance.py:1889} ERROR - Task failed with exception
Traceback (most recent call last):
  File "/usr/lib/python3.10/pathlib.py", line 1175, in mkdir
    self._accessor.mkdir(self, mode)
FileNotFoundError: [Errno 2] No such file or directory: '/datalake/TSLA'

During handling of the above exception, another exception occurred:

Traceback (most recent call last):
  File "/home/kaiwang/Documents/airflow_celeby/venv/lib/python3.10/site-packages/airflow/decorators/base.py", line 179, in execute
    return_value = super().execute(context)
  File "/home/kaiwang/Documents/airflow_celeby/venv/lib/python3.10/site-packages/airflow/operators/python.py", line 171, in execute
    return_value = self.execute_callable()
  File "/home/kaiwang/Documents/airflow_celeby/venv/lib/python3.10/site-packages/airflow/operators/python.py", line 189, in execute_callable
    return self.python_callable(*self.op_args, **self.op_kwargs)
  File "/home/kaiwang/Documents/airflow_celeby/dags/get_stocks.py", line 21, in get_history
    (Path(file_path).parent).mkdir(parents=True, exist_ok=True)
  File "/usr/lib/python3.10/pathlib.py", line 1179, in mkdir
    self.parent.mkdir(parents=True, exist_ok=True)
  File "/usr/lib/python3.10/pathlib.py", line 1175, in mkdir
    self._accessor.mkdir(self, mode)
PermissionError: [Errno 13] Permission denied: '/datalake'
[2024-09-15 20:04:36,110] {taskinstance.py:1395} INFO - Marking task as FAILED. dag_id=BRONZER_GET_STONCKS, task_id=BRONZE_TSLA, execution_date=20240123T000000, start_date=20240915T230436, end_date=20240915T230436
[2024-09-15 20:04:36,118] {standard_task_runner.py:92} ERROR - Failed to execute job 72 for task BRONZE_TSLA ([Errno 13] Permission denied: '/datalake'; 11696)
[2024-09-15 20:04:36,132] {local_task_job.py:156} INFO - Task exited with return code 1
[2024-09-15 20:04:36,142] {local_task_job.py:273} INFO - 0 downstream tasks scheduled from follow-on schedule check
[2024-09-15 20:11:53,036] {taskinstance.py:1159} INFO - Dependencies all met for <TaskInstance: BRONZER_GET_STONCKS.BRONZE_TSLA scheduled__2024-01-23T00:00:00+00:00 [queued]>
[2024-09-15 20:11:53,042] {taskinstance.py:1159} INFO - Dependencies all met for <TaskInstance: BRONZER_GET_STONCKS.BRONZE_TSLA scheduled__2024-01-23T00:00:00+00:00 [queued]>
[2024-09-15 20:11:53,042] {taskinstance.py:1356} INFO - 
--------------------------------------------------------------------------------
[2024-09-15 20:11:53,042] {taskinstance.py:1357} INFO - Starting attempt 1 of 1
[2024-09-15 20:11:53,042] {taskinstance.py:1358} INFO - 
--------------------------------------------------------------------------------
[2024-09-15 20:11:53,054] {taskinstance.py:1377} INFO - Executing <Task(_PythonDecoratedOperator): BRONZE_TSLA> on 2024-01-23 00:00:00+00:00
[2024-09-15 20:11:53,058] {standard_task_runner.py:52} INFO - Started process 13032 to run task
[2024-09-15 20:11:53,061] {standard_task_runner.py:79} INFO - Running: ['airflow', 'tasks', 'run', 'BRONZER_GET_STONCKS', 'BRONZE_TSLA', 'scheduled__2024-01-23T00:00:00+00:00', '--job-id', '123', '--raw', '--subdir', 'DAGS_FOLDER/get_stocks.py', '--cfg-path', '/tmp/tmpwpa2n31u', '--error-file', '/tmp/tmpswojojnc']
[2024-09-15 20:11:53,062] {standard_task_runner.py:80} INFO - Job 123: Subtask BRONZE_TSLA
[2024-09-15 20:11:53,099] {task_command.py:370} INFO - Running <TaskInstance: BRONZER_GET_STONCKS.BRONZE_TSLA scheduled__2024-01-23T00:00:00+00:00 [running]> on host kaiwang.
[2024-09-15 20:11:53,145] {taskinstance.py:1569} INFO - Exporting the following env vars:
AIRFLOW_CTX_DAG_OWNER=airflow
AIRFLOW_CTX_DAG_ID=BRONZER_GET_STONCKS
AIRFLOW_CTX_TASK_ID=BRONZE_TSLA
AIRFLOW_CTX_EXECUTION_DATE=2024-01-23T00:00:00+00:00
AIRFLOW_CTX_TRY_NUMBER=1
AIRFLOW_CTX_DAG_RUN_ID=scheduled__2024-01-23T00:00:00+00:00
[2024-09-15 20:11:53,146] {taskinstance.py:1889} ERROR - Task failed with exception
Traceback (most recent call last):
  File "/usr/lib/python3.10/pathlib.py", line 1175, in mkdir
    self._accessor.mkdir(self, mode)
FileNotFoundError: [Errno 2] No such file or directory: '/Documents/airflow_celeby/datalake/TSLA'

During handling of the above exception, another exception occurred:

Traceback (most recent call last):
  File "/usr/lib/python3.10/pathlib.py", line 1175, in mkdir
    self._accessor.mkdir(self, mode)
FileNotFoundError: [Errno 2] No such file or directory: '/Documents/airflow_celeby/datalake'

During handling of the above exception, another exception occurred:

Traceback (most recent call last):
  File "/usr/lib/python3.10/pathlib.py", line 1175, in mkdir
    self._accessor.mkdir(self, mode)
FileNotFoundError: [Errno 2] No such file or directory: '/Documents/airflow_celeby'

During handling of the above exception, another exception occurred:

Traceback (most recent call last):
  File "/home/kaiwang/Documents/airflow_celeby/venv/lib/python3.10/site-packages/airflow/decorators/base.py", line 179, in execute
    return_value = super().execute(context)
  File "/home/kaiwang/Documents/airflow_celeby/venv/lib/python3.10/site-packages/airflow/operators/python.py", line 171, in execute
    return_value = self.execute_callable()
  File "/home/kaiwang/Documents/airflow_celeby/venv/lib/python3.10/site-packages/airflow/operators/python.py", line 189, in execute_callable
    return self.python_callable(*self.op_args, **self.op_kwargs)
  File "/home/kaiwang/Documents/airflow_celeby/dags/get_stocks.py", line 21, in get_history
    (Path(file_path).parent).mkdir(parents=True, exist_ok=True)
  File "/usr/lib/python3.10/pathlib.py", line 1179, in mkdir
    self.parent.mkdir(parents=True, exist_ok=True)
  File "/usr/lib/python3.10/pathlib.py", line 1179, in mkdir
    self.parent.mkdir(parents=True, exist_ok=True)
  File "/usr/lib/python3.10/pathlib.py", line 1179, in mkdir
    self.parent.mkdir(parents=True, exist_ok=True)
  File "/usr/lib/python3.10/pathlib.py", line 1175, in mkdir
    self._accessor.mkdir(self, mode)
PermissionError: [Errno 13] Permission denied: '/Documents'
[2024-09-15 20:11:53,150] {taskinstance.py:1395} INFO - Marking task as FAILED. dag_id=BRONZER_GET_STONCKS, task_id=BRONZE_TSLA, execution_date=20240123T000000, start_date=20240915T231153, end_date=20240915T231153
[2024-09-15 20:11:53,160] {standard_task_runner.py:92} ERROR - Failed to execute job 123 for task BRONZE_TSLA ([Errno 13] Permission denied: '/Documents'; 13032)
[2024-09-15 20:11:53,193] {local_task_job.py:156} INFO - Task exited with return code 1
[2024-09-15 20:11:53,206] {local_task_job.py:273} INFO - 0 downstream tasks scheduled from follow-on schedule check
[2024-09-15 20:11:53,211] {dagrun.py:547} ERROR - Marking run <DagRun BRONZER_GET_STONCKS @ 2024-01-23 00:00:00+00:00: scheduled__2024-01-23T00:00:00+00:00, externally triggered: False> failed
[2024-09-15 20:11:53,211] {dagrun.py:607} INFO - DagRun Finished: dag_id=BRONZER_GET_STONCKS, execution_date=2024-01-23 00:00:00+00:00, run_id=scheduled__2024-01-23T00:00:00+00:00, run_start_date=2024-09-15 23:11:47.758702+00:00, run_end_date=2024-09-15 23:11:53.211717+00:00, run_duration=5.453015, state=failed, external_trigger=False, run_type=scheduled, data_interval_start=2024-01-23 00:00:00+00:00, data_interval_end=2024-01-24 00:00:00+00:00, dag_hash=d881e529ddca44bbc90b852447cd3348
[2024-09-15 23:28:15,760] {taskinstance.py:1159} INFO - Dependencies all met for <TaskInstance: BRONZER_GET_STONCKS.BRONZE_TSLA scheduled__2024-01-23T00:00:00+00:00 [queued]>
[2024-09-15 23:28:15,765] {taskinstance.py:1159} INFO - Dependencies all met for <TaskInstance: BRONZER_GET_STONCKS.BRONZE_TSLA scheduled__2024-01-23T00:00:00+00:00 [queued]>
[2024-09-15 23:28:15,765] {taskinstance.py:1356} INFO - 
--------------------------------------------------------------------------------
[2024-09-15 23:28:15,765] {taskinstance.py:1357} INFO - Starting attempt 1 of 1
[2024-09-15 23:28:15,765] {taskinstance.py:1358} INFO - 
--------------------------------------------------------------------------------
[2024-09-15 23:28:15,776] {taskinstance.py:1377} INFO - Executing <Task(_PythonDecoratedOperator): BRONZE_TSLA> on 2024-01-23 00:00:00+00:00
[2024-09-15 23:28:15,778] {standard_task_runner.py:52} INFO - Started process 14375 to run task
[2024-09-15 23:28:15,781] {standard_task_runner.py:79} INFO - Running: ['airflow', 'tasks', 'run', 'BRONZER_GET_STONCKS', 'BRONZE_TSLA', 'scheduled__2024-01-23T00:00:00+00:00', '--job-id', '123', '--raw', '--subdir', 'DAGS_FOLDER/get_stocks.py', '--cfg-path', '/tmp/tmplr57pzzl', '--error-file', '/tmp/tmpahdj4frt']
[2024-09-15 23:28:15,781] {standard_task_runner.py:80} INFO - Job 123: Subtask BRONZE_TSLA
[2024-09-15 23:28:15,809] {task_command.py:370} INFO - Running <TaskInstance: BRONZER_GET_STONCKS.BRONZE_TSLA scheduled__2024-01-23T00:00:00+00:00 [running]> on host kaiwang.
[2024-09-15 23:28:15,851] {taskinstance.py:1569} INFO - Exporting the following env vars:
AIRFLOW_CTX_DAG_OWNER=airflow
AIRFLOW_CTX_DAG_ID=BRONZER_GET_STONCKS
AIRFLOW_CTX_TASK_ID=BRONZE_TSLA
AIRFLOW_CTX_EXECUTION_DATE=2024-01-23T00:00:00+00:00
AIRFLOW_CTX_TRY_NUMBER=1
AIRFLOW_CTX_DAG_RUN_ID=scheduled__2024-01-23T00:00:00+00:00
[2024-09-15 23:28:18,687] {history.py:244} ERROR - $TSLA: possibly delisted; no price data found  (1h 2024-01-20 -> 2024-01-03) (Yahoo error = "Invalid input - start date cannot be after end date. startDate = 1705726800, endDate = 1704258000")
[2024-09-15 23:28:18,689] {python.py:173} INFO - Done. Returned value was: None
[2024-09-15 23:28:18,693] {taskinstance.py:1395} INFO - Marking task as SUCCESS. dag_id=BRONZER_GET_STONCKS, task_id=BRONZE_TSLA, execution_date=20240123T000000, start_date=20240916T022815, end_date=20240916T022818
[2024-09-15 23:28:18,731] {local_task_job.py:156} INFO - Task exited with return code 0
[2024-09-15 23:28:18,745] {local_task_job.py:273} INFO - 0 downstream tasks scheduled from follow-on schedule check
