[2024-09-15 20:03:50,320] {taskinstance.py:1159} INFO - Dependencies all met for <TaskInstance: BRONZER_GET_STONCKS.BRONZE_GOOG scheduled__2024-01-11T00:00:00+00:00 [queued]>
[2024-09-15 20:03:50,324] {taskinstance.py:1159} INFO - Dependencies all met for <TaskInstance: BRONZER_GET_STONCKS.BRONZE_GOOG scheduled__2024-01-11T00:00:00+00:00 [queued]>
[2024-09-15 20:03:50,325] {taskinstance.py:1356} INFO - 
--------------------------------------------------------------------------------
[2024-09-15 20:03:50,325] {taskinstance.py:1357} INFO - Starting attempt 1 of 1
[2024-09-15 20:03:50,325] {taskinstance.py:1358} INFO - 
--------------------------------------------------------------------------------
[2024-09-15 20:03:50,337] {taskinstance.py:1377} INFO - Executing <Task(_PythonDecoratedOperator): BRONZE_GOOG> on 2024-01-11 00:00:00+00:00
[2024-09-15 20:03:50,340] {standard_task_runner.py:52} INFO - Started process 11395 to run task
[2024-09-15 20:03:50,342] {standard_task_runner.py:79} INFO - Running: ['airflow', 'tasks', 'run', 'BRONZER_GET_STONCKS', 'BRONZE_GOOG', 'scheduled__2024-01-11T00:00:00+00:00', '--job-id', '39', '--raw', '--subdir', 'DAGS_FOLDER/get_stocks.py', '--cfg-path', '/tmp/tmph838pwnu', '--error-file', '/tmp/tmpdbgtng3g']
[2024-09-15 20:03:50,342] {standard_task_runner.py:80} INFO - Job 39: Subtask BRONZE_GOOG
[2024-09-15 20:03:50,372] {task_command.py:370} INFO - Running <TaskInstance: BRONZER_GET_STONCKS.BRONZE_GOOG scheduled__2024-01-11T00:00:00+00:00 [running]> on host kaiwang.
[2024-09-15 20:03:50,413] {taskinstance.py:1569} INFO - Exporting the following env vars:
AIRFLOW_CTX_DAG_OWNER=airflow
AIRFLOW_CTX_DAG_ID=BRONZER_GET_STONCKS
AIRFLOW_CTX_TASK_ID=BRONZE_GOOG
AIRFLOW_CTX_EXECUTION_DATE=2024-01-11T00:00:00+00:00
AIRFLOW_CTX_TRY_NUMBER=1
AIRFLOW_CTX_DAG_RUN_ID=scheduled__2024-01-11T00:00:00+00:00
[2024-09-15 20:03:50,414] {taskinstance.py:1889} ERROR - Task failed with exception
Traceback (most recent call last):
  File "/usr/lib/python3.10/pathlib.py", line 1175, in mkdir
    self._accessor.mkdir(self, mode)
FileNotFoundError: [Errno 2] No such file or directory: '/datalake/GOOG'

During handling of the above exception, another exception occurred:

Traceback (most recent call last):
  File "/home/kaiwang/Documents/airflow_celeby/venv/lib/python3.10/site-packages/airflow/decorators/base.py", line 179, in execute
    return_value = super().execute(context)
  File "/home/kaiwang/Documents/airflow_celeby/venv/lib/python3.10/site-packages/airflow/operators/python.py", line 171, in execute
    return_value = self.execute_callable()
  File "/home/kaiwang/Documents/airflow_celeby/venv/lib/python3.10/site-packages/airflow/operators/python.py", line 189, in execute_callable
    return self.python_callable(*self.op_args, **self.op_kwargs)
  File "/home/kaiwang/Documents/airflow_celeby/dags/get_stocks.py", line 21, in get_history
    (Path(file_path).parent).mkdir(parents=True, exist_ok=True)
  File "/usr/lib/python3.10/pathlib.py", line 1179, in mkdir
    self.parent.mkdir(parents=True, exist_ok=True)
  File "/usr/lib/python3.10/pathlib.py", line 1175, in mkdir
    self._accessor.mkdir(self, mode)
PermissionError: [Errno 13] Permission denied: '/datalake'
[2024-09-15 20:03:50,416] {taskinstance.py:1395} INFO - Marking task as FAILED. dag_id=BRONZER_GET_STONCKS, task_id=BRONZE_GOOG, execution_date=20240111T000000, start_date=20240915T230350, end_date=20240915T230350
[2024-09-15 20:03:50,425] {standard_task_runner.py:92} ERROR - Failed to execute job 39 for task BRONZE_GOOG ([Errno 13] Permission denied: '/datalake'; 11395)
[2024-09-15 20:03:50,435] {local_task_job.py:156} INFO - Task exited with return code 1
[2024-09-15 20:03:50,450] {local_task_job.py:273} INFO - 0 downstream tasks scheduled from follow-on schedule check
[2024-09-15 20:06:35,095] {taskinstance.py:1159} INFO - Dependencies all met for <TaskInstance: BRONZER_GET_STONCKS.BRONZE_GOOG scheduled__2024-01-11T00:00:00+00:00 [queued]>
[2024-09-15 20:06:35,099] {taskinstance.py:1159} INFO - Dependencies all met for <TaskInstance: BRONZER_GET_STONCKS.BRONZE_GOOG scheduled__2024-01-11T00:00:00+00:00 [queued]>
[2024-09-15 20:06:35,099] {taskinstance.py:1356} INFO - 
--------------------------------------------------------------------------------
[2024-09-15 20:06:35,099] {taskinstance.py:1357} INFO - Starting attempt 1 of 1
[2024-09-15 20:06:35,099] {taskinstance.py:1358} INFO - 
--------------------------------------------------------------------------------
[2024-09-15 20:06:35,110] {taskinstance.py:1377} INFO - Executing <Task(_PythonDecoratedOperator): BRONZE_GOOG> on 2024-01-11 00:00:00+00:00
[2024-09-15 20:06:35,112] {standard_task_runner.py:52} INFO - Started process 12105 to run task
[2024-09-15 20:06:35,114] {standard_task_runner.py:79} INFO - Running: ['airflow', 'tasks', 'run', 'BRONZER_GET_STONCKS', 'BRONZE_GOOG', 'scheduled__2024-01-11T00:00:00+00:00', '--job-id', '41', '--raw', '--subdir', 'DAGS_FOLDER/get_stocks.py', '--cfg-path', '/tmp/tmpbngjvnxd', '--error-file', '/tmp/tmpwsed50vw']
[2024-09-15 20:06:35,115] {standard_task_runner.py:80} INFO - Job 41: Subtask BRONZE_GOOG
[2024-09-15 20:06:35,141] {task_command.py:370} INFO - Running <TaskInstance: BRONZER_GET_STONCKS.BRONZE_GOOG scheduled__2024-01-11T00:00:00+00:00 [running]> on host kaiwang.
[2024-09-15 20:06:35,180] {taskinstance.py:1569} INFO - Exporting the following env vars:
AIRFLOW_CTX_DAG_OWNER=airflow
AIRFLOW_CTX_DAG_ID=BRONZER_GET_STONCKS
AIRFLOW_CTX_TASK_ID=BRONZE_GOOG
AIRFLOW_CTX_EXECUTION_DATE=2024-01-11T00:00:00+00:00
AIRFLOW_CTX_TRY_NUMBER=1
AIRFLOW_CTX_DAG_RUN_ID=scheduled__2024-01-11T00:00:00+00:00
[2024-09-15 20:06:35,181] {taskinstance.py:1889} ERROR - Task failed with exception
Traceback (most recent call last):
  File "/usr/lib/python3.10/pathlib.py", line 1175, in mkdir
    self._accessor.mkdir(self, mode)
FileNotFoundError: [Errno 2] No such file or directory: '/datalake/GOOG'

During handling of the above exception, another exception occurred:

Traceback (most recent call last):
  File "/home/kaiwang/Documents/airflow_celeby/venv/lib/python3.10/site-packages/airflow/decorators/base.py", line 179, in execute
    return_value = super().execute(context)
  File "/home/kaiwang/Documents/airflow_celeby/venv/lib/python3.10/site-packages/airflow/operators/python.py", line 171, in execute
    return_value = self.execute_callable()
  File "/home/kaiwang/Documents/airflow_celeby/venv/lib/python3.10/site-packages/airflow/operators/python.py", line 189, in execute_callable
    return self.python_callable(*self.op_args, **self.op_kwargs)
  File "/home/kaiwang/Documents/airflow_celeby/dags/get_stocks.py", line 21, in get_history
    (Path(file_path).parent).mkdir(parents=True, exist_ok=True)
  File "/usr/lib/python3.10/pathlib.py", line 1179, in mkdir
    self.parent.mkdir(parents=True, exist_ok=True)
  File "/usr/lib/python3.10/pathlib.py", line 1175, in mkdir
    self._accessor.mkdir(self, mode)
PermissionError: [Errno 13] Permission denied: '/datalake'
[2024-09-15 20:06:35,183] {taskinstance.py:1395} INFO - Marking task as FAILED. dag_id=BRONZER_GET_STONCKS, task_id=BRONZE_GOOG, execution_date=20240111T000000, start_date=20240915T230635, end_date=20240915T230635
[2024-09-15 20:06:35,192] {standard_task_runner.py:92} ERROR - Failed to execute job 41 for task BRONZE_GOOG ([Errno 13] Permission denied: '/datalake'; 12105)
[2024-09-15 20:06:35,207] {local_task_job.py:156} INFO - Task exited with return code 1
[2024-09-15 20:06:35,216] {local_task_job.py:273} INFO - 0 downstream tasks scheduled from follow-on schedule check
[2024-09-15 20:10:05,535] {taskinstance.py:1159} INFO - Dependencies all met for <TaskInstance: BRONZER_GET_STONCKS.BRONZE_GOOG scheduled__2024-01-11T00:00:00+00:00 [queued]>
[2024-09-15 20:10:05,540] {taskinstance.py:1159} INFO - Dependencies all met for <TaskInstance: BRONZER_GET_STONCKS.BRONZE_GOOG scheduled__2024-01-11T00:00:00+00:00 [queued]>
[2024-09-15 20:10:05,540] {taskinstance.py:1356} INFO - 
--------------------------------------------------------------------------------
[2024-09-15 20:10:05,540] {taskinstance.py:1357} INFO - Starting attempt 1 of 1
[2024-09-15 20:10:05,540] {taskinstance.py:1358} INFO - 
--------------------------------------------------------------------------------
[2024-09-15 20:10:05,552] {taskinstance.py:1377} INFO - Executing <Task(_PythonDecoratedOperator): BRONZE_GOOG> on 2024-01-11 00:00:00+00:00
[2024-09-15 20:10:05,554] {standard_task_runner.py:52} INFO - Started process 12701 to run task
[2024-09-15 20:10:05,556] {standard_task_runner.py:79} INFO - Running: ['airflow', 'tasks', 'run', 'BRONZER_GET_STONCKS', 'BRONZE_GOOG', 'scheduled__2024-01-11T00:00:00+00:00', '--job-id', '90', '--raw', '--subdir', 'DAGS_FOLDER/get_stocks.py', '--cfg-path', '/tmp/tmpreev2c3e', '--error-file', '/tmp/tmpn3mq9n_r']
[2024-09-15 20:10:05,557] {standard_task_runner.py:80} INFO - Job 90: Subtask BRONZE_GOOG
[2024-09-15 20:10:05,585] {task_command.py:370} INFO - Running <TaskInstance: BRONZER_GET_STONCKS.BRONZE_GOOG scheduled__2024-01-11T00:00:00+00:00 [running]> on host kaiwang.
[2024-09-15 20:10:05,624] {taskinstance.py:1569} INFO - Exporting the following env vars:
AIRFLOW_CTX_DAG_OWNER=airflow
AIRFLOW_CTX_DAG_ID=BRONZER_GET_STONCKS
AIRFLOW_CTX_TASK_ID=BRONZE_GOOG
AIRFLOW_CTX_EXECUTION_DATE=2024-01-11T00:00:00+00:00
AIRFLOW_CTX_TRY_NUMBER=1
AIRFLOW_CTX_DAG_RUN_ID=scheduled__2024-01-11T00:00:00+00:00
[2024-09-15 20:10:10,678] {history.py:244} ERROR - $GOOG: possibly delisted; no price data found  (1h 2024-01-08 -> 2024-01-03) (Yahoo error = "Invalid input - start date cannot be after end date. startDate = 1704690000, endDate = 1704258000")
[2024-09-15 20:10:10,681] {python.py:173} INFO - Done. Returned value was: None
[2024-09-15 20:10:10,686] {taskinstance.py:1395} INFO - Marking task as SUCCESS. dag_id=BRONZER_GET_STONCKS, task_id=BRONZE_GOOG, execution_date=20240111T000000, start_date=20240915T231005, end_date=20240915T231010
[2024-09-15 20:10:10,702] {local_task_job.py:156} INFO - Task exited with return code 0
[2024-09-15 20:10:10,710] {local_task_job.py:273} INFO - 0 downstream tasks scheduled from follow-on schedule check
[2024-09-15 20:13:11,175] {taskinstance.py:1159} INFO - Dependencies all met for <TaskInstance: BRONZER_GET_STONCKS.BRONZE_GOOG scheduled__2024-01-11T00:00:00+00:00 [queued]>
[2024-09-15 20:13:11,180] {taskinstance.py:1159} INFO - Dependencies all met for <TaskInstance: BRONZER_GET_STONCKS.BRONZE_GOOG scheduled__2024-01-11T00:00:00+00:00 [queued]>
[2024-09-15 20:13:11,180] {taskinstance.py:1356} INFO - 
--------------------------------------------------------------------------------
[2024-09-15 20:13:11,180] {taskinstance.py:1357} INFO - Starting attempt 1 of 1
[2024-09-15 20:13:11,180] {taskinstance.py:1358} INFO - 
--------------------------------------------------------------------------------
[2024-09-15 20:13:11,190] {taskinstance.py:1377} INFO - Executing <Task(_PythonDecoratedOperator): BRONZE_GOOG> on 2024-01-11 00:00:00+00:00
[2024-09-15 20:13:11,193] {standard_task_runner.py:52} INFO - Started process 13325 to run task
[2024-09-15 20:13:11,195] {standard_task_runner.py:79} INFO - Running: ['airflow', 'tasks', 'run', 'BRONZER_GET_STONCKS', 'BRONZE_GOOG', 'scheduled__2024-01-11T00:00:00+00:00', '--job-id', '90', '--raw', '--subdir', 'DAGS_FOLDER/get_stocks.py', '--cfg-path', '/tmp/tmpmkmyxm3j', '--error-file', '/tmp/tmpp8viid3j']
[2024-09-15 20:13:11,195] {standard_task_runner.py:80} INFO - Job 90: Subtask BRONZE_GOOG
[2024-09-15 20:13:11,222] {task_command.py:370} INFO - Running <TaskInstance: BRONZER_GET_STONCKS.BRONZE_GOOG scheduled__2024-01-11T00:00:00+00:00 [running]> on host kaiwang.
[2024-09-15 20:13:11,265] {taskinstance.py:1569} INFO - Exporting the following env vars:
AIRFLOW_CTX_DAG_OWNER=airflow
AIRFLOW_CTX_DAG_ID=BRONZER_GET_STONCKS
AIRFLOW_CTX_TASK_ID=BRONZE_GOOG
AIRFLOW_CTX_EXECUTION_DATE=2024-01-11T00:00:00+00:00
AIRFLOW_CTX_TRY_NUMBER=1
AIRFLOW_CTX_DAG_RUN_ID=scheduled__2024-01-11T00:00:00+00:00
[2024-09-15 20:13:11,266] {taskinstance.py:1889} ERROR - Task failed with exception
Traceback (most recent call last):
  File "/usr/lib/python3.10/pathlib.py", line 1175, in mkdir
    self._accessor.mkdir(self, mode)
FileNotFoundError: [Errno 2] No such file or directory: '/Documents/airflow_celeby/datalake/GOOG'

During handling of the above exception, another exception occurred:

Traceback (most recent call last):
  File "/usr/lib/python3.10/pathlib.py", line 1175, in mkdir
    self._accessor.mkdir(self, mode)
FileNotFoundError: [Errno 2] No such file or directory: '/Documents/airflow_celeby/datalake'

During handling of the above exception, another exception occurred:

Traceback (most recent call last):
  File "/usr/lib/python3.10/pathlib.py", line 1175, in mkdir
    self._accessor.mkdir(self, mode)
FileNotFoundError: [Errno 2] No such file or directory: '/Documents/airflow_celeby'

During handling of the above exception, another exception occurred:

Traceback (most recent call last):
  File "/home/kaiwang/Documents/airflow_celeby/venv/lib/python3.10/site-packages/airflow/decorators/base.py", line 179, in execute
    return_value = super().execute(context)
  File "/home/kaiwang/Documents/airflow_celeby/venv/lib/python3.10/site-packages/airflow/operators/python.py", line 171, in execute
    return_value = self.execute_callable()
  File "/home/kaiwang/Documents/airflow_celeby/venv/lib/python3.10/site-packages/airflow/operators/python.py", line 189, in execute_callable
    return self.python_callable(*self.op_args, **self.op_kwargs)
  File "/home/kaiwang/Documents/airflow_celeby/dags/get_stocks.py", line 21, in get_history
    (Path(file_path).parent).mkdir(parents=True, exist_ok=True)
  File "/usr/lib/python3.10/pathlib.py", line 1179, in mkdir
    self.parent.mkdir(parents=True, exist_ok=True)
  File "/usr/lib/python3.10/pathlib.py", line 1179, in mkdir
    self.parent.mkdir(parents=True, exist_ok=True)
  File "/usr/lib/python3.10/pathlib.py", line 1179, in mkdir
    self.parent.mkdir(parents=True, exist_ok=True)
  File "/usr/lib/python3.10/pathlib.py", line 1175, in mkdir
    self._accessor.mkdir(self, mode)
PermissionError: [Errno 13] Permission denied: '/Documents'
[2024-09-15 20:13:11,269] {taskinstance.py:1395} INFO - Marking task as FAILED. dag_id=BRONZER_GET_STONCKS, task_id=BRONZE_GOOG, execution_date=20240111T000000, start_date=20240915T231311, end_date=20240915T231311
[2024-09-15 20:13:11,277] {standard_task_runner.py:92} ERROR - Failed to execute job 90 for task BRONZE_GOOG ([Errno 13] Permission denied: '/Documents'; 13325)
[2024-09-15 20:13:11,288] {local_task_job.py:156} INFO - Task exited with return code 1
[2024-09-15 20:13:11,297] {local_task_job.py:273} INFO - 0 downstream tasks scheduled from follow-on schedule check
[2024-09-15 20:17:09,243] {taskinstance.py:1159} INFO - Dependencies all met for <TaskInstance: BRONZER_GET_STONCKS.BRONZE_GOOG scheduled__2024-01-11T00:00:00+00:00 [queued]>
[2024-09-15 20:17:09,248] {taskinstance.py:1159} INFO - Dependencies all met for <TaskInstance: BRONZER_GET_STONCKS.BRONZE_GOOG scheduled__2024-01-11T00:00:00+00:00 [queued]>
[2024-09-15 20:17:09,248] {taskinstance.py:1356} INFO - 
--------------------------------------------------------------------------------
[2024-09-15 20:17:09,248] {taskinstance.py:1357} INFO - Starting attempt 1 of 1
[2024-09-15 20:17:09,248] {taskinstance.py:1358} INFO - 
--------------------------------------------------------------------------------
[2024-09-15 20:17:09,259] {taskinstance.py:1377} INFO - Executing <Task(_PythonDecoratedOperator): BRONZE_GOOG> on 2024-01-11 00:00:00+00:00
[2024-09-15 20:17:09,261] {standard_task_runner.py:52} INFO - Started process 13987 to run task
[2024-09-15 20:17:09,263] {standard_task_runner.py:79} INFO - Running: ['airflow', 'tasks', 'run', 'BRONZER_GET_STONCKS', 'BRONZE_GOOG', 'scheduled__2024-01-11T00:00:00+00:00', '--job-id', '90', '--raw', '--subdir', 'DAGS_FOLDER/get_stocks.py', '--cfg-path', '/tmp/tmp50_u6blm', '--error-file', '/tmp/tmprh8hoewp']
[2024-09-15 20:17:09,264] {standard_task_runner.py:80} INFO - Job 90: Subtask BRONZE_GOOG
[2024-09-15 20:17:09,291] {task_command.py:370} INFO - Running <TaskInstance: BRONZER_GET_STONCKS.BRONZE_GOOG scheduled__2024-01-11T00:00:00+00:00 [running]> on host kaiwang.
[2024-09-15 20:17:09,332] {taskinstance.py:1569} INFO - Exporting the following env vars:
AIRFLOW_CTX_DAG_OWNER=airflow
AIRFLOW_CTX_DAG_ID=BRONZER_GET_STONCKS
AIRFLOW_CTX_TASK_ID=BRONZE_GOOG
AIRFLOW_CTX_EXECUTION_DATE=2024-01-11T00:00:00+00:00
AIRFLOW_CTX_TRY_NUMBER=1
AIRFLOW_CTX_DAG_RUN_ID=scheduled__2024-01-11T00:00:00+00:00
[2024-09-15 20:17:12,701] {history.py:244} ERROR - $GOOG: possibly delisted; no price data found  (1h 2024-01-08 -> 2024-01-03) (Yahoo error = "Invalid input - start date cannot be after end date. startDate = 1704690000, endDate = 1704258000")
[2024-09-15 20:17:12,707] {python.py:173} INFO - Done. Returned value was: None
[2024-09-15 20:17:12,717] {taskinstance.py:1395} INFO - Marking task as SUCCESS. dag_id=BRONZER_GET_STONCKS, task_id=BRONZE_GOOG, execution_date=20240111T000000, start_date=20240915T231709, end_date=20240915T231712
[2024-09-15 20:17:12,742] {local_task_job.py:156} INFO - Task exited with return code 0
[2024-09-15 20:17:12,753] {local_task_job.py:273} INFO - 0 downstream tasks scheduled from follow-on schedule check
