[2024-09-15 20:04:32,134] {taskinstance.py:1159} INFO - Dependencies all met for <TaskInstance: BRONZER_GET_STONCKS.BRONZE_AAPL scheduled__2024-01-23T00:00:00+00:00 [queued]>
[2024-09-15 20:04:32,138] {taskinstance.py:1159} INFO - Dependencies all met for <TaskInstance: BRONZER_GET_STONCKS.BRONZE_AAPL scheduled__2024-01-23T00:00:00+00:00 [queued]>
[2024-09-15 20:04:32,138] {taskinstance.py:1356} INFO - 
--------------------------------------------------------------------------------
[2024-09-15 20:04:32,138] {taskinstance.py:1357} INFO - Starting attempt 1 of 1
[2024-09-15 20:04:32,138] {taskinstance.py:1358} INFO - 
--------------------------------------------------------------------------------
[2024-09-15 20:04:32,149] {taskinstance.py:1377} INFO - Executing <Task(_PythonDecoratedOperator): BRONZE_AAPL> on 2024-01-23 00:00:00+00:00
[2024-09-15 20:04:32,151] {standard_task_runner.py:52} INFO - Started process 11669 to run task
[2024-09-15 20:04:32,154] {standard_task_runner.py:79} INFO - Running: ['airflow', 'tasks', 'run', 'BRONZER_GET_STONCKS', 'BRONZE_AAPL', 'scheduled__2024-01-23T00:00:00+00:00', '--job-id', '69', '--raw', '--subdir', 'DAGS_FOLDER/get_stocks.py', '--cfg-path', '/tmp/tmpncsejznb', '--error-file', '/tmp/tmp3hnv1q63']
[2024-09-15 20:04:32,154] {standard_task_runner.py:80} INFO - Job 69: Subtask BRONZE_AAPL
[2024-09-15 20:04:32,184] {task_command.py:370} INFO - Running <TaskInstance: BRONZER_GET_STONCKS.BRONZE_AAPL scheduled__2024-01-23T00:00:00+00:00 [running]> on host kaiwang.
[2024-09-15 20:04:32,224] {taskinstance.py:1569} INFO - Exporting the following env vars:
AIRFLOW_CTX_DAG_OWNER=airflow
AIRFLOW_CTX_DAG_ID=BRONZER_GET_STONCKS
AIRFLOW_CTX_TASK_ID=BRONZE_AAPL
AIRFLOW_CTX_EXECUTION_DATE=2024-01-23T00:00:00+00:00
AIRFLOW_CTX_TRY_NUMBER=1
AIRFLOW_CTX_DAG_RUN_ID=scheduled__2024-01-23T00:00:00+00:00
[2024-09-15 20:04:32,224] {taskinstance.py:1889} ERROR - Task failed with exception
Traceback (most recent call last):
  File "/usr/lib/python3.10/pathlib.py", line 1175, in mkdir
    self._accessor.mkdir(self, mode)
FileNotFoundError: [Errno 2] No such file or directory: '/datalake/AAPL'

During handling of the above exception, another exception occurred:

Traceback (most recent call last):
  File "/home/kaiwang/Documents/airflow_celeby/venv/lib/python3.10/site-packages/airflow/decorators/base.py", line 179, in execute
    return_value = super().execute(context)
  File "/home/kaiwang/Documents/airflow_celeby/venv/lib/python3.10/site-packages/airflow/operators/python.py", line 171, in execute
    return_value = self.execute_callable()
  File "/home/kaiwang/Documents/airflow_celeby/venv/lib/python3.10/site-packages/airflow/operators/python.py", line 189, in execute_callable
    return self.python_callable(*self.op_args, **self.op_kwargs)
  File "/home/kaiwang/Documents/airflow_celeby/dags/get_stocks.py", line 21, in get_history
    (Path(file_path).parent).mkdir(parents=True, exist_ok=True)
  File "/usr/lib/python3.10/pathlib.py", line 1179, in mkdir
    self.parent.mkdir(parents=True, exist_ok=True)
  File "/usr/lib/python3.10/pathlib.py", line 1175, in mkdir
    self._accessor.mkdir(self, mode)
PermissionError: [Errno 13] Permission denied: '/datalake'
[2024-09-15 20:04:32,227] {taskinstance.py:1395} INFO - Marking task as FAILED. dag_id=BRONZER_GET_STONCKS, task_id=BRONZE_AAPL, execution_date=20240123T000000, start_date=20240915T230432, end_date=20240915T230432
[2024-09-15 20:04:32,236] {standard_task_runner.py:92} ERROR - Failed to execute job 69 for task BRONZE_AAPL ([Errno 13] Permission denied: '/datalake'; 11669)
[2024-09-15 20:04:32,247] {local_task_job.py:156} INFO - Task exited with return code 1
[2024-09-15 20:04:32,257] {local_task_job.py:273} INFO - 0 downstream tasks scheduled from follow-on schedule check
[2024-09-15 20:11:48,764] {taskinstance.py:1159} INFO - Dependencies all met for <TaskInstance: BRONZER_GET_STONCKS.BRONZE_AAPL scheduled__2024-01-23T00:00:00+00:00 [queued]>
[2024-09-15 20:11:48,771] {taskinstance.py:1159} INFO - Dependencies all met for <TaskInstance: BRONZER_GET_STONCKS.BRONZE_AAPL scheduled__2024-01-23T00:00:00+00:00 [queued]>
[2024-09-15 20:11:48,771] {taskinstance.py:1356} INFO - 
--------------------------------------------------------------------------------
[2024-09-15 20:11:48,771] {taskinstance.py:1357} INFO - Starting attempt 1 of 1
[2024-09-15 20:11:48,771] {taskinstance.py:1358} INFO - 
--------------------------------------------------------------------------------
[2024-09-15 20:11:48,785] {taskinstance.py:1377} INFO - Executing <Task(_PythonDecoratedOperator): BRONZE_AAPL> on 2024-01-23 00:00:00+00:00
[2024-09-15 20:11:48,789] {standard_task_runner.py:52} INFO - Started process 13005 to run task
[2024-09-15 20:11:48,793] {standard_task_runner.py:79} INFO - Running: ['airflow', 'tasks', 'run', 'BRONZER_GET_STONCKS', 'BRONZE_AAPL', 'scheduled__2024-01-23T00:00:00+00:00', '--job-id', '120', '--raw', '--subdir', 'DAGS_FOLDER/get_stocks.py', '--cfg-path', '/tmp/tmpe5xibx1j', '--error-file', '/tmp/tmppbhpq_1i']
[2024-09-15 20:11:48,793] {standard_task_runner.py:80} INFO - Job 120: Subtask BRONZE_AAPL
[2024-09-15 20:11:48,835] {task_command.py:370} INFO - Running <TaskInstance: BRONZER_GET_STONCKS.BRONZE_AAPL scheduled__2024-01-23T00:00:00+00:00 [running]> on host kaiwang.
[2024-09-15 20:11:48,946] {taskinstance.py:1569} INFO - Exporting the following env vars:
AIRFLOW_CTX_DAG_OWNER=airflow
AIRFLOW_CTX_DAG_ID=BRONZER_GET_STONCKS
AIRFLOW_CTX_TASK_ID=BRONZE_AAPL
AIRFLOW_CTX_EXECUTION_DATE=2024-01-23T00:00:00+00:00
AIRFLOW_CTX_TRY_NUMBER=1
AIRFLOW_CTX_DAG_RUN_ID=scheduled__2024-01-23T00:00:00+00:00
[2024-09-15 20:11:48,950] {taskinstance.py:1889} ERROR - Task failed with exception
Traceback (most recent call last):
  File "/usr/lib/python3.10/pathlib.py", line 1175, in mkdir
    self._accessor.mkdir(self, mode)
FileNotFoundError: [Errno 2] No such file or directory: '/Documents/airflow_celeby/datalake/AAPL'

During handling of the above exception, another exception occurred:

Traceback (most recent call last):
  File "/usr/lib/python3.10/pathlib.py", line 1175, in mkdir
    self._accessor.mkdir(self, mode)
FileNotFoundError: [Errno 2] No such file or directory: '/Documents/airflow_celeby/datalake'

During handling of the above exception, another exception occurred:

Traceback (most recent call last):
  File "/usr/lib/python3.10/pathlib.py", line 1175, in mkdir
    self._accessor.mkdir(self, mode)
FileNotFoundError: [Errno 2] No such file or directory: '/Documents/airflow_celeby'

During handling of the above exception, another exception occurred:

Traceback (most recent call last):
  File "/home/kaiwang/Documents/airflow_celeby/venv/lib/python3.10/site-packages/airflow/decorators/base.py", line 179, in execute
    return_value = super().execute(context)
  File "/home/kaiwang/Documents/airflow_celeby/venv/lib/python3.10/site-packages/airflow/operators/python.py", line 171, in execute
    return_value = self.execute_callable()
  File "/home/kaiwang/Documents/airflow_celeby/venv/lib/python3.10/site-packages/airflow/operators/python.py", line 189, in execute_callable
    return self.python_callable(*self.op_args, **self.op_kwargs)
  File "/home/kaiwang/Documents/airflow_celeby/dags/get_stocks.py", line 21, in get_history
    (Path(file_path).parent).mkdir(parents=True, exist_ok=True)
  File "/usr/lib/python3.10/pathlib.py", line 1179, in mkdir
    self.parent.mkdir(parents=True, exist_ok=True)
  File "/usr/lib/python3.10/pathlib.py", line 1179, in mkdir
    self.parent.mkdir(parents=True, exist_ok=True)
  File "/usr/lib/python3.10/pathlib.py", line 1179, in mkdir
    self.parent.mkdir(parents=True, exist_ok=True)
  File "/usr/lib/python3.10/pathlib.py", line 1175, in mkdir
    self._accessor.mkdir(self, mode)
PermissionError: [Errno 13] Permission denied: '/Documents'
[2024-09-15 20:11:48,960] {taskinstance.py:1395} INFO - Marking task as FAILED. dag_id=BRONZER_GET_STONCKS, task_id=BRONZE_AAPL, execution_date=20240123T000000, start_date=20240915T231148, end_date=20240915T231148
[2024-09-15 20:11:48,978] {standard_task_runner.py:92} ERROR - Failed to execute job 120 for task BRONZE_AAPL ([Errno 13] Permission denied: '/Documents'; 13005)
[2024-09-15 20:11:49,006] {local_task_job.py:156} INFO - Task exited with return code 1
[2024-09-15 20:11:49,027] {local_task_job.py:273} INFO - 0 downstream tasks scheduled from follow-on schedule check
[2024-09-15 23:28:04,500] {taskinstance.py:1159} INFO - Dependencies all met for <TaskInstance: BRONZER_GET_STONCKS.BRONZE_AAPL scheduled__2024-01-23T00:00:00+00:00 [queued]>
[2024-09-15 23:28:04,504] {taskinstance.py:1159} INFO - Dependencies all met for <TaskInstance: BRONZER_GET_STONCKS.BRONZE_AAPL scheduled__2024-01-23T00:00:00+00:00 [queued]>
[2024-09-15 23:28:04,504] {taskinstance.py:1356} INFO - 
--------------------------------------------------------------------------------
[2024-09-15 23:28:04,504] {taskinstance.py:1357} INFO - Starting attempt 1 of 1
[2024-09-15 23:28:04,504] {taskinstance.py:1358} INFO - 
--------------------------------------------------------------------------------
[2024-09-15 23:28:04,517] {taskinstance.py:1377} INFO - Executing <Task(_PythonDecoratedOperator): BRONZE_AAPL> on 2024-01-23 00:00:00+00:00
[2024-09-15 23:28:04,520] {standard_task_runner.py:52} INFO - Started process 14344 to run task
[2024-09-15 23:28:04,522] {standard_task_runner.py:79} INFO - Running: ['airflow', 'tasks', 'run', 'BRONZER_GET_STONCKS', 'BRONZE_AAPL', 'scheduled__2024-01-23T00:00:00+00:00', '--job-id', '120', '--raw', '--subdir', 'DAGS_FOLDER/get_stocks.py', '--cfg-path', '/tmp/tmpxg50vdm4', '--error-file', '/tmp/tmpkr3i0w8l']
[2024-09-15 23:28:04,523] {standard_task_runner.py:80} INFO - Job 120: Subtask BRONZE_AAPL
[2024-09-15 23:28:04,551] {task_command.py:370} INFO - Running <TaskInstance: BRONZER_GET_STONCKS.BRONZE_AAPL scheduled__2024-01-23T00:00:00+00:00 [running]> on host kaiwang.
[2024-09-15 23:28:04,592] {taskinstance.py:1569} INFO - Exporting the following env vars:
AIRFLOW_CTX_DAG_OWNER=airflow
AIRFLOW_CTX_DAG_ID=BRONZER_GET_STONCKS
AIRFLOW_CTX_TASK_ID=BRONZE_AAPL
AIRFLOW_CTX_EXECUTION_DATE=2024-01-23T00:00:00+00:00
AIRFLOW_CTX_TRY_NUMBER=1
AIRFLOW_CTX_DAG_RUN_ID=scheduled__2024-01-23T00:00:00+00:00
[2024-09-15 23:28:07,558] {history.py:244} ERROR - $AAPL: possibly delisted; no price data found  (1h 2024-01-20 -> 2024-01-03) (Yahoo error = "Invalid input - start date cannot be after end date. startDate = 1705726800, endDate = 1704258000")
[2024-09-15 23:28:07,560] {python.py:173} INFO - Done. Returned value was: None
[2024-09-15 23:28:07,564] {taskinstance.py:1395} INFO - Marking task as SUCCESS. dag_id=BRONZER_GET_STONCKS, task_id=BRONZE_AAPL, execution_date=20240123T000000, start_date=20240916T022804, end_date=20240916T022807
[2024-09-15 23:28:07,596] {local_task_job.py:156} INFO - Task exited with return code 0
[2024-09-15 23:28:07,605] {local_task_job.py:273} INFO - 0 downstream tasks scheduled from follow-on schedule check
