[2024-09-15 20:04:10,201] {taskinstance.py:1159} INFO - Dependencies all met for <TaskInstance: BRONZER_GET_STONCKS.BRONZE_AAPL scheduled__2024-01-17T00:00:00+00:00 [queued]>
[2024-09-15 20:04:10,204] {taskinstance.py:1159} INFO - Dependencies all met for <TaskInstance: BRONZER_GET_STONCKS.BRONZE_AAPL scheduled__2024-01-17T00:00:00+00:00 [queued]>
[2024-09-15 20:04:10,204] {taskinstance.py:1356} INFO - 
--------------------------------------------------------------------------------
[2024-09-15 20:04:10,204] {taskinstance.py:1357} INFO - Starting attempt 1 of 1
[2024-09-15 20:04:10,204] {taskinstance.py:1358} INFO - 
--------------------------------------------------------------------------------
[2024-09-15 20:04:10,215] {taskinstance.py:1377} INFO - Executing <Task(_PythonDecoratedOperator): BRONZE_AAPL> on 2024-01-17 00:00:00+00:00
[2024-09-15 20:04:10,217] {standard_task_runner.py:52} INFO - Started process 11522 to run task
[2024-09-15 20:04:10,219] {standard_task_runner.py:79} INFO - Running: ['airflow', 'tasks', 'run', 'BRONZER_GET_STONCKS', 'BRONZE_AAPL', 'scheduled__2024-01-17T00:00:00+00:00', '--job-id', '53', '--raw', '--subdir', 'DAGS_FOLDER/get_stocks.py', '--cfg-path', '/tmp/tmp64tlqab8', '--error-file', '/tmp/tmplrwqsxnr']
[2024-09-15 20:04:10,219] {standard_task_runner.py:80} INFO - Job 53: Subtask BRONZE_AAPL
[2024-09-15 20:04:10,246] {task_command.py:370} INFO - Running <TaskInstance: BRONZER_GET_STONCKS.BRONZE_AAPL scheduled__2024-01-17T00:00:00+00:00 [running]> on host kaiwang.
[2024-09-15 20:04:10,284] {taskinstance.py:1569} INFO - Exporting the following env vars:
AIRFLOW_CTX_DAG_OWNER=airflow
AIRFLOW_CTX_DAG_ID=BRONZER_GET_STONCKS
AIRFLOW_CTX_TASK_ID=BRONZE_AAPL
AIRFLOW_CTX_EXECUTION_DATE=2024-01-17T00:00:00+00:00
AIRFLOW_CTX_TRY_NUMBER=1
AIRFLOW_CTX_DAG_RUN_ID=scheduled__2024-01-17T00:00:00+00:00
[2024-09-15 20:04:10,284] {taskinstance.py:1889} ERROR - Task failed with exception
Traceback (most recent call last):
  File "/usr/lib/python3.10/pathlib.py", line 1175, in mkdir
    self._accessor.mkdir(self, mode)
FileNotFoundError: [Errno 2] No such file or directory: '/datalake/AAPL'

During handling of the above exception, another exception occurred:

Traceback (most recent call last):
  File "/home/kaiwang/Documents/airflow_celeby/venv/lib/python3.10/site-packages/airflow/decorators/base.py", line 179, in execute
    return_value = super().execute(context)
  File "/home/kaiwang/Documents/airflow_celeby/venv/lib/python3.10/site-packages/airflow/operators/python.py", line 171, in execute
    return_value = self.execute_callable()
  File "/home/kaiwang/Documents/airflow_celeby/venv/lib/python3.10/site-packages/airflow/operators/python.py", line 189, in execute_callable
    return self.python_callable(*self.op_args, **self.op_kwargs)
  File "/home/kaiwang/Documents/airflow_celeby/dags/get_stocks.py", line 21, in get_history
    (Path(file_path).parent).mkdir(parents=True, exist_ok=True)
  File "/usr/lib/python3.10/pathlib.py", line 1179, in mkdir
    self.parent.mkdir(parents=True, exist_ok=True)
  File "/usr/lib/python3.10/pathlib.py", line 1175, in mkdir
    self._accessor.mkdir(self, mode)
PermissionError: [Errno 13] Permission denied: '/datalake'
[2024-09-15 20:04:10,287] {taskinstance.py:1395} INFO - Marking task as FAILED. dag_id=BRONZER_GET_STONCKS, task_id=BRONZE_AAPL, execution_date=20240117T000000, start_date=20240915T230410, end_date=20240915T230410
[2024-09-15 20:04:10,295] {standard_task_runner.py:92} ERROR - Failed to execute job 53 for task BRONZE_AAPL ([Errno 13] Permission denied: '/datalake'; 11522)
[2024-09-15 20:04:10,312] {local_task_job.py:156} INFO - Task exited with return code 1
[2024-09-15 20:04:10,339] {local_task_job.py:273} INFO - 0 downstream tasks scheduled from follow-on schedule check
[2024-09-15 20:07:19,840] {taskinstance.py:1159} INFO - Dependencies all met for <TaskInstance: BRONZER_GET_STONCKS.BRONZE_AAPL scheduled__2024-01-17T00:00:00+00:00 [queued]>
[2024-09-15 20:07:19,847] {taskinstance.py:1159} INFO - Dependencies all met for <TaskInstance: BRONZER_GET_STONCKS.BRONZE_AAPL scheduled__2024-01-17T00:00:00+00:00 [queued]>
[2024-09-15 20:07:19,847] {taskinstance.py:1356} INFO - 
--------------------------------------------------------------------------------
[2024-09-15 20:07:19,847] {taskinstance.py:1357} INFO - Starting attempt 1 of 1
[2024-09-15 20:07:19,847] {taskinstance.py:1358} INFO - 
--------------------------------------------------------------------------------
[2024-09-15 20:07:19,861] {taskinstance.py:1377} INFO - Executing <Task(_PythonDecoratedOperator): BRONZE_AAPL> on 2024-01-17 00:00:00+00:00
[2024-09-15 20:07:19,864] {standard_task_runner.py:52} INFO - Started process 12339 to run task
[2024-09-15 20:07:19,868] {standard_task_runner.py:79} INFO - Running: ['airflow', 'tasks', 'run', 'BRONZER_GET_STONCKS', 'BRONZE_AAPL', 'scheduled__2024-01-17T00:00:00+00:00', '--job-id', '60', '--raw', '--subdir', 'DAGS_FOLDER/get_stocks.py', '--cfg-path', '/tmp/tmpy8r9sr7r', '--error-file', '/tmp/tmpt435hnaa']
[2024-09-15 20:07:19,869] {standard_task_runner.py:80} INFO - Job 60: Subtask BRONZE_AAPL
[2024-09-15 20:07:19,925] {task_command.py:370} INFO - Running <TaskInstance: BRONZER_GET_STONCKS.BRONZE_AAPL scheduled__2024-01-17T00:00:00+00:00 [running]> on host kaiwang.
[2024-09-15 20:07:19,983] {taskinstance.py:1569} INFO - Exporting the following env vars:
AIRFLOW_CTX_DAG_OWNER=airflow
AIRFLOW_CTX_DAG_ID=BRONZER_GET_STONCKS
AIRFLOW_CTX_TASK_ID=BRONZE_AAPL
AIRFLOW_CTX_EXECUTION_DATE=2024-01-17T00:00:00+00:00
AIRFLOW_CTX_TRY_NUMBER=1
AIRFLOW_CTX_DAG_RUN_ID=scheduled__2024-01-17T00:00:00+00:00
[2024-09-15 20:07:23,431] {history.py:244} ERROR - $AAPL: possibly delisted; no price data found  (1h 2024-01-14 -> 2024-01-03) (Yahoo error = "Invalid input - start date cannot be after end date. startDate = 1705208400, endDate = 1704258000")
[2024-09-15 20:07:23,439] {python.py:173} INFO - Done. Returned value was: None
[2024-09-15 20:07:23,447] {taskinstance.py:1395} INFO - Marking task as SUCCESS. dag_id=BRONZER_GET_STONCKS, task_id=BRONZE_AAPL, execution_date=20240117T000000, start_date=20240915T230719, end_date=20240915T230723
[2024-09-15 20:07:23,463] {local_task_job.py:156} INFO - Task exited with return code 0
[2024-09-15 20:07:23,474] {local_task_job.py:273} INFO - 0 downstream tasks scheduled from follow-on schedule check
[2024-09-15 20:11:09,059] {taskinstance.py:1159} INFO - Dependencies all met for <TaskInstance: BRONZER_GET_STONCKS.BRONZE_AAPL scheduled__2024-01-17T00:00:00+00:00 [queued]>
[2024-09-15 20:11:09,064] {taskinstance.py:1159} INFO - Dependencies all met for <TaskInstance: BRONZER_GET_STONCKS.BRONZE_AAPL scheduled__2024-01-17T00:00:00+00:00 [queued]>
[2024-09-15 20:11:09,064] {taskinstance.py:1356} INFO - 
--------------------------------------------------------------------------------
[2024-09-15 20:11:09,064] {taskinstance.py:1357} INFO - Starting attempt 1 of 1
[2024-09-15 20:11:09,064] {taskinstance.py:1358} INFO - 
--------------------------------------------------------------------------------
[2024-09-15 20:11:09,075] {taskinstance.py:1377} INFO - Executing <Task(_PythonDecoratedOperator): BRONZE_AAPL> on 2024-01-17 00:00:00+00:00
[2024-09-15 20:11:09,078] {standard_task_runner.py:52} INFO - Started process 12849 to run task
[2024-09-15 20:11:09,080] {standard_task_runner.py:79} INFO - Running: ['airflow', 'tasks', 'run', 'BRONZER_GET_STONCKS', 'BRONZE_AAPL', 'scheduled__2024-01-17T00:00:00+00:00', '--job-id', '104', '--raw', '--subdir', 'DAGS_FOLDER/get_stocks.py', '--cfg-path', '/tmp/tmprdj_mspj', '--error-file', '/tmp/tmpnft9uqfi']
[2024-09-15 20:11:09,081] {standard_task_runner.py:80} INFO - Job 104: Subtask BRONZE_AAPL
[2024-09-15 20:11:09,108] {task_command.py:370} INFO - Running <TaskInstance: BRONZER_GET_STONCKS.BRONZE_AAPL scheduled__2024-01-17T00:00:00+00:00 [running]> on host kaiwang.
[2024-09-15 20:11:09,147] {taskinstance.py:1569} INFO - Exporting the following env vars:
AIRFLOW_CTX_DAG_OWNER=airflow
AIRFLOW_CTX_DAG_ID=BRONZER_GET_STONCKS
AIRFLOW_CTX_TASK_ID=BRONZE_AAPL
AIRFLOW_CTX_EXECUTION_DATE=2024-01-17T00:00:00+00:00
AIRFLOW_CTX_TRY_NUMBER=1
AIRFLOW_CTX_DAG_RUN_ID=scheduled__2024-01-17T00:00:00+00:00
[2024-09-15 20:11:09,148] {taskinstance.py:1889} ERROR - Task failed with exception
Traceback (most recent call last):
  File "/usr/lib/python3.10/pathlib.py", line 1175, in mkdir
    self._accessor.mkdir(self, mode)
FileNotFoundError: [Errno 2] No such file or directory: '/datalake/AAPL'

During handling of the above exception, another exception occurred:

Traceback (most recent call last):
  File "/home/kaiwang/Documents/airflow_celeby/venv/lib/python3.10/site-packages/airflow/decorators/base.py", line 179, in execute
    return_value = super().execute(context)
  File "/home/kaiwang/Documents/airflow_celeby/venv/lib/python3.10/site-packages/airflow/operators/python.py", line 171, in execute
    return_value = self.execute_callable()
  File "/home/kaiwang/Documents/airflow_celeby/venv/lib/python3.10/site-packages/airflow/operators/python.py", line 189, in execute_callable
    return self.python_callable(*self.op_args, **self.op_kwargs)
  File "/home/kaiwang/Documents/airflow_celeby/dags/get_stocks.py", line 21, in get_history
    (Path(file_path).parent).mkdir(parents=True, exist_ok=True)
  File "/usr/lib/python3.10/pathlib.py", line 1179, in mkdir
    self.parent.mkdir(parents=True, exist_ok=True)
  File "/usr/lib/python3.10/pathlib.py", line 1175, in mkdir
    self._accessor.mkdir(self, mode)
PermissionError: [Errno 13] Permission denied: '/datalake'
[2024-09-15 20:11:09,151] {taskinstance.py:1395} INFO - Marking task as FAILED. dag_id=BRONZER_GET_STONCKS, task_id=BRONZE_AAPL, execution_date=20240117T000000, start_date=20240915T231109, end_date=20240915T231109
[2024-09-15 20:11:09,160] {standard_task_runner.py:92} ERROR - Failed to execute job 104 for task BRONZE_AAPL ([Errno 13] Permission denied: '/datalake'; 12849)
[2024-09-15 20:11:09,173] {local_task_job.py:156} INFO - Task exited with return code 1
[2024-09-15 20:11:09,183] {local_task_job.py:273} INFO - 0 downstream tasks scheduled from follow-on schedule check
[2024-09-15 20:13:32,343] {taskinstance.py:1159} INFO - Dependencies all met for <TaskInstance: BRONZER_GET_STONCKS.BRONZE_AAPL scheduled__2024-01-17T00:00:00+00:00 [queued]>
[2024-09-15 20:13:32,347] {taskinstance.py:1159} INFO - Dependencies all met for <TaskInstance: BRONZER_GET_STONCKS.BRONZE_AAPL scheduled__2024-01-17T00:00:00+00:00 [queued]>
[2024-09-15 20:13:32,347] {taskinstance.py:1356} INFO - 
--------------------------------------------------------------------------------
[2024-09-15 20:13:32,347] {taskinstance.py:1357} INFO - Starting attempt 1 of 1
[2024-09-15 20:13:32,347] {taskinstance.py:1358} INFO - 
--------------------------------------------------------------------------------
[2024-09-15 20:13:32,360] {taskinstance.py:1377} INFO - Executing <Task(_PythonDecoratedOperator): BRONZE_AAPL> on 2024-01-17 00:00:00+00:00
[2024-09-15 20:13:32,362] {standard_task_runner.py:52} INFO - Started process 13453 to run task
[2024-09-15 20:13:32,364] {standard_task_runner.py:79} INFO - Running: ['airflow', 'tasks', 'run', 'BRONZER_GET_STONCKS', 'BRONZE_AAPL', 'scheduled__2024-01-17T00:00:00+00:00', '--job-id', '104', '--raw', '--subdir', 'DAGS_FOLDER/get_stocks.py', '--cfg-path', '/tmp/tmp1pwt87gd', '--error-file', '/tmp/tmpyhojhi7c']
[2024-09-15 20:13:32,365] {standard_task_runner.py:80} INFO - Job 104: Subtask BRONZE_AAPL
[2024-09-15 20:13:32,391] {task_command.py:370} INFO - Running <TaskInstance: BRONZER_GET_STONCKS.BRONZE_AAPL scheduled__2024-01-17T00:00:00+00:00 [running]> on host kaiwang.
[2024-09-15 20:13:32,428] {taskinstance.py:1569} INFO - Exporting the following env vars:
AIRFLOW_CTX_DAG_OWNER=airflow
AIRFLOW_CTX_DAG_ID=BRONZER_GET_STONCKS
AIRFLOW_CTX_TASK_ID=BRONZE_AAPL
AIRFLOW_CTX_EXECUTION_DATE=2024-01-17T00:00:00+00:00
AIRFLOW_CTX_TRY_NUMBER=1
AIRFLOW_CTX_DAG_RUN_ID=scheduled__2024-01-17T00:00:00+00:00
[2024-09-15 20:13:32,429] {taskinstance.py:1889} ERROR - Task failed with exception
Traceback (most recent call last):
  File "/usr/lib/python3.10/pathlib.py", line 1175, in mkdir
    self._accessor.mkdir(self, mode)
FileNotFoundError: [Errno 2] No such file or directory: '/Documents/airflow_celeby/datalake/AAPL'

During handling of the above exception, another exception occurred:

Traceback (most recent call last):
  File "/usr/lib/python3.10/pathlib.py", line 1175, in mkdir
    self._accessor.mkdir(self, mode)
FileNotFoundError: [Errno 2] No such file or directory: '/Documents/airflow_celeby/datalake'

During handling of the above exception, another exception occurred:

Traceback (most recent call last):
  File "/usr/lib/python3.10/pathlib.py", line 1175, in mkdir
    self._accessor.mkdir(self, mode)
FileNotFoundError: [Errno 2] No such file or directory: '/Documents/airflow_celeby'

During handling of the above exception, another exception occurred:

Traceback (most recent call last):
  File "/home/kaiwang/Documents/airflow_celeby/venv/lib/python3.10/site-packages/airflow/decorators/base.py", line 179, in execute
    return_value = super().execute(context)
  File "/home/kaiwang/Documents/airflow_celeby/venv/lib/python3.10/site-packages/airflow/operators/python.py", line 171, in execute
    return_value = self.execute_callable()
  File "/home/kaiwang/Documents/airflow_celeby/venv/lib/python3.10/site-packages/airflow/operators/python.py", line 189, in execute_callable
    return self.python_callable(*self.op_args, **self.op_kwargs)
  File "/home/kaiwang/Documents/airflow_celeby/dags/get_stocks.py", line 21, in get_history
    (Path(file_path).parent).mkdir(parents=True, exist_ok=True)
  File "/usr/lib/python3.10/pathlib.py", line 1179, in mkdir
    self.parent.mkdir(parents=True, exist_ok=True)
  File "/usr/lib/python3.10/pathlib.py", line 1179, in mkdir
    self.parent.mkdir(parents=True, exist_ok=True)
  File "/usr/lib/python3.10/pathlib.py", line 1179, in mkdir
    self.parent.mkdir(parents=True, exist_ok=True)
  File "/usr/lib/python3.10/pathlib.py", line 1175, in mkdir
    self._accessor.mkdir(self, mode)
PermissionError: [Errno 13] Permission denied: '/Documents'
[2024-09-15 20:13:32,431] {taskinstance.py:1395} INFO - Marking task as FAILED. dag_id=BRONZER_GET_STONCKS, task_id=BRONZE_AAPL, execution_date=20240117T000000, start_date=20240915T231332, end_date=20240915T231332
[2024-09-15 20:13:32,439] {standard_task_runner.py:92} ERROR - Failed to execute job 104 for task BRONZE_AAPL ([Errno 13] Permission denied: '/Documents'; 13453)
[2024-09-15 20:13:32,457] {local_task_job.py:156} INFO - Task exited with return code 1
[2024-09-15 20:13:32,473] {local_task_job.py:273} INFO - 0 downstream tasks scheduled from follow-on schedule check
[2024-09-15 20:18:17,740] {taskinstance.py:1159} INFO - Dependencies all met for <TaskInstance: BRONZER_GET_STONCKS.BRONZE_AAPL scheduled__2024-01-17T00:00:00+00:00 [queued]>
[2024-09-15 20:18:17,745] {taskinstance.py:1159} INFO - Dependencies all met for <TaskInstance: BRONZER_GET_STONCKS.BRONZE_AAPL scheduled__2024-01-17T00:00:00+00:00 [queued]>
[2024-09-15 20:18:17,745] {taskinstance.py:1356} INFO - 
--------------------------------------------------------------------------------
[2024-09-15 20:18:17,745] {taskinstance.py:1357} INFO - Starting attempt 1 of 1
[2024-09-15 20:18:17,745] {taskinstance.py:1358} INFO - 
--------------------------------------------------------------------------------
[2024-09-15 20:18:17,757] {taskinstance.py:1377} INFO - Executing <Task(_PythonDecoratedOperator): BRONZE_AAPL> on 2024-01-17 00:00:00+00:00
[2024-09-15 20:18:17,759] {standard_task_runner.py:52} INFO - Started process 14115 to run task
[2024-09-15 20:18:17,761] {standard_task_runner.py:79} INFO - Running: ['airflow', 'tasks', 'run', 'BRONZER_GET_STONCKS', 'BRONZE_AAPL', 'scheduled__2024-01-17T00:00:00+00:00', '--job-id', '104', '--raw', '--subdir', 'DAGS_FOLDER/get_stocks.py', '--cfg-path', '/tmp/tmpo5ph4kzb', '--error-file', '/tmp/tmpengaf3h0']
[2024-09-15 20:18:17,761] {standard_task_runner.py:80} INFO - Job 104: Subtask BRONZE_AAPL
[2024-09-15 20:18:17,792] {task_command.py:370} INFO - Running <TaskInstance: BRONZER_GET_STONCKS.BRONZE_AAPL scheduled__2024-01-17T00:00:00+00:00 [running]> on host kaiwang.
[2024-09-15 20:18:17,833] {taskinstance.py:1569} INFO - Exporting the following env vars:
AIRFLOW_CTX_DAG_OWNER=airflow
AIRFLOW_CTX_DAG_ID=BRONZER_GET_STONCKS
AIRFLOW_CTX_TASK_ID=BRONZE_AAPL
AIRFLOW_CTX_EXECUTION_DATE=2024-01-17T00:00:00+00:00
AIRFLOW_CTX_TRY_NUMBER=1
AIRFLOW_CTX_DAG_RUN_ID=scheduled__2024-01-17T00:00:00+00:00
[2024-09-15 20:18:21,935] {history.py:244} ERROR - $AAPL: possibly delisted; no price data found  (1h 2024-01-14 -> 2024-01-03) (Yahoo error = "Invalid input - start date cannot be after end date. startDate = 1705208400, endDate = 1704258000")
[2024-09-15 20:18:21,941] {python.py:173} INFO - Done. Returned value was: None
[2024-09-15 20:18:21,949] {taskinstance.py:1395} INFO - Marking task as SUCCESS. dag_id=BRONZER_GET_STONCKS, task_id=BRONZE_AAPL, execution_date=20240117T000000, start_date=20240915T231817, end_date=20240915T231821
[2024-09-15 20:18:21,967] {local_task_job.py:156} INFO - Task exited with return code 0
[2024-09-15 20:18:21,977] {local_task_job.py:273} INFO - 0 downstream tasks scheduled from follow-on schedule check
