[2024-09-15 20:04:05,235] {taskinstance.py:1159} INFO - Dependencies all met for <TaskInstance: BRONZER_GET_STONCKS.BRONZE_AAPL scheduled__2024-01-16T00:00:00+00:00 [queued]>
[2024-09-15 20:04:05,239] {taskinstance.py:1159} INFO - Dependencies all met for <TaskInstance: BRONZER_GET_STONCKS.BRONZE_AAPL scheduled__2024-01-16T00:00:00+00:00 [queued]>
[2024-09-15 20:04:05,239] {taskinstance.py:1356} INFO - 
--------------------------------------------------------------------------------
[2024-09-15 20:04:05,239] {taskinstance.py:1357} INFO - Starting attempt 1 of 1
[2024-09-15 20:04:05,239] {taskinstance.py:1358} INFO - 
--------------------------------------------------------------------------------
[2024-09-15 20:04:05,249] {taskinstance.py:1377} INFO - Executing <Task(_PythonDecoratedOperator): BRONZE_AAPL> on 2024-01-16 00:00:00+00:00
[2024-09-15 20:04:05,252] {standard_task_runner.py:52} INFO - Started process 11486 to run task
[2024-09-15 20:04:05,255] {standard_task_runner.py:79} INFO - Running: ['airflow', 'tasks', 'run', 'BRONZER_GET_STONCKS', 'BRONZE_AAPL', 'scheduled__2024-01-16T00:00:00+00:00', '--job-id', '49', '--raw', '--subdir', 'DAGS_FOLDER/get_stocks.py', '--cfg-path', '/tmp/tmpldjp8isr', '--error-file', '/tmp/tmp7xasc40r']
[2024-09-15 20:04:05,255] {standard_task_runner.py:80} INFO - Job 49: Subtask BRONZE_AAPL
[2024-09-15 20:04:05,287] {task_command.py:370} INFO - Running <TaskInstance: BRONZER_GET_STONCKS.BRONZE_AAPL scheduled__2024-01-16T00:00:00+00:00 [running]> on host kaiwang.
[2024-09-15 20:04:05,326] {taskinstance.py:1569} INFO - Exporting the following env vars:
AIRFLOW_CTX_DAG_OWNER=airflow
AIRFLOW_CTX_DAG_ID=BRONZER_GET_STONCKS
AIRFLOW_CTX_TASK_ID=BRONZE_AAPL
AIRFLOW_CTX_EXECUTION_DATE=2024-01-16T00:00:00+00:00
AIRFLOW_CTX_TRY_NUMBER=1
AIRFLOW_CTX_DAG_RUN_ID=scheduled__2024-01-16T00:00:00+00:00
[2024-09-15 20:04:05,327] {taskinstance.py:1889} ERROR - Task failed with exception
Traceback (most recent call last):
  File "/usr/lib/python3.10/pathlib.py", line 1175, in mkdir
    self._accessor.mkdir(self, mode)
FileNotFoundError: [Errno 2] No such file or directory: '/datalake/AAPL'

During handling of the above exception, another exception occurred:

Traceback (most recent call last):
  File "/home/kaiwang/Documents/airflow_celeby/venv/lib/python3.10/site-packages/airflow/decorators/base.py", line 179, in execute
    return_value = super().execute(context)
  File "/home/kaiwang/Documents/airflow_celeby/venv/lib/python3.10/site-packages/airflow/operators/python.py", line 171, in execute
    return_value = self.execute_callable()
  File "/home/kaiwang/Documents/airflow_celeby/venv/lib/python3.10/site-packages/airflow/operators/python.py", line 189, in execute_callable
    return self.python_callable(*self.op_args, **self.op_kwargs)
  File "/home/kaiwang/Documents/airflow_celeby/dags/get_stocks.py", line 21, in get_history
    (Path(file_path).parent).mkdir(parents=True, exist_ok=True)
  File "/usr/lib/python3.10/pathlib.py", line 1179, in mkdir
    self.parent.mkdir(parents=True, exist_ok=True)
  File "/usr/lib/python3.10/pathlib.py", line 1175, in mkdir
    self._accessor.mkdir(self, mode)
PermissionError: [Errno 13] Permission denied: '/datalake'
[2024-09-15 20:04:05,329] {taskinstance.py:1395} INFO - Marking task as FAILED. dag_id=BRONZER_GET_STONCKS, task_id=BRONZE_AAPL, execution_date=20240116T000000, start_date=20240915T230405, end_date=20240915T230405
[2024-09-15 20:04:05,338] {standard_task_runner.py:92} ERROR - Failed to execute job 49 for task BRONZE_AAPL ([Errno 13] Permission denied: '/datalake'; 11486)
[2024-09-15 20:04:05,347] {local_task_job.py:156} INFO - Task exited with return code 1
[2024-09-15 20:04:05,356] {local_task_job.py:273} INFO - 0 downstream tasks scheduled from follow-on schedule check
[2024-09-15 20:06:50,441] {taskinstance.py:1159} INFO - Dependencies all met for <TaskInstance: BRONZER_GET_STONCKS.BRONZE_AAPL scheduled__2024-01-16T00:00:00+00:00 [queued]>
[2024-09-15 20:06:50,446] {taskinstance.py:1159} INFO - Dependencies all met for <TaskInstance: BRONZER_GET_STONCKS.BRONZE_AAPL scheduled__2024-01-16T00:00:00+00:00 [queued]>
[2024-09-15 20:06:50,446] {taskinstance.py:1356} INFO - 
--------------------------------------------------------------------------------
[2024-09-15 20:06:50,446] {taskinstance.py:1357} INFO - Starting attempt 1 of 1
[2024-09-15 20:06:50,446] {taskinstance.py:1358} INFO - 
--------------------------------------------------------------------------------
[2024-09-15 20:06:50,456] {taskinstance.py:1377} INFO - Executing <Task(_PythonDecoratedOperator): BRONZE_AAPL> on 2024-01-16 00:00:00+00:00
[2024-09-15 20:06:50,459] {standard_task_runner.py:52} INFO - Started process 12198 to run task
[2024-09-15 20:06:50,461] {standard_task_runner.py:79} INFO - Running: ['airflow', 'tasks', 'run', 'BRONZER_GET_STONCKS', 'BRONZE_AAPL', 'scheduled__2024-01-16T00:00:00+00:00', '--job-id', '51', '--raw', '--subdir', 'DAGS_FOLDER/get_stocks.py', '--cfg-path', '/tmp/tmpp_wl1fve', '--error-file', '/tmp/tmp_u0y3mcf']
[2024-09-15 20:06:50,461] {standard_task_runner.py:80} INFO - Job 51: Subtask BRONZE_AAPL
[2024-09-15 20:06:50,489] {task_command.py:370} INFO - Running <TaskInstance: BRONZER_GET_STONCKS.BRONZE_AAPL scheduled__2024-01-16T00:00:00+00:00 [running]> on host kaiwang.
[2024-09-15 20:06:50,530] {taskinstance.py:1569} INFO - Exporting the following env vars:
AIRFLOW_CTX_DAG_OWNER=airflow
AIRFLOW_CTX_DAG_ID=BRONZER_GET_STONCKS
AIRFLOW_CTX_TASK_ID=BRONZE_AAPL
AIRFLOW_CTX_EXECUTION_DATE=2024-01-16T00:00:00+00:00
AIRFLOW_CTX_TRY_NUMBER=1
AIRFLOW_CTX_DAG_RUN_ID=scheduled__2024-01-16T00:00:00+00:00
[2024-09-15 20:06:50,531] {taskinstance.py:1889} ERROR - Task failed with exception
Traceback (most recent call last):
  File "/usr/lib/python3.10/pathlib.py", line 1175, in mkdir
    self._accessor.mkdir(self, mode)
FileNotFoundError: [Errno 2] No such file or directory: '/datalake/AAPL'

During handling of the above exception, another exception occurred:

Traceback (most recent call last):
  File "/home/kaiwang/Documents/airflow_celeby/venv/lib/python3.10/site-packages/airflow/decorators/base.py", line 179, in execute
    return_value = super().execute(context)
  File "/home/kaiwang/Documents/airflow_celeby/venv/lib/python3.10/site-packages/airflow/operators/python.py", line 171, in execute
    return_value = self.execute_callable()
  File "/home/kaiwang/Documents/airflow_celeby/venv/lib/python3.10/site-packages/airflow/operators/python.py", line 189, in execute_callable
    return self.python_callable(*self.op_args, **self.op_kwargs)
  File "/home/kaiwang/Documents/airflow_celeby/dags/get_stocks.py", line 21, in get_history
    (Path(file_path).parent).mkdir(parents=True, exist_ok=True)
  File "/usr/lib/python3.10/pathlib.py", line 1179, in mkdir
    self.parent.mkdir(parents=True, exist_ok=True)
  File "/usr/lib/python3.10/pathlib.py", line 1175, in mkdir
    self._accessor.mkdir(self, mode)
PermissionError: [Errno 13] Permission denied: '/datalake'
[2024-09-15 20:06:50,533] {taskinstance.py:1395} INFO - Marking task as FAILED. dag_id=BRONZER_GET_STONCKS, task_id=BRONZE_AAPL, execution_date=20240116T000000, start_date=20240915T230650, end_date=20240915T230650
[2024-09-15 20:06:50,542] {standard_task_runner.py:92} ERROR - Failed to execute job 51 for task BRONZE_AAPL ([Errno 13] Permission denied: '/datalake'; 12198)
[2024-09-15 20:06:50,554] {local_task_job.py:156} INFO - Task exited with return code 1
[2024-09-15 20:06:50,563] {local_task_job.py:273} INFO - 0 downstream tasks scheduled from follow-on schedule check
[2024-09-15 20:11:03,625] {taskinstance.py:1159} INFO - Dependencies all met for <TaskInstance: BRONZER_GET_STONCKS.BRONZE_AAPL scheduled__2024-01-16T00:00:00+00:00 [queued]>
[2024-09-15 20:11:03,629] {taskinstance.py:1159} INFO - Dependencies all met for <TaskInstance: BRONZER_GET_STONCKS.BRONZE_AAPL scheduled__2024-01-16T00:00:00+00:00 [queued]>
[2024-09-15 20:11:03,629] {taskinstance.py:1356} INFO - 
--------------------------------------------------------------------------------
[2024-09-15 20:11:03,629] {taskinstance.py:1357} INFO - Starting attempt 1 of 1
[2024-09-15 20:11:03,629] {taskinstance.py:1358} INFO - 
--------------------------------------------------------------------------------
[2024-09-15 20:11:03,641] {taskinstance.py:1377} INFO - Executing <Task(_PythonDecoratedOperator): BRONZE_AAPL> on 2024-01-16 00:00:00+00:00
[2024-09-15 20:11:03,643] {standard_task_runner.py:52} INFO - Started process 12813 to run task
[2024-09-15 20:11:03,646] {standard_task_runner.py:79} INFO - Running: ['airflow', 'tasks', 'run', 'BRONZER_GET_STONCKS', 'BRONZE_AAPL', 'scheduled__2024-01-16T00:00:00+00:00', '--job-id', '100', '--raw', '--subdir', 'DAGS_FOLDER/get_stocks.py', '--cfg-path', '/tmp/tmpc_8evnc_', '--error-file', '/tmp/tmp31ny7wls']
[2024-09-15 20:11:03,646] {standard_task_runner.py:80} INFO - Job 100: Subtask BRONZE_AAPL
[2024-09-15 20:11:03,674] {task_command.py:370} INFO - Running <TaskInstance: BRONZER_GET_STONCKS.BRONZE_AAPL scheduled__2024-01-16T00:00:00+00:00 [running]> on host kaiwang.
[2024-09-15 20:11:03,716] {taskinstance.py:1569} INFO - Exporting the following env vars:
AIRFLOW_CTX_DAG_OWNER=airflow
AIRFLOW_CTX_DAG_ID=BRONZER_GET_STONCKS
AIRFLOW_CTX_TASK_ID=BRONZE_AAPL
AIRFLOW_CTX_EXECUTION_DATE=2024-01-16T00:00:00+00:00
AIRFLOW_CTX_TRY_NUMBER=1
AIRFLOW_CTX_DAG_RUN_ID=scheduled__2024-01-16T00:00:00+00:00
[2024-09-15 20:11:03,717] {taskinstance.py:1889} ERROR - Task failed with exception
Traceback (most recent call last):
  File "/usr/lib/python3.10/pathlib.py", line 1175, in mkdir
    self._accessor.mkdir(self, mode)
FileNotFoundError: [Errno 2] No such file or directory: '/datalake/AAPL'

During handling of the above exception, another exception occurred:

Traceback (most recent call last):
  File "/home/kaiwang/Documents/airflow_celeby/venv/lib/python3.10/site-packages/airflow/decorators/base.py", line 179, in execute
    return_value = super().execute(context)
  File "/home/kaiwang/Documents/airflow_celeby/venv/lib/python3.10/site-packages/airflow/operators/python.py", line 171, in execute
    return_value = self.execute_callable()
  File "/home/kaiwang/Documents/airflow_celeby/venv/lib/python3.10/site-packages/airflow/operators/python.py", line 189, in execute_callable
    return self.python_callable(*self.op_args, **self.op_kwargs)
  File "/home/kaiwang/Documents/airflow_celeby/dags/get_stocks.py", line 21, in get_history
    (Path(file_path).parent).mkdir(parents=True, exist_ok=True)
  File "/usr/lib/python3.10/pathlib.py", line 1179, in mkdir
    self.parent.mkdir(parents=True, exist_ok=True)
  File "/usr/lib/python3.10/pathlib.py", line 1175, in mkdir
    self._accessor.mkdir(self, mode)
PermissionError: [Errno 13] Permission denied: '/datalake'
[2024-09-15 20:11:03,720] {taskinstance.py:1395} INFO - Marking task as FAILED. dag_id=BRONZER_GET_STONCKS, task_id=BRONZE_AAPL, execution_date=20240116T000000, start_date=20240915T231103, end_date=20240915T231103
[2024-09-15 20:11:03,729] {standard_task_runner.py:92} ERROR - Failed to execute job 100 for task BRONZE_AAPL ([Errno 13] Permission denied: '/datalake'; 12813)
[2024-09-15 20:11:03,738] {local_task_job.py:156} INFO - Task exited with return code 1
[2024-09-15 20:11:03,751] {local_task_job.py:273} INFO - 0 downstream tasks scheduled from follow-on schedule check
[2024-09-15 20:13:26,109] {taskinstance.py:1159} INFO - Dependencies all met for <TaskInstance: BRONZER_GET_STONCKS.BRONZE_AAPL scheduled__2024-01-16T00:00:00+00:00 [queued]>
[2024-09-15 20:13:26,113] {taskinstance.py:1159} INFO - Dependencies all met for <TaskInstance: BRONZER_GET_STONCKS.BRONZE_AAPL scheduled__2024-01-16T00:00:00+00:00 [queued]>
[2024-09-15 20:13:26,113] {taskinstance.py:1356} INFO - 
--------------------------------------------------------------------------------
[2024-09-15 20:13:26,113] {taskinstance.py:1357} INFO - Starting attempt 1 of 1
[2024-09-15 20:13:26,113] {taskinstance.py:1358} INFO - 
--------------------------------------------------------------------------------
[2024-09-15 20:13:26,124] {taskinstance.py:1377} INFO - Executing <Task(_PythonDecoratedOperator): BRONZE_AAPL> on 2024-01-16 00:00:00+00:00
[2024-09-15 20:13:26,127] {standard_task_runner.py:52} INFO - Started process 13417 to run task
[2024-09-15 20:13:26,129] {standard_task_runner.py:79} INFO - Running: ['airflow', 'tasks', 'run', 'BRONZER_GET_STONCKS', 'BRONZE_AAPL', 'scheduled__2024-01-16T00:00:00+00:00', '--job-id', '100', '--raw', '--subdir', 'DAGS_FOLDER/get_stocks.py', '--cfg-path', '/tmp/tmpwl8xjr15', '--error-file', '/tmp/tmpfsbtkyv3']
[2024-09-15 20:13:26,129] {standard_task_runner.py:80} INFO - Job 100: Subtask BRONZE_AAPL
[2024-09-15 20:13:26,156] {task_command.py:370} INFO - Running <TaskInstance: BRONZER_GET_STONCKS.BRONZE_AAPL scheduled__2024-01-16T00:00:00+00:00 [running]> on host kaiwang.
[2024-09-15 20:13:26,195] {taskinstance.py:1569} INFO - Exporting the following env vars:
AIRFLOW_CTX_DAG_OWNER=airflow
AIRFLOW_CTX_DAG_ID=BRONZER_GET_STONCKS
AIRFLOW_CTX_TASK_ID=BRONZE_AAPL
AIRFLOW_CTX_EXECUTION_DATE=2024-01-16T00:00:00+00:00
AIRFLOW_CTX_TRY_NUMBER=1
AIRFLOW_CTX_DAG_RUN_ID=scheduled__2024-01-16T00:00:00+00:00
[2024-09-15 20:13:26,196] {taskinstance.py:1889} ERROR - Task failed with exception
Traceback (most recent call last):
  File "/usr/lib/python3.10/pathlib.py", line 1175, in mkdir
    self._accessor.mkdir(self, mode)
FileNotFoundError: [Errno 2] No such file or directory: '/Documents/airflow_celeby/datalake/AAPL'

During handling of the above exception, another exception occurred:

Traceback (most recent call last):
  File "/usr/lib/python3.10/pathlib.py", line 1175, in mkdir
    self._accessor.mkdir(self, mode)
FileNotFoundError: [Errno 2] No such file or directory: '/Documents/airflow_celeby/datalake'

During handling of the above exception, another exception occurred:

Traceback (most recent call last):
  File "/usr/lib/python3.10/pathlib.py", line 1175, in mkdir
    self._accessor.mkdir(self, mode)
FileNotFoundError: [Errno 2] No such file or directory: '/Documents/airflow_celeby'

During handling of the above exception, another exception occurred:

Traceback (most recent call last):
  File "/home/kaiwang/Documents/airflow_celeby/venv/lib/python3.10/site-packages/airflow/decorators/base.py", line 179, in execute
    return_value = super().execute(context)
  File "/home/kaiwang/Documents/airflow_celeby/venv/lib/python3.10/site-packages/airflow/operators/python.py", line 171, in execute
    return_value = self.execute_callable()
  File "/home/kaiwang/Documents/airflow_celeby/venv/lib/python3.10/site-packages/airflow/operators/python.py", line 189, in execute_callable
    return self.python_callable(*self.op_args, **self.op_kwargs)
  File "/home/kaiwang/Documents/airflow_celeby/dags/get_stocks.py", line 21, in get_history
    (Path(file_path).parent).mkdir(parents=True, exist_ok=True)
  File "/usr/lib/python3.10/pathlib.py", line 1179, in mkdir
    self.parent.mkdir(parents=True, exist_ok=True)
  File "/usr/lib/python3.10/pathlib.py", line 1179, in mkdir
    self.parent.mkdir(parents=True, exist_ok=True)
  File "/usr/lib/python3.10/pathlib.py", line 1179, in mkdir
    self.parent.mkdir(parents=True, exist_ok=True)
  File "/usr/lib/python3.10/pathlib.py", line 1175, in mkdir
    self._accessor.mkdir(self, mode)
PermissionError: [Errno 13] Permission denied: '/Documents'
[2024-09-15 20:13:26,198] {taskinstance.py:1395} INFO - Marking task as FAILED. dag_id=BRONZER_GET_STONCKS, task_id=BRONZE_AAPL, execution_date=20240116T000000, start_date=20240915T231326, end_date=20240915T231326
[2024-09-15 20:13:26,207] {standard_task_runner.py:92} ERROR - Failed to execute job 100 for task BRONZE_AAPL ([Errno 13] Permission denied: '/Documents'; 13417)
[2024-09-15 20:13:26,222] {local_task_job.py:156} INFO - Task exited with return code 1
[2024-09-15 20:13:26,231] {local_task_job.py:273} INFO - 0 downstream tasks scheduled from follow-on schedule check
[2024-09-15 20:17:56,976] {taskinstance.py:1159} INFO - Dependencies all met for <TaskInstance: BRONZER_GET_STONCKS.BRONZE_AAPL scheduled__2024-01-16T00:00:00+00:00 [queued]>
[2024-09-15 20:17:56,980] {taskinstance.py:1159} INFO - Dependencies all met for <TaskInstance: BRONZER_GET_STONCKS.BRONZE_AAPL scheduled__2024-01-16T00:00:00+00:00 [queued]>
[2024-09-15 20:17:56,980] {taskinstance.py:1356} INFO - 
--------------------------------------------------------------------------------
[2024-09-15 20:17:56,980] {taskinstance.py:1357} INFO - Starting attempt 1 of 1
[2024-09-15 20:17:56,980] {taskinstance.py:1358} INFO - 
--------------------------------------------------------------------------------
[2024-09-15 20:17:56,994] {taskinstance.py:1377} INFO - Executing <Task(_PythonDecoratedOperator): BRONZE_AAPL> on 2024-01-16 00:00:00+00:00
[2024-09-15 20:17:56,996] {standard_task_runner.py:52} INFO - Started process 14079 to run task
[2024-09-15 20:17:56,998] {standard_task_runner.py:79} INFO - Running: ['airflow', 'tasks', 'run', 'BRONZER_GET_STONCKS', 'BRONZE_AAPL', 'scheduled__2024-01-16T00:00:00+00:00', '--job-id', '100', '--raw', '--subdir', 'DAGS_FOLDER/get_stocks.py', '--cfg-path', '/tmp/tmp3c2mvc8b', '--error-file', '/tmp/tmprem2kqjy']
[2024-09-15 20:17:56,999] {standard_task_runner.py:80} INFO - Job 100: Subtask BRONZE_AAPL
[2024-09-15 20:17:57,025] {task_command.py:370} INFO - Running <TaskInstance: BRONZER_GET_STONCKS.BRONZE_AAPL scheduled__2024-01-16T00:00:00+00:00 [running]> on host kaiwang.
[2024-09-15 20:17:57,065] {taskinstance.py:1569} INFO - Exporting the following env vars:
AIRFLOW_CTX_DAG_OWNER=airflow
AIRFLOW_CTX_DAG_ID=BRONZER_GET_STONCKS
AIRFLOW_CTX_TASK_ID=BRONZE_AAPL
AIRFLOW_CTX_EXECUTION_DATE=2024-01-16T00:00:00+00:00
AIRFLOW_CTX_TRY_NUMBER=1
AIRFLOW_CTX_DAG_RUN_ID=scheduled__2024-01-16T00:00:00+00:00
[2024-09-15 20:18:00,647] {history.py:244} ERROR - $AAPL: possibly delisted; no price data found  (1h 2024-01-13 -> 2024-01-03) (Yahoo error = "Invalid input - start date cannot be after end date. startDate = 1705122000, endDate = 1704258000")
[2024-09-15 20:18:00,656] {python.py:173} INFO - Done. Returned value was: None
[2024-09-15 20:18:00,667] {taskinstance.py:1395} INFO - Marking task as SUCCESS. dag_id=BRONZER_GET_STONCKS, task_id=BRONZE_AAPL, execution_date=20240116T000000, start_date=20240915T231756, end_date=20240915T231800
[2024-09-15 20:18:00,719] {local_task_job.py:156} INFO - Task exited with return code 0
[2024-09-15 20:18:00,733] {local_task_job.py:273} INFO - 0 downstream tasks scheduled from follow-on schedule check
