[2024-09-15 20:03:59,135] {taskinstance.py:1159} INFO - Dependencies all met for <TaskInstance: BRONZER_GET_STONCKS.BRONZE_AAPL scheduled__2024-01-13T00:00:00+00:00 [queued]>
[2024-09-15 20:03:59,139] {taskinstance.py:1159} INFO - Dependencies all met for <TaskInstance: BRONZER_GET_STONCKS.BRONZE_AAPL scheduled__2024-01-13T00:00:00+00:00 [queued]>
[2024-09-15 20:03:59,139] {taskinstance.py:1356} INFO - 
--------------------------------------------------------------------------------
[2024-09-15 20:03:59,139] {taskinstance.py:1357} INFO - Starting attempt 1 of 1
[2024-09-15 20:03:59,139] {taskinstance.py:1358} INFO - 
--------------------------------------------------------------------------------
[2024-09-15 20:03:59,149] {taskinstance.py:1377} INFO - Executing <Task(_PythonDecoratedOperator): BRONZE_AAPL> on 2024-01-13 00:00:00+00:00
[2024-09-15 20:03:59,151] {standard_task_runner.py:52} INFO - Started process 11450 to run task
[2024-09-15 20:03:59,153] {standard_task_runner.py:79} INFO - Running: ['airflow', 'tasks', 'run', 'BRONZER_GET_STONCKS', 'BRONZE_AAPL', 'scheduled__2024-01-13T00:00:00+00:00', '--job-id', '45', '--raw', '--subdir', 'DAGS_FOLDER/get_stocks.py', '--cfg-path', '/tmp/tmpt20q5gbv', '--error-file', '/tmp/tmpneuj5yc9']
[2024-09-15 20:03:59,154] {standard_task_runner.py:80} INFO - Job 45: Subtask BRONZE_AAPL
[2024-09-15 20:03:59,181] {task_command.py:370} INFO - Running <TaskInstance: BRONZER_GET_STONCKS.BRONZE_AAPL scheduled__2024-01-13T00:00:00+00:00 [running]> on host kaiwang.
[2024-09-15 20:03:59,220] {taskinstance.py:1569} INFO - Exporting the following env vars:
AIRFLOW_CTX_DAG_OWNER=airflow
AIRFLOW_CTX_DAG_ID=BRONZER_GET_STONCKS
AIRFLOW_CTX_TASK_ID=BRONZE_AAPL
AIRFLOW_CTX_EXECUTION_DATE=2024-01-13T00:00:00+00:00
AIRFLOW_CTX_TRY_NUMBER=1
AIRFLOW_CTX_DAG_RUN_ID=scheduled__2024-01-13T00:00:00+00:00
[2024-09-15 20:03:59,221] {taskinstance.py:1889} ERROR - Task failed with exception
Traceback (most recent call last):
  File "/usr/lib/python3.10/pathlib.py", line 1175, in mkdir
    self._accessor.mkdir(self, mode)
FileNotFoundError: [Errno 2] No such file or directory: '/datalake/AAPL'

During handling of the above exception, another exception occurred:

Traceback (most recent call last):
  File "/home/kaiwang/Documents/airflow_celeby/venv/lib/python3.10/site-packages/airflow/decorators/base.py", line 179, in execute
    return_value = super().execute(context)
  File "/home/kaiwang/Documents/airflow_celeby/venv/lib/python3.10/site-packages/airflow/operators/python.py", line 171, in execute
    return_value = self.execute_callable()
  File "/home/kaiwang/Documents/airflow_celeby/venv/lib/python3.10/site-packages/airflow/operators/python.py", line 189, in execute_callable
    return self.python_callable(*self.op_args, **self.op_kwargs)
  File "/home/kaiwang/Documents/airflow_celeby/dags/get_stocks.py", line 21, in get_history
    (Path(file_path).parent).mkdir(parents=True, exist_ok=True)
  File "/usr/lib/python3.10/pathlib.py", line 1179, in mkdir
    self.parent.mkdir(parents=True, exist_ok=True)
  File "/usr/lib/python3.10/pathlib.py", line 1175, in mkdir
    self._accessor.mkdir(self, mode)
PermissionError: [Errno 13] Permission denied: '/datalake'
[2024-09-15 20:03:59,223] {taskinstance.py:1395} INFO - Marking task as FAILED. dag_id=BRONZER_GET_STONCKS, task_id=BRONZE_AAPL, execution_date=20240113T000000, start_date=20240915T230359, end_date=20240915T230359
[2024-09-15 20:03:59,232] {standard_task_runner.py:92} ERROR - Failed to execute job 45 for task BRONZE_AAPL ([Errno 13] Permission denied: '/datalake'; 11450)
[2024-09-15 20:03:59,246] {local_task_job.py:156} INFO - Task exited with return code 1
[2024-09-15 20:03:59,256] {local_task_job.py:273} INFO - 0 downstream tasks scheduled from follow-on schedule check
[2024-09-15 20:06:44,327] {taskinstance.py:1159} INFO - Dependencies all met for <TaskInstance: BRONZER_GET_STONCKS.BRONZE_AAPL scheduled__2024-01-13T00:00:00+00:00 [queued]>
[2024-09-15 20:06:44,331] {taskinstance.py:1159} INFO - Dependencies all met for <TaskInstance: BRONZER_GET_STONCKS.BRONZE_AAPL scheduled__2024-01-13T00:00:00+00:00 [queued]>
[2024-09-15 20:06:44,331] {taskinstance.py:1356} INFO - 
--------------------------------------------------------------------------------
[2024-09-15 20:06:44,331] {taskinstance.py:1357} INFO - Starting attempt 1 of 1
[2024-09-15 20:06:44,331] {taskinstance.py:1358} INFO - 
--------------------------------------------------------------------------------
[2024-09-15 20:06:44,342] {taskinstance.py:1377} INFO - Executing <Task(_PythonDecoratedOperator): BRONZE_AAPL> on 2024-01-13 00:00:00+00:00
[2024-09-15 20:06:44,344] {standard_task_runner.py:52} INFO - Started process 12162 to run task
[2024-09-15 20:06:44,346] {standard_task_runner.py:79} INFO - Running: ['airflow', 'tasks', 'run', 'BRONZER_GET_STONCKS', 'BRONZE_AAPL', 'scheduled__2024-01-13T00:00:00+00:00', '--job-id', '47', '--raw', '--subdir', 'DAGS_FOLDER/get_stocks.py', '--cfg-path', '/tmp/tmpeqzwqebd', '--error-file', '/tmp/tmpq11ypnkw']
[2024-09-15 20:06:44,347] {standard_task_runner.py:80} INFO - Job 47: Subtask BRONZE_AAPL
[2024-09-15 20:06:44,373] {task_command.py:370} INFO - Running <TaskInstance: BRONZER_GET_STONCKS.BRONZE_AAPL scheduled__2024-01-13T00:00:00+00:00 [running]> on host kaiwang.
[2024-09-15 20:06:44,411] {taskinstance.py:1569} INFO - Exporting the following env vars:
AIRFLOW_CTX_DAG_OWNER=airflow
AIRFLOW_CTX_DAG_ID=BRONZER_GET_STONCKS
AIRFLOW_CTX_TASK_ID=BRONZE_AAPL
AIRFLOW_CTX_EXECUTION_DATE=2024-01-13T00:00:00+00:00
AIRFLOW_CTX_TRY_NUMBER=1
AIRFLOW_CTX_DAG_RUN_ID=scheduled__2024-01-13T00:00:00+00:00
[2024-09-15 20:06:44,412] {taskinstance.py:1889} ERROR - Task failed with exception
Traceback (most recent call last):
  File "/usr/lib/python3.10/pathlib.py", line 1175, in mkdir
    self._accessor.mkdir(self, mode)
FileNotFoundError: [Errno 2] No such file or directory: '/datalake/AAPL'

During handling of the above exception, another exception occurred:

Traceback (most recent call last):
  File "/home/kaiwang/Documents/airflow_celeby/venv/lib/python3.10/site-packages/airflow/decorators/base.py", line 179, in execute
    return_value = super().execute(context)
  File "/home/kaiwang/Documents/airflow_celeby/venv/lib/python3.10/site-packages/airflow/operators/python.py", line 171, in execute
    return_value = self.execute_callable()
  File "/home/kaiwang/Documents/airflow_celeby/venv/lib/python3.10/site-packages/airflow/operators/python.py", line 189, in execute_callable
    return self.python_callable(*self.op_args, **self.op_kwargs)
  File "/home/kaiwang/Documents/airflow_celeby/dags/get_stocks.py", line 21, in get_history
    (Path(file_path).parent).mkdir(parents=True, exist_ok=True)
  File "/usr/lib/python3.10/pathlib.py", line 1179, in mkdir
    self.parent.mkdir(parents=True, exist_ok=True)
  File "/usr/lib/python3.10/pathlib.py", line 1175, in mkdir
    self._accessor.mkdir(self, mode)
PermissionError: [Errno 13] Permission denied: '/datalake'
[2024-09-15 20:06:44,414] {taskinstance.py:1395} INFO - Marking task as FAILED. dag_id=BRONZER_GET_STONCKS, task_id=BRONZE_AAPL, execution_date=20240113T000000, start_date=20240915T230644, end_date=20240915T230644
[2024-09-15 20:06:44,422] {standard_task_runner.py:92} ERROR - Failed to execute job 47 for task BRONZE_AAPL ([Errno 13] Permission denied: '/datalake'; 12162)
[2024-09-15 20:06:44,439] {local_task_job.py:156} INFO - Task exited with return code 1
[2024-09-15 20:06:44,448] {local_task_job.py:273} INFO - 0 downstream tasks scheduled from follow-on schedule check
[2024-09-15 20:10:40,166] {taskinstance.py:1159} INFO - Dependencies all met for <TaskInstance: BRONZER_GET_STONCKS.BRONZE_AAPL scheduled__2024-01-13T00:00:00+00:00 [queued]>
[2024-09-15 20:10:40,170] {taskinstance.py:1159} INFO - Dependencies all met for <TaskInstance: BRONZER_GET_STONCKS.BRONZE_AAPL scheduled__2024-01-13T00:00:00+00:00 [queued]>
[2024-09-15 20:10:40,171] {taskinstance.py:1356} INFO - 
--------------------------------------------------------------------------------
[2024-09-15 20:10:40,171] {taskinstance.py:1357} INFO - Starting attempt 1 of 1
[2024-09-15 20:10:40,171] {taskinstance.py:1358} INFO - 
--------------------------------------------------------------------------------
[2024-09-15 20:10:40,181] {taskinstance.py:1377} INFO - Executing <Task(_PythonDecoratedOperator): BRONZE_AAPL> on 2024-01-13 00:00:00+00:00
[2024-09-15 20:10:40,184] {standard_task_runner.py:52} INFO - Started process 12770 to run task
[2024-09-15 20:10:40,186] {standard_task_runner.py:79} INFO - Running: ['airflow', 'tasks', 'run', 'BRONZER_GET_STONCKS', 'BRONZE_AAPL', 'scheduled__2024-01-13T00:00:00+00:00', '--job-id', '96', '--raw', '--subdir', 'DAGS_FOLDER/get_stocks.py', '--cfg-path', '/tmp/tmpwyj17kft', '--error-file', '/tmp/tmpi5d89hlc']
[2024-09-15 20:10:40,186] {standard_task_runner.py:80} INFO - Job 96: Subtask BRONZE_AAPL
[2024-09-15 20:10:40,214] {task_command.py:370} INFO - Running <TaskInstance: BRONZER_GET_STONCKS.BRONZE_AAPL scheduled__2024-01-13T00:00:00+00:00 [running]> on host kaiwang.
[2024-09-15 20:10:40,255] {taskinstance.py:1569} INFO - Exporting the following env vars:
AIRFLOW_CTX_DAG_OWNER=airflow
AIRFLOW_CTX_DAG_ID=BRONZER_GET_STONCKS
AIRFLOW_CTX_TASK_ID=BRONZE_AAPL
AIRFLOW_CTX_EXECUTION_DATE=2024-01-13T00:00:00+00:00
AIRFLOW_CTX_TRY_NUMBER=1
AIRFLOW_CTX_DAG_RUN_ID=scheduled__2024-01-13T00:00:00+00:00
[2024-09-15 20:10:44,540] {history.py:244} ERROR - $AAPL: possibly delisted; no price data found  (1h 2024-01-10 -> 2024-01-03) (Yahoo error = "Invalid input - start date cannot be after end date. startDate = 1704862800, endDate = 1704258000")
[2024-09-15 20:10:44,542] {python.py:173} INFO - Done. Returned value was: None
[2024-09-15 20:10:44,548] {taskinstance.py:1395} INFO - Marking task as SUCCESS. dag_id=BRONZER_GET_STONCKS, task_id=BRONZE_AAPL, execution_date=20240113T000000, start_date=20240915T231040, end_date=20240915T231044
[2024-09-15 20:10:44,591] {local_task_job.py:156} INFO - Task exited with return code 0
[2024-09-15 20:10:44,602] {local_task_job.py:273} INFO - 0 downstream tasks scheduled from follow-on schedule check
[2024-09-15 20:13:20,953] {taskinstance.py:1159} INFO - Dependencies all met for <TaskInstance: BRONZER_GET_STONCKS.BRONZE_AAPL scheduled__2024-01-13T00:00:00+00:00 [queued]>
[2024-09-15 20:13:20,958] {taskinstance.py:1159} INFO - Dependencies all met for <TaskInstance: BRONZER_GET_STONCKS.BRONZE_AAPL scheduled__2024-01-13T00:00:00+00:00 [queued]>
[2024-09-15 20:13:20,958] {taskinstance.py:1356} INFO - 
--------------------------------------------------------------------------------
[2024-09-15 20:13:20,958] {taskinstance.py:1357} INFO - Starting attempt 1 of 1
[2024-09-15 20:13:20,958] {taskinstance.py:1358} INFO - 
--------------------------------------------------------------------------------
[2024-09-15 20:13:20,969] {taskinstance.py:1377} INFO - Executing <Task(_PythonDecoratedOperator): BRONZE_AAPL> on 2024-01-13 00:00:00+00:00
[2024-09-15 20:13:20,972] {standard_task_runner.py:52} INFO - Started process 13381 to run task
[2024-09-15 20:13:20,974] {standard_task_runner.py:79} INFO - Running: ['airflow', 'tasks', 'run', 'BRONZER_GET_STONCKS', 'BRONZE_AAPL', 'scheduled__2024-01-13T00:00:00+00:00', '--job-id', '96', '--raw', '--subdir', 'DAGS_FOLDER/get_stocks.py', '--cfg-path', '/tmp/tmpffgvpb85', '--error-file', '/tmp/tmpmwv0vyw1']
[2024-09-15 20:13:20,975] {standard_task_runner.py:80} INFO - Job 96: Subtask BRONZE_AAPL
[2024-09-15 20:13:21,002] {task_command.py:370} INFO - Running <TaskInstance: BRONZER_GET_STONCKS.BRONZE_AAPL scheduled__2024-01-13T00:00:00+00:00 [running]> on host kaiwang.
[2024-09-15 20:13:21,041] {taskinstance.py:1569} INFO - Exporting the following env vars:
AIRFLOW_CTX_DAG_OWNER=airflow
AIRFLOW_CTX_DAG_ID=BRONZER_GET_STONCKS
AIRFLOW_CTX_TASK_ID=BRONZE_AAPL
AIRFLOW_CTX_EXECUTION_DATE=2024-01-13T00:00:00+00:00
AIRFLOW_CTX_TRY_NUMBER=1
AIRFLOW_CTX_DAG_RUN_ID=scheduled__2024-01-13T00:00:00+00:00
[2024-09-15 20:13:21,041] {taskinstance.py:1889} ERROR - Task failed with exception
Traceback (most recent call last):
  File "/usr/lib/python3.10/pathlib.py", line 1175, in mkdir
    self._accessor.mkdir(self, mode)
FileNotFoundError: [Errno 2] No such file or directory: '/Documents/airflow_celeby/datalake/AAPL'

During handling of the above exception, another exception occurred:

Traceback (most recent call last):
  File "/usr/lib/python3.10/pathlib.py", line 1175, in mkdir
    self._accessor.mkdir(self, mode)
FileNotFoundError: [Errno 2] No such file or directory: '/Documents/airflow_celeby/datalake'

During handling of the above exception, another exception occurred:

Traceback (most recent call last):
  File "/usr/lib/python3.10/pathlib.py", line 1175, in mkdir
    self._accessor.mkdir(self, mode)
FileNotFoundError: [Errno 2] No such file or directory: '/Documents/airflow_celeby'

During handling of the above exception, another exception occurred:

Traceback (most recent call last):
  File "/home/kaiwang/Documents/airflow_celeby/venv/lib/python3.10/site-packages/airflow/decorators/base.py", line 179, in execute
    return_value = super().execute(context)
  File "/home/kaiwang/Documents/airflow_celeby/venv/lib/python3.10/site-packages/airflow/operators/python.py", line 171, in execute
    return_value = self.execute_callable()
  File "/home/kaiwang/Documents/airflow_celeby/venv/lib/python3.10/site-packages/airflow/operators/python.py", line 189, in execute_callable
    return self.python_callable(*self.op_args, **self.op_kwargs)
  File "/home/kaiwang/Documents/airflow_celeby/dags/get_stocks.py", line 21, in get_history
    (Path(file_path).parent).mkdir(parents=True, exist_ok=True)
  File "/usr/lib/python3.10/pathlib.py", line 1179, in mkdir
    self.parent.mkdir(parents=True, exist_ok=True)
  File "/usr/lib/python3.10/pathlib.py", line 1179, in mkdir
    self.parent.mkdir(parents=True, exist_ok=True)
  File "/usr/lib/python3.10/pathlib.py", line 1179, in mkdir
    self.parent.mkdir(parents=True, exist_ok=True)
  File "/usr/lib/python3.10/pathlib.py", line 1175, in mkdir
    self._accessor.mkdir(self, mode)
PermissionError: [Errno 13] Permission denied: '/Documents'
[2024-09-15 20:13:21,044] {taskinstance.py:1395} INFO - Marking task as FAILED. dag_id=BRONZER_GET_STONCKS, task_id=BRONZE_AAPL, execution_date=20240113T000000, start_date=20240915T231320, end_date=20240915T231321
[2024-09-15 20:13:21,053] {standard_task_runner.py:92} ERROR - Failed to execute job 96 for task BRONZE_AAPL ([Errno 13] Permission denied: '/Documents'; 13381)
[2024-09-15 20:13:21,067] {local_task_job.py:156} INFO - Task exited with return code 1
[2024-09-15 20:13:21,076] {local_task_job.py:273} INFO - 0 downstream tasks scheduled from follow-on schedule check
[2024-09-15 20:17:37,941] {taskinstance.py:1159} INFO - Dependencies all met for <TaskInstance: BRONZER_GET_STONCKS.BRONZE_AAPL scheduled__2024-01-13T00:00:00+00:00 [queued]>
[2024-09-15 20:17:37,944] {taskinstance.py:1159} INFO - Dependencies all met for <TaskInstance: BRONZER_GET_STONCKS.BRONZE_AAPL scheduled__2024-01-13T00:00:00+00:00 [queued]>
[2024-09-15 20:17:37,945] {taskinstance.py:1356} INFO - 
--------------------------------------------------------------------------------
[2024-09-15 20:17:37,945] {taskinstance.py:1357} INFO - Starting attempt 1 of 1
[2024-09-15 20:17:37,945] {taskinstance.py:1358} INFO - 
--------------------------------------------------------------------------------
[2024-09-15 20:17:37,955] {taskinstance.py:1377} INFO - Executing <Task(_PythonDecoratedOperator): BRONZE_AAPL> on 2024-01-13 00:00:00+00:00
[2024-09-15 20:17:37,957] {standard_task_runner.py:52} INFO - Started process 14042 to run task
[2024-09-15 20:17:37,959] {standard_task_runner.py:79} INFO - Running: ['airflow', 'tasks', 'run', 'BRONZER_GET_STONCKS', 'BRONZE_AAPL', 'scheduled__2024-01-13T00:00:00+00:00', '--job-id', '96', '--raw', '--subdir', 'DAGS_FOLDER/get_stocks.py', '--cfg-path', '/tmp/tmph2ay2lul', '--error-file', '/tmp/tmpen7caeas']
[2024-09-15 20:17:37,960] {standard_task_runner.py:80} INFO - Job 96: Subtask BRONZE_AAPL
[2024-09-15 20:17:37,987] {task_command.py:370} INFO - Running <TaskInstance: BRONZER_GET_STONCKS.BRONZE_AAPL scheduled__2024-01-13T00:00:00+00:00 [running]> on host kaiwang.
[2024-09-15 20:17:38,027] {taskinstance.py:1569} INFO - Exporting the following env vars:
AIRFLOW_CTX_DAG_OWNER=airflow
AIRFLOW_CTX_DAG_ID=BRONZER_GET_STONCKS
AIRFLOW_CTX_TASK_ID=BRONZE_AAPL
AIRFLOW_CTX_EXECUTION_DATE=2024-01-13T00:00:00+00:00
AIRFLOW_CTX_TRY_NUMBER=1
AIRFLOW_CTX_DAG_RUN_ID=scheduled__2024-01-13T00:00:00+00:00
[2024-09-15 20:17:41,820] {history.py:244} ERROR - $AAPL: possibly delisted; no price data found  (1h 2024-01-10 -> 2024-01-03) (Yahoo error = "Invalid input - start date cannot be after end date. startDate = 1704862800, endDate = 1704258000")
[2024-09-15 20:17:41,828] {python.py:173} INFO - Done. Returned value was: None
[2024-09-15 20:17:41,838] {taskinstance.py:1395} INFO - Marking task as SUCCESS. dag_id=BRONZER_GET_STONCKS, task_id=BRONZE_AAPL, execution_date=20240113T000000, start_date=20240915T231737, end_date=20240915T231741
[2024-09-15 20:17:41,884] {local_task_job.py:156} INFO - Task exited with return code 0
[2024-09-15 20:17:41,894] {local_task_job.py:273} INFO - 0 downstream tasks scheduled from follow-on schedule check
