[2024-09-15 20:04:20,518] {taskinstance.py:1159} INFO - Dependencies all met for <TaskInstance: BRONZER_GET_STONCKS.BRONZE_AAPL scheduled__2024-01-19T00:00:00+00:00 [queued]>
[2024-09-15 20:04:20,521] {taskinstance.py:1159} INFO - Dependencies all met for <TaskInstance: BRONZER_GET_STONCKS.BRONZE_AAPL scheduled__2024-01-19T00:00:00+00:00 [queued]>
[2024-09-15 20:04:20,521] {taskinstance.py:1356} INFO - 
--------------------------------------------------------------------------------
[2024-09-15 20:04:20,521] {taskinstance.py:1357} INFO - Starting attempt 1 of 1
[2024-09-15 20:04:20,521] {taskinstance.py:1358} INFO - 
--------------------------------------------------------------------------------
[2024-09-15 20:04:20,532] {taskinstance.py:1377} INFO - Executing <Task(_PythonDecoratedOperator): BRONZE_AAPL> on 2024-01-19 00:00:00+00:00
[2024-09-15 20:04:20,534] {standard_task_runner.py:52} INFO - Started process 11595 to run task
[2024-09-15 20:04:20,536] {standard_task_runner.py:79} INFO - Running: ['airflow', 'tasks', 'run', 'BRONZER_GET_STONCKS', 'BRONZE_AAPL', 'scheduled__2024-01-19T00:00:00+00:00', '--job-id', '61', '--raw', '--subdir', 'DAGS_FOLDER/get_stocks.py', '--cfg-path', '/tmp/tmpzojfp16l', '--error-file', '/tmp/tmp716wy_u7']
[2024-09-15 20:04:20,537] {standard_task_runner.py:80} INFO - Job 61: Subtask BRONZE_AAPL
[2024-09-15 20:04:20,565] {task_command.py:370} INFO - Running <TaskInstance: BRONZER_GET_STONCKS.BRONZE_AAPL scheduled__2024-01-19T00:00:00+00:00 [running]> on host kaiwang.
[2024-09-15 20:04:20,603] {taskinstance.py:1569} INFO - Exporting the following env vars:
AIRFLOW_CTX_DAG_OWNER=airflow
AIRFLOW_CTX_DAG_ID=BRONZER_GET_STONCKS
AIRFLOW_CTX_TASK_ID=BRONZE_AAPL
AIRFLOW_CTX_EXECUTION_DATE=2024-01-19T00:00:00+00:00
AIRFLOW_CTX_TRY_NUMBER=1
AIRFLOW_CTX_DAG_RUN_ID=scheduled__2024-01-19T00:00:00+00:00
[2024-09-15 20:04:20,604] {taskinstance.py:1889} ERROR - Task failed with exception
Traceback (most recent call last):
  File "/usr/lib/python3.10/pathlib.py", line 1175, in mkdir
    self._accessor.mkdir(self, mode)
FileNotFoundError: [Errno 2] No such file or directory: '/datalake/AAPL'

During handling of the above exception, another exception occurred:

Traceback (most recent call last):
  File "/home/kaiwang/Documents/airflow_celeby/venv/lib/python3.10/site-packages/airflow/decorators/base.py", line 179, in execute
    return_value = super().execute(context)
  File "/home/kaiwang/Documents/airflow_celeby/venv/lib/python3.10/site-packages/airflow/operators/python.py", line 171, in execute
    return_value = self.execute_callable()
  File "/home/kaiwang/Documents/airflow_celeby/venv/lib/python3.10/site-packages/airflow/operators/python.py", line 189, in execute_callable
    return self.python_callable(*self.op_args, **self.op_kwargs)
  File "/home/kaiwang/Documents/airflow_celeby/dags/get_stocks.py", line 21, in get_history
    (Path(file_path).parent).mkdir(parents=True, exist_ok=True)
  File "/usr/lib/python3.10/pathlib.py", line 1179, in mkdir
    self.parent.mkdir(parents=True, exist_ok=True)
  File "/usr/lib/python3.10/pathlib.py", line 1175, in mkdir
    self._accessor.mkdir(self, mode)
PermissionError: [Errno 13] Permission denied: '/datalake'
[2024-09-15 20:04:20,606] {taskinstance.py:1395} INFO - Marking task as FAILED. dag_id=BRONZER_GET_STONCKS, task_id=BRONZE_AAPL, execution_date=20240119T000000, start_date=20240915T230420, end_date=20240915T230420
[2024-09-15 20:04:20,615] {standard_task_runner.py:92} ERROR - Failed to execute job 61 for task BRONZE_AAPL ([Errno 13] Permission denied: '/datalake'; 11595)
[2024-09-15 20:04:20,629] {local_task_job.py:156} INFO - Task exited with return code 1
[2024-09-15 20:04:20,638] {local_task_job.py:273} INFO - 0 downstream tasks scheduled from follow-on schedule check
[2024-09-15 20:11:21,029] {taskinstance.py:1159} INFO - Dependencies all met for <TaskInstance: BRONZER_GET_STONCKS.BRONZE_AAPL scheduled__2024-01-19T00:00:00+00:00 [queued]>
[2024-09-15 20:11:21,033] {taskinstance.py:1159} INFO - Dependencies all met for <TaskInstance: BRONZER_GET_STONCKS.BRONZE_AAPL scheduled__2024-01-19T00:00:00+00:00 [queued]>
[2024-09-15 20:11:21,033] {taskinstance.py:1356} INFO - 
--------------------------------------------------------------------------------
[2024-09-15 20:11:21,033] {taskinstance.py:1357} INFO - Starting attempt 1 of 1
[2024-09-15 20:11:21,033] {taskinstance.py:1358} INFO - 
--------------------------------------------------------------------------------
[2024-09-15 20:11:21,044] {taskinstance.py:1377} INFO - Executing <Task(_PythonDecoratedOperator): BRONZE_AAPL> on 2024-01-19 00:00:00+00:00
[2024-09-15 20:11:21,048] {standard_task_runner.py:52} INFO - Started process 12922 to run task
[2024-09-15 20:11:21,051] {standard_task_runner.py:79} INFO - Running: ['airflow', 'tasks', 'run', 'BRONZER_GET_STONCKS', 'BRONZE_AAPL', 'scheduled__2024-01-19T00:00:00+00:00', '--job-id', '112', '--raw', '--subdir', 'DAGS_FOLDER/get_stocks.py', '--cfg-path', '/tmp/tmppebds8ra', '--error-file', '/tmp/tmpeb86t9m2']
[2024-09-15 20:11:21,052] {standard_task_runner.py:80} INFO - Job 112: Subtask BRONZE_AAPL
[2024-09-15 20:11:21,080] {task_command.py:370} INFO - Running <TaskInstance: BRONZER_GET_STONCKS.BRONZE_AAPL scheduled__2024-01-19T00:00:00+00:00 [running]> on host kaiwang.
[2024-09-15 20:11:21,119] {taskinstance.py:1569} INFO - Exporting the following env vars:
AIRFLOW_CTX_DAG_OWNER=airflow
AIRFLOW_CTX_DAG_ID=BRONZER_GET_STONCKS
AIRFLOW_CTX_TASK_ID=BRONZE_AAPL
AIRFLOW_CTX_EXECUTION_DATE=2024-01-19T00:00:00+00:00
AIRFLOW_CTX_TRY_NUMBER=1
AIRFLOW_CTX_DAG_RUN_ID=scheduled__2024-01-19T00:00:00+00:00
[2024-09-15 20:11:21,120] {taskinstance.py:1889} ERROR - Task failed with exception
Traceback (most recent call last):
  File "/usr/lib/python3.10/pathlib.py", line 1175, in mkdir
    self._accessor.mkdir(self, mode)
FileNotFoundError: [Errno 2] No such file or directory: '/datalake/AAPL'

During handling of the above exception, another exception occurred:

Traceback (most recent call last):
  File "/home/kaiwang/Documents/airflow_celeby/venv/lib/python3.10/site-packages/airflow/decorators/base.py", line 179, in execute
    return_value = super().execute(context)
  File "/home/kaiwang/Documents/airflow_celeby/venv/lib/python3.10/site-packages/airflow/operators/python.py", line 171, in execute
    return_value = self.execute_callable()
  File "/home/kaiwang/Documents/airflow_celeby/venv/lib/python3.10/site-packages/airflow/operators/python.py", line 189, in execute_callable
    return self.python_callable(*self.op_args, **self.op_kwargs)
  File "/home/kaiwang/Documents/airflow_celeby/dags/get_stocks.py", line 21, in get_history
    (Path(file_path).parent).mkdir(parents=True, exist_ok=True)
  File "/usr/lib/python3.10/pathlib.py", line 1179, in mkdir
    self.parent.mkdir(parents=True, exist_ok=True)
  File "/usr/lib/python3.10/pathlib.py", line 1175, in mkdir
    self._accessor.mkdir(self, mode)
PermissionError: [Errno 13] Permission denied: '/datalake'
[2024-09-15 20:11:21,122] {taskinstance.py:1395} INFO - Marking task as FAILED. dag_id=BRONZER_GET_STONCKS, task_id=BRONZE_AAPL, execution_date=20240119T000000, start_date=20240915T231121, end_date=20240915T231121
[2024-09-15 20:11:21,131] {standard_task_runner.py:92} ERROR - Failed to execute job 112 for task BRONZE_AAPL ([Errno 13] Permission denied: '/datalake'; 12922)
[2024-09-15 20:11:21,144] {local_task_job.py:156} INFO - Task exited with return code 1
[2024-09-15 20:11:21,153] {local_task_job.py:273} INFO - 0 downstream tasks scheduled from follow-on schedule check
[2024-09-15 20:19:01,004] {taskinstance.py:1159} INFO - Dependencies all met for <TaskInstance: BRONZER_GET_STONCKS.BRONZE_AAPL scheduled__2024-01-19T00:00:00+00:00 [queued]>
[2024-09-15 20:19:01,008] {taskinstance.py:1159} INFO - Dependencies all met for <TaskInstance: BRONZER_GET_STONCKS.BRONZE_AAPL scheduled__2024-01-19T00:00:00+00:00 [queued]>
[2024-09-15 20:19:01,009] {taskinstance.py:1356} INFO - 
--------------------------------------------------------------------------------
[2024-09-15 20:19:01,009] {taskinstance.py:1357} INFO - Starting attempt 1 of 1
[2024-09-15 20:19:01,009] {taskinstance.py:1358} INFO - 
--------------------------------------------------------------------------------
[2024-09-15 20:19:01,021] {taskinstance.py:1377} INFO - Executing <Task(_PythonDecoratedOperator): BRONZE_AAPL> on 2024-01-19 00:00:00+00:00
[2024-09-15 20:19:01,024] {standard_task_runner.py:52} INFO - Started process 14188 to run task
[2024-09-15 20:19:01,026] {standard_task_runner.py:79} INFO - Running: ['airflow', 'tasks', 'run', 'BRONZER_GET_STONCKS', 'BRONZE_AAPL', 'scheduled__2024-01-19T00:00:00+00:00', '--job-id', '112', '--raw', '--subdir', 'DAGS_FOLDER/get_stocks.py', '--cfg-path', '/tmp/tmpm169dz7j', '--error-file', '/tmp/tmpuswqme7v']
[2024-09-15 20:19:01,026] {standard_task_runner.py:80} INFO - Job 112: Subtask BRONZE_AAPL
[2024-09-15 20:19:01,058] {task_command.py:370} INFO - Running <TaskInstance: BRONZER_GET_STONCKS.BRONZE_AAPL scheduled__2024-01-19T00:00:00+00:00 [running]> on host kaiwang.
[2024-09-15 20:19:01,098] {taskinstance.py:1569} INFO - Exporting the following env vars:
AIRFLOW_CTX_DAG_OWNER=airflow
AIRFLOW_CTX_DAG_ID=BRONZER_GET_STONCKS
AIRFLOW_CTX_TASK_ID=BRONZE_AAPL
AIRFLOW_CTX_EXECUTION_DATE=2024-01-19T00:00:00+00:00
AIRFLOW_CTX_TRY_NUMBER=1
AIRFLOW_CTX_DAG_RUN_ID=scheduled__2024-01-19T00:00:00+00:00
[2024-09-15 20:19:04,703] {history.py:244} ERROR - $AAPL: possibly delisted; no price data found  (1h 2024-01-16 -> 2024-01-03) (Yahoo error = "Invalid input - start date cannot be after end date. startDate = 1705381200, endDate = 1704258000")
[2024-09-15 20:19:04,711] {python.py:173} INFO - Done. Returned value was: None
[2024-09-15 20:19:04,721] {taskinstance.py:1395} INFO - Marking task as SUCCESS. dag_id=BRONZER_GET_STONCKS, task_id=BRONZE_AAPL, execution_date=20240119T000000, start_date=20240915T231901, end_date=20240915T231904
[2024-09-15 20:19:04,750] {local_task_job.py:156} INFO - Task exited with return code 0
[2024-09-15 20:19:04,760] {local_task_job.py:273} INFO - 0 downstream tasks scheduled from follow-on schedule check
