[2024-09-15 20:04:34,730] {taskinstance.py:1159} INFO - Dependencies all met for <TaskInstance: BRONZER_GET_STONCKS.BRONZE_GOOG scheduled__2024-01-23T00:00:00+00:00 [queued]>
[2024-09-15 20:04:34,736] {taskinstance.py:1159} INFO - Dependencies all met for <TaskInstance: BRONZER_GET_STONCKS.BRONZE_GOOG scheduled__2024-01-23T00:00:00+00:00 [queued]>
[2024-09-15 20:04:34,736] {taskinstance.py:1356} INFO - 
--------------------------------------------------------------------------------
[2024-09-15 20:04:34,736] {taskinstance.py:1357} INFO - Starting attempt 1 of 1
[2024-09-15 20:04:34,736] {taskinstance.py:1358} INFO - 
--------------------------------------------------------------------------------
[2024-09-15 20:04:34,747] {taskinstance.py:1377} INFO - Executing <Task(_PythonDecoratedOperator): BRONZE_GOOG> on 2024-01-23 00:00:00+00:00
[2024-09-15 20:04:34,749] {standard_task_runner.py:52} INFO - Started process 11687 to run task
[2024-09-15 20:04:34,751] {standard_task_runner.py:79} INFO - Running: ['airflow', 'tasks', 'run', 'BRONZER_GET_STONCKS', 'BRONZE_GOOG', 'scheduled__2024-01-23T00:00:00+00:00', '--job-id', '71', '--raw', '--subdir', 'DAGS_FOLDER/get_stocks.py', '--cfg-path', '/tmp/tmp7_fi6_rc', '--error-file', '/tmp/tmpcvftouwa']
[2024-09-15 20:04:34,752] {standard_task_runner.py:80} INFO - Job 71: Subtask BRONZE_GOOG
[2024-09-15 20:04:34,781] {task_command.py:370} INFO - Running <TaskInstance: BRONZER_GET_STONCKS.BRONZE_GOOG scheduled__2024-01-23T00:00:00+00:00 [running]> on host kaiwang.
[2024-09-15 20:04:34,821] {taskinstance.py:1569} INFO - Exporting the following env vars:
AIRFLOW_CTX_DAG_OWNER=airflow
AIRFLOW_CTX_DAG_ID=BRONZER_GET_STONCKS
AIRFLOW_CTX_TASK_ID=BRONZE_GOOG
AIRFLOW_CTX_EXECUTION_DATE=2024-01-23T00:00:00+00:00
AIRFLOW_CTX_TRY_NUMBER=1
AIRFLOW_CTX_DAG_RUN_ID=scheduled__2024-01-23T00:00:00+00:00
[2024-09-15 20:04:34,822] {taskinstance.py:1889} ERROR - Task failed with exception
Traceback (most recent call last):
  File "/usr/lib/python3.10/pathlib.py", line 1175, in mkdir
    self._accessor.mkdir(self, mode)
FileNotFoundError: [Errno 2] No such file or directory: '/datalake/GOOG'

During handling of the above exception, another exception occurred:

Traceback (most recent call last):
  File "/home/kaiwang/Documents/airflow_celeby/venv/lib/python3.10/site-packages/airflow/decorators/base.py", line 179, in execute
    return_value = super().execute(context)
  File "/home/kaiwang/Documents/airflow_celeby/venv/lib/python3.10/site-packages/airflow/operators/python.py", line 171, in execute
    return_value = self.execute_callable()
  File "/home/kaiwang/Documents/airflow_celeby/venv/lib/python3.10/site-packages/airflow/operators/python.py", line 189, in execute_callable
    return self.python_callable(*self.op_args, **self.op_kwargs)
  File "/home/kaiwang/Documents/airflow_celeby/dags/get_stocks.py", line 21, in get_history
    (Path(file_path).parent).mkdir(parents=True, exist_ok=True)
  File "/usr/lib/python3.10/pathlib.py", line 1179, in mkdir
    self.parent.mkdir(parents=True, exist_ok=True)
  File "/usr/lib/python3.10/pathlib.py", line 1175, in mkdir
    self._accessor.mkdir(self, mode)
PermissionError: [Errno 13] Permission denied: '/datalake'
[2024-09-15 20:04:34,824] {taskinstance.py:1395} INFO - Marking task as FAILED. dag_id=BRONZER_GET_STONCKS, task_id=BRONZE_GOOG, execution_date=20240123T000000, start_date=20240915T230434, end_date=20240915T230434
[2024-09-15 20:04:34,832] {standard_task_runner.py:92} ERROR - Failed to execute job 71 for task BRONZE_GOOG ([Errno 13] Permission denied: '/datalake'; 11687)
[2024-09-15 20:04:34,844] {local_task_job.py:156} INFO - Task exited with return code 1
[2024-09-15 20:04:34,854] {local_task_job.py:273} INFO - 0 downstream tasks scheduled from follow-on schedule check
[2024-09-15 20:11:51,669] {taskinstance.py:1159} INFO - Dependencies all met for <TaskInstance: BRONZER_GET_STONCKS.BRONZE_GOOG scheduled__2024-01-23T00:00:00+00:00 [queued]>
[2024-09-15 20:11:51,674] {taskinstance.py:1159} INFO - Dependencies all met for <TaskInstance: BRONZER_GET_STONCKS.BRONZE_GOOG scheduled__2024-01-23T00:00:00+00:00 [queued]>
[2024-09-15 20:11:51,674] {taskinstance.py:1356} INFO - 
--------------------------------------------------------------------------------
[2024-09-15 20:11:51,674] {taskinstance.py:1357} INFO - Starting attempt 1 of 1
[2024-09-15 20:11:51,674] {taskinstance.py:1358} INFO - 
--------------------------------------------------------------------------------
[2024-09-15 20:11:51,684] {taskinstance.py:1377} INFO - Executing <Task(_PythonDecoratedOperator): BRONZE_GOOG> on 2024-01-23 00:00:00+00:00
[2024-09-15 20:11:51,687] {standard_task_runner.py:52} INFO - Started process 13023 to run task
[2024-09-15 20:11:51,689] {standard_task_runner.py:79} INFO - Running: ['airflow', 'tasks', 'run', 'BRONZER_GET_STONCKS', 'BRONZE_GOOG', 'scheduled__2024-01-23T00:00:00+00:00', '--job-id', '122', '--raw', '--subdir', 'DAGS_FOLDER/get_stocks.py', '--cfg-path', '/tmp/tmps6pdjrig', '--error-file', '/tmp/tmp3nw10nmg']
[2024-09-15 20:11:51,690] {standard_task_runner.py:80} INFO - Job 122: Subtask BRONZE_GOOG
[2024-09-15 20:11:51,718] {task_command.py:370} INFO - Running <TaskInstance: BRONZER_GET_STONCKS.BRONZE_GOOG scheduled__2024-01-23T00:00:00+00:00 [running]> on host kaiwang.
[2024-09-15 20:11:51,758] {taskinstance.py:1569} INFO - Exporting the following env vars:
AIRFLOW_CTX_DAG_OWNER=airflow
AIRFLOW_CTX_DAG_ID=BRONZER_GET_STONCKS
AIRFLOW_CTX_TASK_ID=BRONZE_GOOG
AIRFLOW_CTX_EXECUTION_DATE=2024-01-23T00:00:00+00:00
AIRFLOW_CTX_TRY_NUMBER=1
AIRFLOW_CTX_DAG_RUN_ID=scheduled__2024-01-23T00:00:00+00:00
[2024-09-15 20:11:51,759] {taskinstance.py:1889} ERROR - Task failed with exception
Traceback (most recent call last):
  File "/usr/lib/python3.10/pathlib.py", line 1175, in mkdir
    self._accessor.mkdir(self, mode)
FileNotFoundError: [Errno 2] No such file or directory: '/Documents/airflow_celeby/datalake/GOOG'

During handling of the above exception, another exception occurred:

Traceback (most recent call last):
  File "/usr/lib/python3.10/pathlib.py", line 1175, in mkdir
    self._accessor.mkdir(self, mode)
FileNotFoundError: [Errno 2] No such file or directory: '/Documents/airflow_celeby/datalake'

During handling of the above exception, another exception occurred:

Traceback (most recent call last):
  File "/usr/lib/python3.10/pathlib.py", line 1175, in mkdir
    self._accessor.mkdir(self, mode)
FileNotFoundError: [Errno 2] No such file or directory: '/Documents/airflow_celeby'

During handling of the above exception, another exception occurred:

Traceback (most recent call last):
  File "/home/kaiwang/Documents/airflow_celeby/venv/lib/python3.10/site-packages/airflow/decorators/base.py", line 179, in execute
    return_value = super().execute(context)
  File "/home/kaiwang/Documents/airflow_celeby/venv/lib/python3.10/site-packages/airflow/operators/python.py", line 171, in execute
    return_value = self.execute_callable()
  File "/home/kaiwang/Documents/airflow_celeby/venv/lib/python3.10/site-packages/airflow/operators/python.py", line 189, in execute_callable
    return self.python_callable(*self.op_args, **self.op_kwargs)
  File "/home/kaiwang/Documents/airflow_celeby/dags/get_stocks.py", line 21, in get_history
    (Path(file_path).parent).mkdir(parents=True, exist_ok=True)
  File "/usr/lib/python3.10/pathlib.py", line 1179, in mkdir
    self.parent.mkdir(parents=True, exist_ok=True)
  File "/usr/lib/python3.10/pathlib.py", line 1179, in mkdir
    self.parent.mkdir(parents=True, exist_ok=True)
  File "/usr/lib/python3.10/pathlib.py", line 1179, in mkdir
    self.parent.mkdir(parents=True, exist_ok=True)
  File "/usr/lib/python3.10/pathlib.py", line 1175, in mkdir
    self._accessor.mkdir(self, mode)
PermissionError: [Errno 13] Permission denied: '/Documents'
[2024-09-15 20:11:51,761] {taskinstance.py:1395} INFO - Marking task as FAILED. dag_id=BRONZER_GET_STONCKS, task_id=BRONZE_GOOG, execution_date=20240123T000000, start_date=20240915T231151, end_date=20240915T231151
[2024-09-15 20:11:51,771] {standard_task_runner.py:92} ERROR - Failed to execute job 122 for task BRONZE_GOOG ([Errno 13] Permission denied: '/Documents'; 13023)
[2024-09-15 20:11:51,782] {local_task_job.py:156} INFO - Task exited with return code 1
[2024-09-15 20:11:51,793] {local_task_job.py:273} INFO - 0 downstream tasks scheduled from follow-on schedule check
[2024-09-15 23:28:12,083] {taskinstance.py:1159} INFO - Dependencies all met for <TaskInstance: BRONZER_GET_STONCKS.BRONZE_GOOG scheduled__2024-01-23T00:00:00+00:00 [queued]>
[2024-09-15 23:28:12,088] {taskinstance.py:1159} INFO - Dependencies all met for <TaskInstance: BRONZER_GET_STONCKS.BRONZE_GOOG scheduled__2024-01-23T00:00:00+00:00 [queued]>
[2024-09-15 23:28:12,088] {taskinstance.py:1356} INFO - 
--------------------------------------------------------------------------------
[2024-09-15 23:28:12,088] {taskinstance.py:1357} INFO - Starting attempt 1 of 1
[2024-09-15 23:28:12,088] {taskinstance.py:1358} INFO - 
--------------------------------------------------------------------------------
[2024-09-15 23:28:12,101] {taskinstance.py:1377} INFO - Executing <Task(_PythonDecoratedOperator): BRONZE_GOOG> on 2024-01-23 00:00:00+00:00
[2024-09-15 23:28:12,104] {standard_task_runner.py:52} INFO - Started process 14362 to run task
[2024-09-15 23:28:12,106] {standard_task_runner.py:79} INFO - Running: ['airflow', 'tasks', 'run', 'BRONZER_GET_STONCKS', 'BRONZE_GOOG', 'scheduled__2024-01-23T00:00:00+00:00', '--job-id', '122', '--raw', '--subdir', 'DAGS_FOLDER/get_stocks.py', '--cfg-path', '/tmp/tmpn83_aqrc', '--error-file', '/tmp/tmp0higeq3s']
[2024-09-15 23:28:12,106] {standard_task_runner.py:80} INFO - Job 122: Subtask BRONZE_GOOG
[2024-09-15 23:28:12,134] {task_command.py:370} INFO - Running <TaskInstance: BRONZER_GET_STONCKS.BRONZE_GOOG scheduled__2024-01-23T00:00:00+00:00 [running]> on host kaiwang.
[2024-09-15 23:28:12,175] {taskinstance.py:1569} INFO - Exporting the following env vars:
AIRFLOW_CTX_DAG_OWNER=airflow
AIRFLOW_CTX_DAG_ID=BRONZER_GET_STONCKS
AIRFLOW_CTX_TASK_ID=BRONZE_GOOG
AIRFLOW_CTX_EXECUTION_DATE=2024-01-23T00:00:00+00:00
AIRFLOW_CTX_TRY_NUMBER=1
AIRFLOW_CTX_DAG_RUN_ID=scheduled__2024-01-23T00:00:00+00:00
[2024-09-15 23:28:14,464] {history.py:244} ERROR - $GOOG: possibly delisted; no price data found  (1h 2024-01-20 -> 2024-01-03) (Yahoo error = "Invalid input - start date cannot be after end date. startDate = 1705726800, endDate = 1704258000")
[2024-09-15 23:28:14,466] {python.py:173} INFO - Done. Returned value was: None
[2024-09-15 23:28:14,471] {taskinstance.py:1395} INFO - Marking task as SUCCESS. dag_id=BRONZER_GET_STONCKS, task_id=BRONZE_GOOG, execution_date=20240123T000000, start_date=20240916T022812, end_date=20240916T022814
[2024-09-15 23:28:14,530] {local_task_job.py:156} INFO - Task exited with return code 0
[2024-09-15 23:28:14,539] {local_task_job.py:273} INFO - 0 downstream tasks scheduled from follow-on schedule check
