[2024-09-15 20:03:51,616] {taskinstance.py:1159} INFO - Dependencies all met for <TaskInstance: BRONZER_GET_STONCKS.BRONZE_TSLA scheduled__2024-01-11T00:00:00+00:00 [queued]>
[2024-09-15 20:03:51,620] {taskinstance.py:1159} INFO - Dependencies all met for <TaskInstance: BRONZER_GET_STONCKS.BRONZE_TSLA scheduled__2024-01-11T00:00:00+00:00 [queued]>
[2024-09-15 20:03:51,620] {taskinstance.py:1356} INFO - 
--------------------------------------------------------------------------------
[2024-09-15 20:03:51,620] {taskinstance.py:1357} INFO - Starting attempt 1 of 1
[2024-09-15 20:03:51,620] {taskinstance.py:1358} INFO - 
--------------------------------------------------------------------------------
[2024-09-15 20:03:51,630] {taskinstance.py:1377} INFO - Executing <Task(_PythonDecoratedOperator): BRONZE_TSLA> on 2024-01-11 00:00:00+00:00
[2024-09-15 20:03:51,633] {standard_task_runner.py:52} INFO - Started process 11404 to run task
[2024-09-15 20:03:51,635] {standard_task_runner.py:79} INFO - Running: ['airflow', 'tasks', 'run', 'BRONZER_GET_STONCKS', 'BRONZE_TSLA', 'scheduled__2024-01-11T00:00:00+00:00', '--job-id', '40', '--raw', '--subdir', 'DAGS_FOLDER/get_stocks.py', '--cfg-path', '/tmp/tmppxo0zotq', '--error-file', '/tmp/tmpk5koudvx']
[2024-09-15 20:03:51,635] {standard_task_runner.py:80} INFO - Job 40: Subtask BRONZE_TSLA
[2024-09-15 20:03:51,663] {task_command.py:370} INFO - Running <TaskInstance: BRONZER_GET_STONCKS.BRONZE_TSLA scheduled__2024-01-11T00:00:00+00:00 [running]> on host kaiwang.
[2024-09-15 20:03:51,702] {taskinstance.py:1569} INFO - Exporting the following env vars:
AIRFLOW_CTX_DAG_OWNER=airflow
AIRFLOW_CTX_DAG_ID=BRONZER_GET_STONCKS
AIRFLOW_CTX_TASK_ID=BRONZE_TSLA
AIRFLOW_CTX_EXECUTION_DATE=2024-01-11T00:00:00+00:00
AIRFLOW_CTX_TRY_NUMBER=1
AIRFLOW_CTX_DAG_RUN_ID=scheduled__2024-01-11T00:00:00+00:00
[2024-09-15 20:03:51,702] {taskinstance.py:1889} ERROR - Task failed with exception
Traceback (most recent call last):
  File "/usr/lib/python3.10/pathlib.py", line 1175, in mkdir
    self._accessor.mkdir(self, mode)
FileNotFoundError: [Errno 2] No such file or directory: '/datalake/TSLA'

During handling of the above exception, another exception occurred:

Traceback (most recent call last):
  File "/home/kaiwang/Documents/airflow_celeby/venv/lib/python3.10/site-packages/airflow/decorators/base.py", line 179, in execute
    return_value = super().execute(context)
  File "/home/kaiwang/Documents/airflow_celeby/venv/lib/python3.10/site-packages/airflow/operators/python.py", line 171, in execute
    return_value = self.execute_callable()
  File "/home/kaiwang/Documents/airflow_celeby/venv/lib/python3.10/site-packages/airflow/operators/python.py", line 189, in execute_callable
    return self.python_callable(*self.op_args, **self.op_kwargs)
  File "/home/kaiwang/Documents/airflow_celeby/dags/get_stocks.py", line 21, in get_history
    (Path(file_path).parent).mkdir(parents=True, exist_ok=True)
  File "/usr/lib/python3.10/pathlib.py", line 1179, in mkdir
    self.parent.mkdir(parents=True, exist_ok=True)
  File "/usr/lib/python3.10/pathlib.py", line 1175, in mkdir
    self._accessor.mkdir(self, mode)
PermissionError: [Errno 13] Permission denied: '/datalake'
[2024-09-15 20:03:51,705] {taskinstance.py:1395} INFO - Marking task as FAILED. dag_id=BRONZER_GET_STONCKS, task_id=BRONZE_TSLA, execution_date=20240111T000000, start_date=20240915T230351, end_date=20240915T230351
[2024-09-15 20:03:51,714] {standard_task_runner.py:92} ERROR - Failed to execute job 40 for task BRONZE_TSLA ([Errno 13] Permission denied: '/datalake'; 11404)
[2024-09-15 20:03:51,727] {local_task_job.py:156} INFO - Task exited with return code 1
[2024-09-15 20:03:51,738] {local_task_job.py:273} INFO - 0 downstream tasks scheduled from follow-on schedule check
[2024-09-15 20:06:36,355] {taskinstance.py:1159} INFO - Dependencies all met for <TaskInstance: BRONZER_GET_STONCKS.BRONZE_TSLA scheduled__2024-01-11T00:00:00+00:00 [queued]>
[2024-09-15 20:06:36,360] {taskinstance.py:1159} INFO - Dependencies all met for <TaskInstance: BRONZER_GET_STONCKS.BRONZE_TSLA scheduled__2024-01-11T00:00:00+00:00 [queued]>
[2024-09-15 20:06:36,360] {taskinstance.py:1356} INFO - 
--------------------------------------------------------------------------------
[2024-09-15 20:06:36,360] {taskinstance.py:1357} INFO - Starting attempt 1 of 1
[2024-09-15 20:06:36,360] {taskinstance.py:1358} INFO - 
--------------------------------------------------------------------------------
[2024-09-15 20:06:36,370] {taskinstance.py:1377} INFO - Executing <Task(_PythonDecoratedOperator): BRONZE_TSLA> on 2024-01-11 00:00:00+00:00
[2024-09-15 20:06:36,372] {standard_task_runner.py:52} INFO - Started process 12114 to run task
[2024-09-15 20:06:36,375] {standard_task_runner.py:79} INFO - Running: ['airflow', 'tasks', 'run', 'BRONZER_GET_STONCKS', 'BRONZE_TSLA', 'scheduled__2024-01-11T00:00:00+00:00', '--job-id', '42', '--raw', '--subdir', 'DAGS_FOLDER/get_stocks.py', '--cfg-path', '/tmp/tmpja4hx28f', '--error-file', '/tmp/tmpo57q2omw']
[2024-09-15 20:06:36,375] {standard_task_runner.py:80} INFO - Job 42: Subtask BRONZE_TSLA
[2024-09-15 20:06:36,402] {task_command.py:370} INFO - Running <TaskInstance: BRONZER_GET_STONCKS.BRONZE_TSLA scheduled__2024-01-11T00:00:00+00:00 [running]> on host kaiwang.
[2024-09-15 20:06:36,438] {taskinstance.py:1569} INFO - Exporting the following env vars:
AIRFLOW_CTX_DAG_OWNER=airflow
AIRFLOW_CTX_DAG_ID=BRONZER_GET_STONCKS
AIRFLOW_CTX_TASK_ID=BRONZE_TSLA
AIRFLOW_CTX_EXECUTION_DATE=2024-01-11T00:00:00+00:00
AIRFLOW_CTX_TRY_NUMBER=1
AIRFLOW_CTX_DAG_RUN_ID=scheduled__2024-01-11T00:00:00+00:00
[2024-09-15 20:06:36,439] {taskinstance.py:1889} ERROR - Task failed with exception
Traceback (most recent call last):
  File "/usr/lib/python3.10/pathlib.py", line 1175, in mkdir
    self._accessor.mkdir(self, mode)
FileNotFoundError: [Errno 2] No such file or directory: '/datalake/TSLA'

During handling of the above exception, another exception occurred:

Traceback (most recent call last):
  File "/home/kaiwang/Documents/airflow_celeby/venv/lib/python3.10/site-packages/airflow/decorators/base.py", line 179, in execute
    return_value = super().execute(context)
  File "/home/kaiwang/Documents/airflow_celeby/venv/lib/python3.10/site-packages/airflow/operators/python.py", line 171, in execute
    return_value = self.execute_callable()
  File "/home/kaiwang/Documents/airflow_celeby/venv/lib/python3.10/site-packages/airflow/operators/python.py", line 189, in execute_callable
    return self.python_callable(*self.op_args, **self.op_kwargs)
  File "/home/kaiwang/Documents/airflow_celeby/dags/get_stocks.py", line 21, in get_history
    (Path(file_path).parent).mkdir(parents=True, exist_ok=True)
  File "/usr/lib/python3.10/pathlib.py", line 1179, in mkdir
    self.parent.mkdir(parents=True, exist_ok=True)
  File "/usr/lib/python3.10/pathlib.py", line 1175, in mkdir
    self._accessor.mkdir(self, mode)
PermissionError: [Errno 13] Permission denied: '/datalake'
[2024-09-15 20:06:36,441] {taskinstance.py:1395} INFO - Marking task as FAILED. dag_id=BRONZER_GET_STONCKS, task_id=BRONZE_TSLA, execution_date=20240111T000000, start_date=20240915T230636, end_date=20240915T230636
[2024-09-15 20:06:36,450] {standard_task_runner.py:92} ERROR - Failed to execute job 42 for task BRONZE_TSLA ([Errno 13] Permission denied: '/datalake'; 12114)
[2024-09-15 20:06:36,467] {local_task_job.py:156} INFO - Task exited with return code 1
[2024-09-15 20:06:36,477] {local_task_job.py:273} INFO - 0 downstream tasks scheduled from follow-on schedule check
[2024-09-15 20:10:11,975] {taskinstance.py:1159} INFO - Dependencies all met for <TaskInstance: BRONZER_GET_STONCKS.BRONZE_TSLA scheduled__2024-01-11T00:00:00+00:00 [queued]>
[2024-09-15 20:10:11,980] {taskinstance.py:1159} INFO - Dependencies all met for <TaskInstance: BRONZER_GET_STONCKS.BRONZE_TSLA scheduled__2024-01-11T00:00:00+00:00 [queued]>
[2024-09-15 20:10:11,980] {taskinstance.py:1356} INFO - 
--------------------------------------------------------------------------------
[2024-09-15 20:10:11,980] {taskinstance.py:1357} INFO - Starting attempt 1 of 1
[2024-09-15 20:10:11,980] {taskinstance.py:1358} INFO - 
--------------------------------------------------------------------------------
[2024-09-15 20:10:11,992] {taskinstance.py:1377} INFO - Executing <Task(_PythonDecoratedOperator): BRONZE_TSLA> on 2024-01-11 00:00:00+00:00
[2024-09-15 20:10:11,994] {standard_task_runner.py:52} INFO - Started process 12710 to run task
[2024-09-15 20:10:11,996] {standard_task_runner.py:79} INFO - Running: ['airflow', 'tasks', 'run', 'BRONZER_GET_STONCKS', 'BRONZE_TSLA', 'scheduled__2024-01-11T00:00:00+00:00', '--job-id', '91', '--raw', '--subdir', 'DAGS_FOLDER/get_stocks.py', '--cfg-path', '/tmp/tmp2p5qsotl', '--error-file', '/tmp/tmpknal96w3']
[2024-09-15 20:10:11,996] {standard_task_runner.py:80} INFO - Job 91: Subtask BRONZE_TSLA
[2024-09-15 20:10:12,024] {task_command.py:370} INFO - Running <TaskInstance: BRONZER_GET_STONCKS.BRONZE_TSLA scheduled__2024-01-11T00:00:00+00:00 [running]> on host kaiwang.
[2024-09-15 20:10:12,064] {taskinstance.py:1569} INFO - Exporting the following env vars:
AIRFLOW_CTX_DAG_OWNER=airflow
AIRFLOW_CTX_DAG_ID=BRONZER_GET_STONCKS
AIRFLOW_CTX_TASK_ID=BRONZE_TSLA
AIRFLOW_CTX_EXECUTION_DATE=2024-01-11T00:00:00+00:00
AIRFLOW_CTX_TRY_NUMBER=1
AIRFLOW_CTX_DAG_RUN_ID=scheduled__2024-01-11T00:00:00+00:00
[2024-09-15 20:10:15,832] {history.py:244} ERROR - $TSLA: possibly delisted; no price data found  (1h 2024-01-08 -> 2024-01-03) (Yahoo error = "Invalid input - start date cannot be after end date. startDate = 1704690000, endDate = 1704258000")
[2024-09-15 20:10:15,840] {python.py:173} INFO - Done. Returned value was: None
[2024-09-15 20:10:15,852] {taskinstance.py:1395} INFO - Marking task as SUCCESS. dag_id=BRONZER_GET_STONCKS, task_id=BRONZE_TSLA, execution_date=20240111T000000, start_date=20240915T231011, end_date=20240915T231015
[2024-09-15 20:10:15,878] {local_task_job.py:156} INFO - Task exited with return code 0
[2024-09-15 20:10:15,887] {local_task_job.py:273} INFO - 0 downstream tasks scheduled from follow-on schedule check
[2024-09-15 20:13:12,470] {taskinstance.py:1159} INFO - Dependencies all met for <TaskInstance: BRONZER_GET_STONCKS.BRONZE_TSLA scheduled__2024-01-11T00:00:00+00:00 [queued]>
[2024-09-15 20:13:12,474] {taskinstance.py:1159} INFO - Dependencies all met for <TaskInstance: BRONZER_GET_STONCKS.BRONZE_TSLA scheduled__2024-01-11T00:00:00+00:00 [queued]>
[2024-09-15 20:13:12,474] {taskinstance.py:1356} INFO - 
--------------------------------------------------------------------------------
[2024-09-15 20:13:12,474] {taskinstance.py:1357} INFO - Starting attempt 1 of 1
[2024-09-15 20:13:12,474] {taskinstance.py:1358} INFO - 
--------------------------------------------------------------------------------
[2024-09-15 20:13:12,485] {taskinstance.py:1377} INFO - Executing <Task(_PythonDecoratedOperator): BRONZE_TSLA> on 2024-01-11 00:00:00+00:00
[2024-09-15 20:13:12,487] {standard_task_runner.py:52} INFO - Started process 13334 to run task
[2024-09-15 20:13:12,489] {standard_task_runner.py:79} INFO - Running: ['airflow', 'tasks', 'run', 'BRONZER_GET_STONCKS', 'BRONZE_TSLA', 'scheduled__2024-01-11T00:00:00+00:00', '--job-id', '91', '--raw', '--subdir', 'DAGS_FOLDER/get_stocks.py', '--cfg-path', '/tmp/tmph379urt_', '--error-file', '/tmp/tmppn3mip07']
[2024-09-15 20:13:12,490] {standard_task_runner.py:80} INFO - Job 91: Subtask BRONZE_TSLA
[2024-09-15 20:13:12,522] {task_command.py:370} INFO - Running <TaskInstance: BRONZER_GET_STONCKS.BRONZE_TSLA scheduled__2024-01-11T00:00:00+00:00 [running]> on host kaiwang.
[2024-09-15 20:13:12,567] {taskinstance.py:1569} INFO - Exporting the following env vars:
AIRFLOW_CTX_DAG_OWNER=airflow
AIRFLOW_CTX_DAG_ID=BRONZER_GET_STONCKS
AIRFLOW_CTX_TASK_ID=BRONZE_TSLA
AIRFLOW_CTX_EXECUTION_DATE=2024-01-11T00:00:00+00:00
AIRFLOW_CTX_TRY_NUMBER=1
AIRFLOW_CTX_DAG_RUN_ID=scheduled__2024-01-11T00:00:00+00:00
[2024-09-15 20:13:12,568] {taskinstance.py:1889} ERROR - Task failed with exception
Traceback (most recent call last):
  File "/usr/lib/python3.10/pathlib.py", line 1175, in mkdir
    self._accessor.mkdir(self, mode)
FileNotFoundError: [Errno 2] No such file or directory: '/Documents/airflow_celeby/datalake/TSLA'

During handling of the above exception, another exception occurred:

Traceback (most recent call last):
  File "/usr/lib/python3.10/pathlib.py", line 1175, in mkdir
    self._accessor.mkdir(self, mode)
FileNotFoundError: [Errno 2] No such file or directory: '/Documents/airflow_celeby/datalake'

During handling of the above exception, another exception occurred:

Traceback (most recent call last):
  File "/usr/lib/python3.10/pathlib.py", line 1175, in mkdir
    self._accessor.mkdir(self, mode)
FileNotFoundError: [Errno 2] No such file or directory: '/Documents/airflow_celeby'

During handling of the above exception, another exception occurred:

Traceback (most recent call last):
  File "/home/kaiwang/Documents/airflow_celeby/venv/lib/python3.10/site-packages/airflow/decorators/base.py", line 179, in execute
    return_value = super().execute(context)
  File "/home/kaiwang/Documents/airflow_celeby/venv/lib/python3.10/site-packages/airflow/operators/python.py", line 171, in execute
    return_value = self.execute_callable()
  File "/home/kaiwang/Documents/airflow_celeby/venv/lib/python3.10/site-packages/airflow/operators/python.py", line 189, in execute_callable
    return self.python_callable(*self.op_args, **self.op_kwargs)
  File "/home/kaiwang/Documents/airflow_celeby/dags/get_stocks.py", line 21, in get_history
    (Path(file_path).parent).mkdir(parents=True, exist_ok=True)
  File "/usr/lib/python3.10/pathlib.py", line 1179, in mkdir
    self.parent.mkdir(parents=True, exist_ok=True)
  File "/usr/lib/python3.10/pathlib.py", line 1179, in mkdir
    self.parent.mkdir(parents=True, exist_ok=True)
  File "/usr/lib/python3.10/pathlib.py", line 1179, in mkdir
    self.parent.mkdir(parents=True, exist_ok=True)
  File "/usr/lib/python3.10/pathlib.py", line 1175, in mkdir
    self._accessor.mkdir(self, mode)
PermissionError: [Errno 13] Permission denied: '/Documents'
[2024-09-15 20:13:12,571] {taskinstance.py:1395} INFO - Marking task as FAILED. dag_id=BRONZER_GET_STONCKS, task_id=BRONZE_TSLA, execution_date=20240111T000000, start_date=20240915T231312, end_date=20240915T231312
[2024-09-15 20:13:12,580] {standard_task_runner.py:92} ERROR - Failed to execute job 91 for task BRONZE_TSLA ([Errno 13] Permission denied: '/Documents'; 13334)
[2024-09-15 20:13:12,623] {local_task_job.py:156} INFO - Task exited with return code 1
[2024-09-15 20:13:12,648] {local_task_job.py:273} INFO - 0 downstream tasks scheduled from follow-on schedule check
[2024-09-15 20:17:13,855] {taskinstance.py:1159} INFO - Dependencies all met for <TaskInstance: BRONZER_GET_STONCKS.BRONZE_TSLA scheduled__2024-01-11T00:00:00+00:00 [queued]>
[2024-09-15 20:17:13,860] {taskinstance.py:1159} INFO - Dependencies all met for <TaskInstance: BRONZER_GET_STONCKS.BRONZE_TSLA scheduled__2024-01-11T00:00:00+00:00 [queued]>
[2024-09-15 20:17:13,860] {taskinstance.py:1356} INFO - 
--------------------------------------------------------------------------------
[2024-09-15 20:17:13,860] {taskinstance.py:1357} INFO - Starting attempt 1 of 1
[2024-09-15 20:17:13,860] {taskinstance.py:1358} INFO - 
--------------------------------------------------------------------------------
[2024-09-15 20:17:13,870] {taskinstance.py:1377} INFO - Executing <Task(_PythonDecoratedOperator): BRONZE_TSLA> on 2024-01-11 00:00:00+00:00
[2024-09-15 20:17:13,873] {standard_task_runner.py:52} INFO - Started process 13996 to run task
[2024-09-15 20:17:13,875] {standard_task_runner.py:79} INFO - Running: ['airflow', 'tasks', 'run', 'BRONZER_GET_STONCKS', 'BRONZE_TSLA', 'scheduled__2024-01-11T00:00:00+00:00', '--job-id', '91', '--raw', '--subdir', 'DAGS_FOLDER/get_stocks.py', '--cfg-path', '/tmp/tmp_4hp4x7i', '--error-file', '/tmp/tmpeqzlhnlk']
[2024-09-15 20:17:13,876] {standard_task_runner.py:80} INFO - Job 91: Subtask BRONZE_TSLA
[2024-09-15 20:17:13,907] {task_command.py:370} INFO - Running <TaskInstance: BRONZER_GET_STONCKS.BRONZE_TSLA scheduled__2024-01-11T00:00:00+00:00 [running]> on host kaiwang.
[2024-09-15 20:17:13,949] {taskinstance.py:1569} INFO - Exporting the following env vars:
AIRFLOW_CTX_DAG_OWNER=airflow
AIRFLOW_CTX_DAG_ID=BRONZER_GET_STONCKS
AIRFLOW_CTX_TASK_ID=BRONZE_TSLA
AIRFLOW_CTX_EXECUTION_DATE=2024-01-11T00:00:00+00:00
AIRFLOW_CTX_TRY_NUMBER=1
AIRFLOW_CTX_DAG_RUN_ID=scheduled__2024-01-11T00:00:00+00:00
[2024-09-15 20:17:17,189] {history.py:244} ERROR - $TSLA: possibly delisted; no price data found  (1h 2024-01-08 -> 2024-01-03) (Yahoo error = "Invalid input - start date cannot be after end date. startDate = 1704690000, endDate = 1704258000")
[2024-09-15 20:17:17,191] {python.py:173} INFO - Done. Returned value was: None
[2024-09-15 20:17:17,196] {taskinstance.py:1395} INFO - Marking task as SUCCESS. dag_id=BRONZER_GET_STONCKS, task_id=BRONZE_TSLA, execution_date=20240111T000000, start_date=20240915T231713, end_date=20240915T231717
[2024-09-15 20:17:17,238] {local_task_job.py:156} INFO - Task exited with return code 0
[2024-09-15 20:17:17,249] {local_task_job.py:273} INFO - 0 downstream tasks scheduled from follow-on schedule check
